Workbook

Sheet Read Me
A1: Advantedge Operations - KPI Catalog v9
A2: Complete redesign. Level-of-care aware. Prepared 2026-09-22 for VMP Systems.
A4: SECTION
A5: What changed | B5: v8 carried 98 KPIs applied more or less uniformly across every care level. v9 rebuilds the set from the ground up so that each measure is scored only where it is valid, and is benchmarked against the source that actually publishes that care level. 108 KPIs across the same nine departments: 72 outside SNF, 36 inside it.
A6: Departments | B6: Unchanged from v8: Operations (OPS), Sales and Marketing (SAL), Nursing (NUR), Skilled Nursing (SNF), Finance (FIN), Human Resources (HR), Plant and Maintenance (PLT), Life Enrichment (LE), Dining Services (DIN).
A7: Concision rule | B7: Every department outside SNF is held to 10 measures or fewer: OPS 8, SAL 9, FIN 10, HR 10, PLT 10, LE 6, DIN 7. Nursing carries 12 because it holds two separate blocks (8 AL/MC clinical measures and 4 SNF-only MDS and PDPM measures). SNF is exempt by design and carries 36, because the brief is to cover every contributing aspect of the CMS Five-Star rating.
A9: HOW CARE LEVEL FILTERING WORKS
A10: Applicability columns | B10: Each KPI carries an X in the IL, AL, MC, SNF and Entity columns where it is valid. When the operator selects care levels on Community Profile (Screen 03, Care Levels Offered), the catalog filters to the union of the selected columns. A KPI with no X in any selected column is suppressed entirely - not scored, not shown, not counted against coverage.
A11: Scope classes | B11: UNIVERSAL - valid at every care level the community operates. These are the yellow rows. Level-specific - valid only at the named levels, usually because the benchmark is published by care level. Care-delivering - AL, MC and SNF only. Excluded from IL because no care is delivered there. SNF only - the measure has no meaning outside a skilled nursing license. Entity - computed once for the organization from the trial balance. Does not decompose by care level. Entity (CCRC) - entity measure whose construct and benchmark are CCRC and Life Plan specific. Suppressed for rental communities and for a standalone SNF.
A12: Yellow highlighting | B12: Yellow rows are the universal measures - they apply to every care level and are therefore always in scope regardless of what the operator selects. 32 of the 108 KPIs are universal. The clearest example is the HR block: all ten HR measures are universal, and the turnover, engagement and training targets come from the RC 2025 CCRC benchmarks.
A13: Entity measures and SNF | B13: Days Cash on Hand, Debt Service Coverage, Days in AR, Entity Operating Margin, Entrance Fee Refund Funding and Average Age of Plant are entity measures. They are computed once from the balance sheet and are not assigned to a care level. A standalone SNF with no entity-level balance sheet in scope does not receive them. Entrance Fee Refund Funding is further restricted to CCRC and Life Plan contracts and is suppressed when no entrance fee contract exists.
A15: BENCHMARK SOURCE BY DOMAIN
A16: IL, AL and MC | B16: State of Seniors Housing 2025 (occupancy, turnover, revenue and expense per occupied unit, labor percent of revenue, dietary cost per resident day).
A17: SNF | B17: CMS only. Five-Star Quality Rating System Technical Users Guide, September 2026, plus the CMS Provider Data Catalog.
A18: CCRC and Life Plan | B18: CARF 2025 Financial Ratios and Trend Analysis (CARF / Ziegler / Baker Tilly, 33rd edition, 2024 medians) and the RC 2025 CCRC Performance Benchmarks.
A19: Sales and Marketing | B19: Aline Sales and Marketing Benchmark Report Q1 2024, which publishes funnel volume and conversion by IL, AL, MC and Life Plan Residential, with urban and rural cuts.
A20: Plant and Maintenance | B20: Siemens / Brightly Senior Living Maintenance Benchmarks, drawn from 1,000+ senior living organizations.
A21: Universal people measures | B21: RC 2025 CCRC Performance Benchmarks supply the turnover, employee satisfaction, training and resident experience targets. These are applied at every care level, which is why the HR block is entirely yellow.
A23: THE SNF BLOCK
A24: Rule applied | B24: The SNF department now contains CMS Five-Star contributors and nothing else. Every measure is tool-fetched from CMS. No operator upload feeds any SNF KPI.
A25: Coverage | B25: All three domains are complete: Health Inspections (9 measures), Staffing (7 PBJ measures), Quality Measures (15 rating measures plus the schizophrenia audit exception), and the 4 composite ratings. See the SNF Five-Star Coverage sheet.
A26: Moved out of SNF | B26: Four v8 SNF measures were not Five-Star contributors and were relocated: Medicare and Skilled Census to FIN-06, PDPM Case Mix Index to NUR-11, Average Medicare Length of Stay to OPS-04, and Skilled Revenue per Patient Day to FIN-03. Life Safety Code survey moved to PLT-08 because CMS states that Life Safety deficiencies are excluded from the Five-Star calculation.
A27: Corrections to v8 | B27: Three material errors were found against the September 2026 CMS guide and are corrected in v9. (1) The health inspection weighting is no longer three cycles at 50/33/17 - as of the July 2025 refresh it is two cycles at 3/4 and 1/4. (2) RN Turnover was missing entirely from the v8 staffing block and is added as SNF-S5. (3) The short-stay self-report moderate-to-severe pain measure was retired by CMS in October 2019 and has been removed.
A29: NURSING SPLIT
A30: AL and MC block | B30: NUR-01 through NUR-08. Clinically focused, covering what CMS does not measure and what AL and MC are actually surveyed on: medication error, falls, unplanned transfers, service plan reassessment timeliness, acuity migration, pressure injury, elopement, antipsychotic use. Benchmarks come from RC 2025, state regulation and the CMS QM distributions used as external reference points.
A31: SNF-only MDS block | B31: NUR-09 through NUR-12. MDS and PDPM measures that are genuinely SNF-only but are not Five-Star contributors, so they cannot sit in the SNF block: MDS transmission timeliness, ARD and late assessment rate, PDPM case mix index by component, care plan timeliness.
A32: Deliberate overlap | B32: NUR-01 Medication Administration Error Rate is the one clinical measure that spans AL, MC and SNF. CMS Five-Star has no medication error measure, so scoring it at SNF as well leaves no gap.
A34: SBC BOUNDARY
A35: Rule applied | B35: The Staffing Base Calculator owns staffing efficiency. No KPI duplicates an SBC output. See the SBC Boundary sheet for the full exclusion list.
A36: The one exception | B36: SNF RN HPRD, total nurse HPRD and weekend HPRD remain in the SNF block. They are CMS Five-Star rating inputs computed from PBJ, not outputs of the SBC staffing model, and they move the star rating. AL and MC HPPD stays with the SBC and is not a KPI.
A37: The PBJ rule | B37: PBJ-derived measures exist only in the SNF block. HR-01 and HR-02 measure turnover from the operator payroll file and apply at every care level, which is what makes them valid for assisted living.
A39: DATA BASIS
A40: Intake grounding | B40: Every KPI is traced to a screen in the Advantedge Onboarding Screen Inventory (v3.0.41). The Intake column names the screen. No KPI depends on data the operator is not already being asked for.
A41: Excluded by design | B41: Policy and procedure alignment, contract analysis, and similar document-review outputs are not KPIs. They remain analysis sections of the report and are not scored.
A42: Data vintage note | B42: Aline figures are Q1 2024 from the attached report. CARF figures are 2024 medians from the 2025 edition. SOSH figures are 2025. CMS methodology is the September 2026 Technical Users Guide, verified 2026-09-22. CMS raises the QM composite thresholds every six months; the next increase is expected at the January 2027 refresh.
A43: Real vs placeholder | B43: Every benchmark value in this catalog is a real published figure traced to a named source. Nothing in the Benchmark and Target column is a placeholder. Where no benchmark exists, the target column says so explicitly and the measure is scored on the community's own trend.

Sheet KPI Catalog
A1: KPI Catalog v9 - 108 measures across nine departments
A2: Yellow rows are UNIVERSAL measures: valid at every care level the community operates. X marks the care levels where a measure is scored.
A4: Code | B4: Department | C4: KPI | D4: What It Measures | E4: Direction | F4: IL | G4: AL | H4: MC | I4: SNF | J4: Entity | K4: Scope Class | L4: Benchmark Source | M4: Benchmark / Target | N4: Intake (Onboarding Screen) | O4: Boundary and Notes | P4: What the Benchmark Reveals | Q4: Primary Benchmark Source Group
A5: OPS-01 | B5: Operations | C5: Occupancy Rate by Care Level | D5: Occupied units or beds / available units or beds, computed separately for each care level | E5: Higher | F5: X | G5: X | H5: X | I5: X | K5: Level-specific | L5: SOSH 2025 Table 2.7 (IL/AL/MC/CCRC); CARF 2025 Occupancy Trends (SNF) | M5: IL 87.8% | AL 89.9% | MC 86.0% | CCRC 90.6% | SNF 79.2% (CARF 2024) | N5: Census / occupancy report (Screen 09) | P5: Below the segment median in a rising market means the problem is local - product, price, reputation or sales execution - not demand. High occupancy paired with weak achieved rate means census is being bought. | Q5: {=IFERROR(INDEX('Benchmark Source Map'!$A$5:$A$13,MATCH(TRUE,(ISNUMBER(SEARCH('Benchmark Source Map'!$E$5:$E$13,$L5))+ISNUMBER(SEARCH('Benchmark Source Map'!$F$5:$F$13,$L5)))>0,0)),"Other named sources")} -> State of Seniors Housing (SOSH) 2025
A6: OPS-02 | B6: Operations | C6: Net Census Change | D6: Move-ins minus move-outs for the period, by care level | E6: Higher | F6: X | G6: X | H6: X | I6: X | K6: UNIVERSAL | L6: Rob Clark - internal standard | M6: Directional. Sector occupancy has risen ~0.5-0.7 pp/qtr for 17+ quarters; net decline against a rising market is the flag | N6: Census / occupancy report (Screen 09) | O6: RE-ATTRIBUTED 22 Sep 2026 by owner instruction: third-party named sources are not carried in this catalog, and removing the previous attribution left no source, so this benchmark is recorded as a Rob Clark internal standard. Previous attribution read: 'NIC MAP Senior Housing Market Fundamentals (quarterly)'. The target value itself was not changed - only the attribution. Treat the figure as an advisor standard with no external publication behind it. | P6: Reads intent rather than condition. Net decline while the sector adds 0.5-0.7 pp a quarter means share is being lost to competitors, not to the market. | Q6: {=IFERROR(INDEX('Benchmark Source Map'!$A$5:$A$13,MATCH(TRUE,(ISNUMBER(SEARCH('Benchmark Source Map'!$E$5:$E$13,$L6))+ISNUMBER(SEARCH('Benchmark Source Map'!$F$5:$F$13,$L6)))>0,0)),"Other named sources")} -> Rob Clark - 2025 CCRC Performance Benchmarks and advisor internal standards
A7: OPS-03 | B7: Operations | C7: Annual Resident Turnover by Care Level | D7: Move-outs / average occupied units, annualized | E7: Lower | F7: X | G7: X | H7: X | K7: Level-specific | L7: SOSH 2025 Table 2.15 | M7: IL 44.3% | AL 48.1% | MC 64.7% | CCRC 15.6% | N7: Census / occupancy report (Screen 09) | O7: Excludes SNF: short-stay turns are by design, not attrition | P7: Turnover above the level median points at expectation-setting at move-in or a care model that cannot hold acuity. IL turnover approaching AL levels usually means residents are leaving to get care the community cannot provide. | Q7: {=IFERROR(INDEX('Benchmark Source Map'!$A$5:$A$13,MATCH(TRUE,(ISNUMBER(SEARCH('Benchmark Source Map'!$E$5:$E$13,$L7))+ISNUMBER(SEARCH('Benchmark Source Map'!$F$5:$F$13,$L7)))>0,0)),"Other named sources")} -> State of Seniors Housing (SOSH) 2025
A8: OPS-04 | B8: Operations | C8: Average Length of Stay by Care Level | D8: Average resident tenure at move-out, by care level; SNF reported separately for short-stay and long-stay | E8: Higher (IL/AL/MC) | F8: X | G8: X | H8: X | I8: X | K8: Level-specific | L8: SOSH 2025 Table 2.15 (inverse of turnover); CMS MDS (SNF) | M8: Derived from SOSH turnover: IL ~2.3 yr | AL ~2.1 yr | MC ~1.5 yr. SNF Medicare LOS on own trend | N8: Census report + clinical / MDS report (Screen 09) | O8: Absorbs retired SNF-1.03 Average Medicare Length of Stay | P8: Short tenure against the level norm is the revenue leak hiding behind a healthy occupancy number: the community is refilling faster than it is retaining. | Q8: {=IFERROR(INDEX('Benchmark Source Map'!$A$5:$A$13,MATCH(TRUE,(ISNUMBER(SEARCH('Benchmark Source Map'!$E$5:$E$13,$L8))+ISNUMBER(SEARCH('Benchmark Source Map'!$F$5:$F$13,$L8)))>0,0)),"Other named sources")} -> State of Seniors Housing (SOSH) 2025
A9: OPS-05 | B9: Operations | C9: Resident Satisfaction Score | D9: As measured by the operator's instrument, normalized to a 0-100 scale, with source and instrument recorded | E9: Higher | F9: X | G9: X | H9: X | I9: X | K9: UNIVERSAL | L9: RC 2025 CCRC Benchmarks | M9: RC 2025 target >= 90%. Reference: J.D. Power 2025 IL 753/1000; Holleran Choice Award > 85th percentile | N9: Manual entry (Screen 10) | O9: Clears the resident-side cultural health red flag SOURCE TRIMMED 22 Sep 2026 by owner instruction - third-party named sources removed from the Benchmark Source column. Original read: 'RC 2025 CCRC Benchmarks; J.D. Power 2025; Holleran'. | P9: The best leading indicator of census risk in the catalog. Scores below target typically surface in turnover and referral volume two to three quarters later. | Q9: {=IFERROR(INDEX('Benchmark Source Map'!$A$5:$A$13,MATCH(TRUE,(ISNUMBER(SEARCH('Benchmark Source Map'!$E$5:$E$13,$L9))+ISNUMBER(SEARCH('Benchmark Source Map'!$F$5:$F$13,$L9)))>0,0)),"Other named sources")} -> Rob Clark - 2025 CCRC Performance Benchmarks and advisor internal standards
A10: OPS-06 | B10: Operations | C10: Family Satisfaction Score | D10: As measured by the operator's instrument, normalized to a 0-100 scale | E10: Higher | F10: X | G10: X | H10: X | I10: X | K10: UNIVERSAL | L10: RC 2025 CCRC Benchmarks | M10: RC 2025 target >= 88%. Reference: J.D. Power 2025 AL/MC 867/1000 | N10: Manual entry (Screen 10) | O10: SOURCE TRIMMED 22 Sep 2026 by owner instruction - third-party named sources removed from the Benchmark Source column. Original read: 'RC 2025 CCRC Benchmarks; J.D. Power 2025; Holleran'. | P10: Families drive both the move-in and the move-out decision. A family score well below the resident score means a communication failure, not a care failure. | Q10: {=IFERROR(INDEX('Benchmark Source Map'!$A$5:$A$13,MATCH(TRUE,(ISNUMBER(SEARCH('Benchmark Source Map'!$E$5:$E$13,$L10))+ISNUMBER(SEARCH('Benchmark Source Map'!$F$5:$F$13,$L10)))>0,0)),"Other named sources")} -> Rob Clark - 2025 CCRC Performance Benchmarks and advisor internal standards
A11: OPS-07 | B11: Operations | C11: Reportable Incident Rate | D11: All reportable incidents / resident days x 1,000 | E11: Lower | F11: X | G11: X | H11: X | I11: X | K11: UNIVERSAL | L11: Rob Clark - internal standard | M11: Scored on the community's own trend. Component reference: falls 3.5-4.0 per 1,000 resident days | N11: Incident and grievance log (Screen 09) | O11: Composite only. Clinical components are scored in NUR (AL/MC) and SNF (CMS QMs) RE-ATTRIBUTED 22 Sep 2026 by owner instruction: third-party named sources are not carried in this catalog, and removing the previous attribution left no source, so this benchmark is recorded as a Rob Clark internal standard. Previous attribution read: 'Component benchmarks only (no published composite)'. The target value itself was not changed - only the attribution. Treat the figure as an advisor standard with no external publication behind it. | P11: Read the trend, not the level. A falling incident count against a rising acuity mix is more often under-reporting than improvement. | Q11: {=IFERROR(INDEX('Benchmark Source Map'!$A$5:$A$13,MATCH(TRUE,(ISNUMBER(SEARCH('Benchmark Source Map'!$E$5:$E$13,$L11))+ISNUMBER(SEARCH('Benchmark Source Map'!$F$5:$F$13,$L11)))>0,0)),"Other named sources")} -> Rob Clark - 2025 CCRC Performance Benchmarks and advisor internal standards
A12: OPS-08 | B12: Operations | C12: Grievance Resolution Time | D12: Average calendar days from grievance receipt to documented resolution, plus grievance volume per 100 residents | E12: Lower | F12: X | G12: X | H12: X | I12: X | K12: UNIVERSAL | L12: CMS 42 CFR 483.10(j); CMS Medicare-plan 30-day grievance standard (reference) | M12: Resolution <= 30 days; acknowledgment <= 5 business days | N12: Incident and grievance log (Screen 09) | P12: Slow resolution with low volume means complaints are being suppressed. Fast resolution with high volume means the process works but something upstream keeps breaking. | Q12: {=IFERROR(INDEX('Benchmark Source Map'!$A$5:$A$13,MATCH(TRUE,(ISNUMBER(SEARCH('Benchmark Source Map'!$E$5:$E$13,$L12))+ISNUMBER(SEARCH('Benchmark Source Map'!$F$5:$F$13,$L12)))>0,0)),"Other named sources")} -> CMS and regulatory requirements (Five-Star Technical Users' Guide, RAI Manual, 42 CFR, Life Safety Code, state regulation)
A13: SAL-01 | B13: Sales and Marketing | C13: Inquiries per 100 Units per Month | D13: Total inquiries / (units / 100) / months in period | E13: Higher | F13: X | G13: X | H13: X | K13: Level-specific | L13: Aline Sales and Marketing Benchmark Report Q1 2024 | M13: IL 37 | AL 45 | MC 41 | Life Plan Residential 30. Urban and rural cuts available | N13: Sales / CRM report (Screen 09) + months in period (Screen 10) | O13: Aline does not benchmark SNF admissions; SNF excluded ALINE VINTAGE 22 Sep 2026: reverted to the Q1 2024 edition, which is the vintage the target figures actually come from. The 2026 report is registration-gated and its figures cannot be obtained by either workbook, so the catalog cites the edition it holds rather than the newest edition it cannot substantiate. | P13: Tests demand generation, not sales skill. Below benchmark means market presence or marketing spend falls short before any sales conversation happens. | Q13: {=IFERROR(INDEX('Benchmark Source Map'!$A$5:$A$13,MATCH(TRUE,(ISNUMBER(SEARCH('Benchmark Source Map'!$E$5:$E$13,$L13))+ISNUMBER(SEARCH('Benchmark Source Map'!$F$5:$F$13,$L13)))>0,0)),"Other named sources")} -> Aline Sales and Marketing Benchmark Report
A14: SAL-02 | B14: Sales and Marketing | C14: Tours per 100 Units per Month | D14: Total tours / (units / 100) / months in period | E14: Higher | F14: X | G14: X | H14: X | K14: Level-specific | L14: Aline Sales and Marketing Benchmark Report Q1 2024 | M14: IL 8 | AL 11 | MC 13 | Life Plan Residential 7 | N14: Sales / CRM report (Screen 09) | O14: ALINE VINTAGE 22 Sep 2026: reverted to the Q1 2024 edition, which is the vintage the target figures actually come from. The 2026 report is registration-gated and its figures cannot be obtained by either workbook, so the catalog cites the edition it holds rather than the newest edition it cannot substantiate. | P14: The bridge measure. Low tours on healthy inquiry volume means inquiries are not being worked. | Q14: {=IFERROR(INDEX('Benchmark Source Map'!$A$5:$A$13,MATCH(TRUE,(ISNUMBER(SEARCH('Benchmark Source Map'!$E$5:$E$13,$L14))+ISNUMBER(SEARCH('Benchmark Source Map'!$F$5:$F$13,$L14)))>0,0)),"Other named sources")} -> Aline Sales and Marketing Benchmark Report
A15: SAL-03 | B15: Sales and Marketing | C15: Move-Ins per 100 Units per Month | D15: Total move-ins / (units / 100) / months in period | E15: Higher | F15: X | G15: X | H15: X | K15: Level-specific | L15: Aline Sales and Marketing Benchmark Report Q1 2024 | M15: IL 3 | AL 5 | MC 7 | Life Plan Residential 2 | N15: Sales / CRM report (Screen 09) | O15: ALINE VINTAGE 22 Sep 2026: reverted to the Q1 2024 edition, which is the vintage the target figures actually come from. The 2026 report is registration-gated and its figures cannot be obtained by either workbook, so the catalog cites the edition it holds rather than the newest edition it cannot substantiate. | P15: The only sales measure that pays. Benchmark inquiries with sub-benchmark move-ins means the funnel is leaking, not starving. | Q15: {=IFERROR(INDEX('Benchmark Source Map'!$A$5:$A$13,MATCH(TRUE,(ISNUMBER(SEARCH('Benchmark Source Map'!$E$5:$E$13,$L15))+ISNUMBER(SEARCH('Benchmark Source Map'!$F$5:$F$13,$L15)))>0,0)),"Other named sources")} -> Aline Sales and Marketing Benchmark Report
A16: SAL-04 | B16: Sales and Marketing | C16: Inquiry-to-Tour Conversion Rate | D16: Tours / inquiries, all channels | E16: Higher | F16: X | G16: X | H16: X | K16: Level-specific | L16: Aline Sales and Marketing Benchmark Report Q1 2024 | M16: IL 28% | AL 29% | MC 36% | Life Plan Residential 29% | N16: Sales / CRM report (Screen 09) | O16: ALINE VINTAGE 22 Sep 2026: reverted to the Q1 2024 edition, which is the vintage the target figures actually come from. The 2026 report is registration-gated and its figures cannot be obtained by either workbook, so the catalog cites the edition it holds rather than the newest edition it cannot substantiate. | P16: Reads lead quality and speed of response together. Below benchmark is usually response time rather than lead quality. | Q16: {=IFERROR(INDEX('Benchmark Source Map'!$A$5:$A$13,MATCH(TRUE,(ISNUMBER(SEARCH('Benchmark Source Map'!$E$5:$E$13,$L16))+ISNUMBER(SEARCH('Benchmark Source Map'!$F$5:$F$13,$L16)))>0,0)),"Other named sources")} -> Aline Sales and Marketing Benchmark Report
A17: SAL-05 | B17: Sales and Marketing | C17: Tour-to-Move-In Conversion Rate | D17: Move-ins / tours | E17: Higher | F17: X | G17: X | H17: X | K17: Level-specific | L17: Aline Sales and Marketing Benchmark Report Q1 2024 | M17: IL 34% | AL 45% | MC 58% | Life Plan Residential 31% | N17: Sales / CRM report (Screen 09) | O17: ALINE VINTAGE 22 Sep 2026: reverted to the Q1 2024 edition, which is the vintage the target figures actually come from. The 2026 report is registration-gated and its figures cannot be obtained by either workbook, so the catalog cites the edition it holds rather than the newest edition it cannot substantiate. | P17: Reads the close and the product. Weak conversion on healthy tour volume points at price, unit condition or the tour experience itself. | Q17: {=IFERROR(INDEX('Benchmark Source Map'!$A$5:$A$13,MATCH(TRUE,(ISNUMBER(SEARCH('Benchmark Source Map'!$E$5:$E$13,$L17))+ISNUMBER(SEARCH('Benchmark Source Map'!$F$5:$F$13,$L17)))>0,0)),"Other named sources")} -> Aline Sales and Marketing Benchmark Report
A18: SAL-06 | B18: Sales and Marketing | C18: Inquiry Channel Mix | D18: Share of inquiries by channel: web, paid, unpaid referral, call-in | E18: Distribution | F18: X | G18: X | H18: X | K18: Level-specific | L18: Aline Sales and Marketing Benchmark Report Q1 2024 | M18: Web IL 40 / AL 43 / MC 35 / LPR 47 | Paid IL 27 / AL 32 / MC 34 / LPR 7 | Call-in IL 24 / AL 14 / MC 14 / LPR 32 | Unpaid IL 9 / AL 11 / MC 17 / LPR 14 (percent) | N18: Sales / CRM report (Screen 09) | O18: ALINE VINTAGE 22 Sep 2026: reverted to the Q1 2024 edition, which is the vintage the target figures actually come from. The 2026 report is registration-gated and its figures cannot be obtained by either workbook, so the catalog cites the edition it holds rather than the newest edition it cannot substantiate. | P18: A paid and aggregator-heavy mix is rented demand: it stops the day spend stops. A high unpaid referral share is the signature of a community with reputation equity. | Q18: {=IFERROR(INDEX('Benchmark Source Map'!$A$5:$A$13,MATCH(TRUE,(ISNUMBER(SEARCH('Benchmark Source Map'!$E$5:$E$13,$L18))+ISNUMBER(SEARCH('Benchmark Source Map'!$F$5:$F$13,$L18)))>0,0)),"Other named sources")} -> Aline Sales and Marketing Benchmark Report
A19: SAL-07 | B19: Sales and Marketing | C19: Inquiry-to-Tour Conversion by Channel | D19: Tours / inquiries computed separately for each acquisition channel | E19: Higher | F19: X | G19: X | H19: X | K19: Level-specific | L19: Aline Sales and Marketing Benchmark Report Q1 2024 | M19: Unpaid referral IL 61 / AL 59 / MC 61 / LPR 51 | Call-in and other IL 50 / AL 55 / MC 56 / LPR 42 | Web IL 28 / AL 28 / MC 37 / LPR 28 | Paid and aggregator IL 22 / AL 27 / MC 36 / LPR 30 (percent) | N19: Sales / CRM report (Screen 09) | O19: This is the spend-allocation measure: it separates channel volume from channel quality ALINE VINTAGE 22 Sep 2026: reverted to the Q1 2024 edition, which is the vintage the target figures actually come from. The 2026 report is registration-gated and its figures cannot be obtained by either workbook, so the catalog cites the edition it holds rather than the newest edition it cannot substantiate. | P19: The spend-allocation test. Unpaid referral converts at roughly double paid, so a paid-heavy mix with weak conversion means money is buying poor leads. | Q19: {=IFERROR(INDEX('Benchmark Source Map'!$A$5:$A$13,MATCH(TRUE,(ISNUMBER(SEARCH('Benchmark Source Map'!$E$5:$E$13,$L19))+ISNUMBER(SEARCH('Benchmark Source Map'!$F$5:$F$13,$L19)))>0,0)),"Other named sources")} -> Aline Sales and Marketing Benchmark Report
A20: SAL-08 | B20: Sales and Marketing | C20: Average Rate Achieved vs Published Rate | D20: Average rate achieved on new move-ins / published street rate for the same unit type | E20: Higher | F20: X | G20: X | H20: X | K20: Level-specific | L20: SOSH 2025; operator rate sheet | M20: Concessions < 3% of gross rent | N20: Rate sheet (Screen 04) + sales / CRM report (Screen 09) + published rate (Screen 10) | P20: Concessions above 3% of gross rent mean census is being purchased. Rising occupancy on a falling achieved rate is not a win. | Q20: {=IFERROR(INDEX('Benchmark Source Map'!$A$5:$A$13,MATCH(TRUE,(ISNUMBER(SEARCH('Benchmark Source Map'!$E$5:$E$13,$L20))+ISNUMBER(SEARCH('Benchmark Source Map'!$F$5:$F$13,$L20)))>0,0)),"Other named sources")} -> State of Seniors Housing (SOSH) 2025
A21: SAL-09 | B21: Sales and Marketing | C21: Online Reputation Score | D21: Average star rating, review volume, and operator response rate, by platform | E21: Higher | F21: X | G21: X | H21: X | I21: X | K21: UNIVERSAL | L21: RC 2025 CCRC Benchmarks | M21: RC 2025 target >= 4.3 stars. Practice standard 4.5+ stars, 50+ reviews, 100% response rate | N21: Manual entry with source platform (Screen 10) | O21: SOURCE TRIMMED 22 Sep 2026 by owner instruction - third-party named sources removed from the Benchmark Source column. Original read: 'RC 2025 CCRC Benchmarks; Caring.com; Senior Housing News'. | P21: The cheapest leading indicator available. Star rating matters less than review volume and response rate - no responses reads to families as an absent operator. | Q21: {=IFERROR(INDEX('Benchmark Source Map'!$A$5:$A$13,MATCH(TRUE,(ISNUMBER(SEARCH('Benchmark Source Map'!$E$5:$E$13,$L21))+ISNUMBER(SEARCH('Benchmark Source Map'!$F$5:$F$13,$L21)))>0,0)),"Other named sources")} -> Rob Clark - 2025 CCRC Performance Benchmarks and advisor internal standards
A22: SAL-10 | B22: Sales and Marketing | C22: Deposit-to-Move-In Conversion Rate | D22: Move-ins originating from deposits / deposits taken | E22: Higher | F22: X | G22: X | H22: X | I22: X | K22: UNIVERSAL | L22: RC 2025 CCRC Performance Benchmarks; Kushant Shah internal standard | M22: 80-90% deposit-to-move-in; target 85% | N22: TO BE MAPPED - added from Gap Matrix v9; intake screen not yet assigned | O22: Sits between SAL-05 tour-to-move-in and the move-in itself. The deposit stage was absent from v9 and is where late-stage fallout concentrates. Added 22 Sep 2026 from the Gap Matrix v9 (Rob Clark, Kushant Shah). | P22: The deepest point in the funnel and the least forgiving. Fallout after a deposit reveals move-in friction - unit readiness, financial qualification or family second-guessing - not sales skill. | Q22: {=IFERROR(INDEX('Benchmark Source Map'!$A$5:$A$13,MATCH(TRUE,(ISNUMBER(SEARCH('Benchmark Source Map'!$E$5:$E$13,$L22))+ISNUMBER(SEARCH('Benchmark Source Map'!$F$5:$F$13,$L22)))>0,0)),"Other named sources")} -> Rob Clark - 2025 CCRC Performance Benchmarks and advisor internal standards
A23: SAL-11 | B23: Sales and Marketing | C23: Cost per Acquired Resident | D23: Total sales and marketing spend / move-ins | E23: Lower | F23: X | G23: X | H23: X | I23: X | K23: UNIVERSAL | L23: RC 2025 CCRC Performance Benchmarks - CDS Best Practice Metrics 2025 (advisor material, derived) | M23: Community-specific ceiling = (marketing spend at 2-3% of operating expenses) / expected annual move-ins | N23: TO BE MAPPED - added from Gap Matrix v9; intake screen not yet assigned | O23: Target is derived, not published - compute the ceiling per community from its own operating expense base. No external per-resident acquisition cost benchmark exists. Added 22 Sep 2026 from the Gap Matrix v9 (Rob Clark). | P23: The only measure that tells you whether census growth was earned or purchased. A community hitting move-in targets at double the acceptable acquisition cost is not performing, it is spending. | Q23: {=IFERROR(INDEX('Benchmark Source Map'!$A$5:$A$13,MATCH(TRUE,(ISNUMBER(SEARCH('Benchmark Source Map'!$E$5:$E$13,$L23))+ISNUMBER(SEARCH('Benchmark Source Map'!$F$5:$F$13,$L23)))>0,0)),"Other named sources")} -> Rob Clark - 2025 CCRC Performance Benchmarks and advisor internal standards
A24: NUR-01 | B24: Nursing | C24: Medication Administration Error Rate | D24: Medication errors / doses administered x 1,000 | E24: Lower | G24: X | H24: X | I24: X | K24: Care-delivering | L24: RC 2025 CCRC Benchmarks | M24: RC 2025: >= 98% administration accuracy, < 2% error rate | N24: Clinical / EHR report (Screen 09) | O24: CMS Five-Star has no medication error measure, so this applies to SNF as well as AL/MC | P24: Accuracy below 98% is a staffing and training signal before it is a clinical one. It tracks closely with agency use and overtime. | Q24: {=IFERROR(INDEX('Benchmark Source Map'!$A$5:$A$13,MATCH(TRUE,(ISNUMBER(SEARCH('Benchmark Source Map'!$E$5:$E$13,$L24))+ISNUMBER(SEARCH('Benchmark Source Map'!$F$5:$F$13,$L24)))>0,0)),"Other named sources")} -> Rob Clark - 2025 CCRC Performance Benchmarks and advisor internal standards
A25: NUR-02 | B25: Nursing | C25: Fall Rate per 1,000 Resident Days | D25: All falls / resident days x 1,000 | E25: Lower | G25: X | H25: X | K25: Level-specific | L25: Rob Clark - internal standard | M25: 3.5-4.0 falls per 1,000 resident days | N25: Clinical / EHR report + incident log (Screen 09) | O25: SNF falls with major injury are scored at SNF-Q6 (CMS QM) RE-ATTRIBUTED 22 Sep 2026 by owner instruction: third-party named sources are not carried in this catalog, and removing the previous attribution left no source, so this benchmark is recorded as a Rob Clark internal standard. Previous attribution read: 'Industry falls benchmark'. The target value itself was not changed - only the attribution. Treat the figure as an advisor standard with no external publication behind it. | P25: The rate alone is ambiguous. A very low fall rate against a high acuity mix usually means falls are not being captured. Read with acuity and injury severity. | Q25: {=IFERROR(INDEX('Benchmark Source Map'!$A$5:$A$13,MATCH(TRUE,(ISNUMBER(SEARCH('Benchmark Source Map'!$E$5:$E$13,$L25))+ISNUMBER(SEARCH('Benchmark Source Map'!$F$5:$F$13,$L25)))>0,0)),"Other named sources")} -> Rob Clark - 2025 CCRC Performance Benchmarks and advisor internal standards
A26: NUR-03 | B26: Nursing | C26: Unplanned Hospital Transfer Rate | D26: Unplanned transfers to acute care / 100 residents / month | E26: Lower | G26: X | H26: X | K26: Level-specific | L26: RC 2025 CCRC Benchmarks (care transition efficiency) | M26: RC 2025: >= 95% timely transitions, < 10% readmission | N26: Clinical / EHR report (Screen 09) | O26: SNF hospitalization and ED rates are scored at SNF-Q8, Q9, Q13, Q14 (CMS QMs) | P26: Measures the ability to manage change in condition in place. High transfer rates erode census, revenue and hospital referral relationships simultaneously. | Q26: {=IFERROR(INDEX('Benchmark Source Map'!$A$5:$A$13,MATCH(TRUE,(ISNUMBER(SEARCH('Benchmark Source Map'!$E$5:$E$13,$L26))+ISNUMBER(SEARCH('Benchmark Source Map'!$F$5:$F$13,$L26)))>0,0)),"Other named sources")} -> Rob Clark - 2025 CCRC Performance Benchmarks and advisor internal standards
A27: NUR-04 | B27: Nursing | C27: Service Plan Reassessment Timeliness | D27: Required AL/MC service plan reassessments completed within the state-mandated interval / reassessments due | E27: Higher | G27: X | H27: X | K27: Level-specific | L27: State regulation (Advantedge State Regulatory Reference) | M27: 100% on time. Interval is state-specific and pulled from the state regulatory dataset | N27: Clinical / EHR report (Screen 09) | O27: This is the AL/MC analogue of MDS timeliness. The MDS measures themselves are SNF only (NUR-09 to NUR-12) | P27: Anything below 100% is regulatory exposure. Chronic lateness means the clinical leadership span of control is too wide. | Q27: {=IFERROR(INDEX('Benchmark Source Map'!$A$5:$A$13,MATCH(TRUE,(ISNUMBER(SEARCH('Benchmark Source Map'!$E$5:$E$13,$L27))+ISNUMBER(SEARCH('Benchmark Source Map'!$F$5:$F$13,$L27)))>0,0)),"Other named sources")} -> CMS and regulatory requirements (Five-Star Technical Users' Guide, RAI Manual, 42 CFR, Life Safety Code, state regulation)
A28: NUR-05 | B28: Nursing | C28: Resident Acuity and Care Tier Mix | D28: Distribution of residents across care tiers or point bands, with period-over-period migration | E28: Trend | G28: X | H28: X | K28: Level-specific | L28: Internal trend, read against SOSH 2025 revenue per occupied unit | M28: Directional. Upward acuity migration without a matching rate or staffing response is the flag | N28: Clinical / EHR report + census report (Screen 09) | O28: SBC consumes census to size staffing; this measures the acuity behind it | P28: Upward acuity migration without a matching rate or staffing response is the most common cause of a margin collapse nobody saw coming. | Q28: {=IFERROR(INDEX('Benchmark Source Map'!$A$5:$A$13,MATCH(TRUE,(ISNUMBER(SEARCH('Benchmark Source Map'!$E$5:$E$13,$L28))+ISNUMBER(SEARCH('Benchmark Source Map'!$F$5:$F$13,$L28)))>0,0)),"Other named sources")} -> State of Seniors Housing (SOSH) 2025
A29: NUR-06 | B29: Nursing | C29: New Pressure Injury Incidence, Stage 2 and Above | E29: Lower | G29: X | H29: X | K29: Level-specific | L29: CMS long-stay pressure ulcer QM distribution used as reference | M29: Trend to zero; CMS SNF long-stay rate as the external reference point | N29: Clinical / EHR report (Screen 09) | O29: SNF is scored at SNF-Q3 (long-stay) and SNF-Q11 (short-stay) | P29: In-house acquired Stage 2+ injuries read repositioning, nutrition and staffing consistency directly. Near-zero is achievable; an upward trend is never benign. | Q29: {=IFERROR(INDEX('Benchmark Source Map'!$A$5:$A$13,MATCH(TRUE,(ISNUMBER(SEARCH('Benchmark Source Map'!$E$5:$E$13,$L29))+ISNUMBER(SEARCH('Benchmark Source Map'!$F$5:$F$13,$L29)))>0,0)),"Other named sources")} -> CMS and regulatory requirements (Five-Star Technical Users' Guide, RAI Manual, 42 CFR, Life Safety Code, state regulation)
A30: NUR-07 | B30: Nursing | C30: Elopement and Exit-Seeking Incidents | D30: Count of elopement and exit-seeking events per 100 MC residents per month | E30: Lower | G30: X | H30: X | K30: Level-specific | L30: State regulation; no published rate benchmark | M30: Zero tolerance. Any event triggers review; trend scored on the community's own baseline | N30: Incident and grievance log (Screen 09) | O30: MC-weighted. No CMS Five-Star equivalent exists | P30: Zero tolerance. Any event is a licensure and litigation event, and the trend reveals whether the MC environment and staffing ratio actually match the resident profile. | Q30: {=IFERROR(INDEX('Benchmark Source Map'!$A$5:$A$13,MATCH(TRUE,(ISNUMBER(SEARCH('Benchmark Source Map'!$E$5:$E$13,$L30))+ISNUMBER(SEARCH('Benchmark Source Map'!$F$5:$F$13,$L30)))>0,0)),"Other named sources")} -> CMS and regulatory requirements (Five-Star Technical Users' Guide, RAI Manual, 42 CFR, Life Safety Code, state regulation)
A31: NUR-08 | B31: Nursing | C31: Antipsychotic Use Rate | D31: Residents receiving an antipsychotic without a supporting diagnosis / total residents | E31: Lower | G31: X | H31: X | K31: Level-specific | L31: CMS long-stay antipsychotic QM distribution used as reference | M31: CMS long-stay QM distribution as the external reference point | N31: Clinical / EHR report (Screen 09) | O31: SNF is scored at SNF-Q7 (long-stay) and SNF-Q12 (short-stay, first-time) | P31: High use without a supporting diagnosis usually substitutes for staffing and behavioral programming. A culture measure disguised as a clinical one - read against LE-06 programming coverage, since unstructured time is what drives behavioural events. | Q31: {=IFERROR(INDEX('Benchmark Source Map'!$A$5:$A$13,MATCH(TRUE,(ISNUMBER(SEARCH('Benchmark Source Map'!$E$5:$E$13,$L31))+ISNUMBER(SEARCH('Benchmark Source Map'!$F$5:$F$13,$L31)))>0,0)),"Other named sources")} -> CMS and regulatory requirements (Five-Star Technical Users' Guide, RAI Manual, 42 CFR, Life Safety Code, state regulation)
A32: NUR-09 | B32: Nursing | C32: MDS Assessment Completion Timeliness | D32: MDS assessments transmitted within the CMS-required window / assessments due | E32: Higher | I32: X | K32: SNF only | L32: CMS RAI Manual | M32: 100% transmitted within the required window | N32: Clinical / EHR MDS report (Screen 09) | O32: MDS-derived and SNF only. Not a Five-Star input, so it lives here rather than in the SNF block | P32: Below 100% costs money. Late transmission hits payment and Five-Star QM inputs at the same time. | Q32: {=IFERROR(INDEX('Benchmark Source Map'!$A$5:$A$13,MATCH(TRUE,(ISNUMBER(SEARCH('Benchmark Source Map'!$E$5:$E$13,$L32))+ISNUMBER(SEARCH('Benchmark Source Map'!$F$5:$F$13,$L32)))>0,0)),"Other named sources")} -> CMS and regulatory requirements (Five-Star Technical Users' Guide, RAI Manual, 42 CFR, Life Safety Code, state regulation)
A33: NUR-10 | B33: Nursing | C33: ARD and Late Assessment Rate | D33: Assessments with a late or defaulted Assessment Reference Date / total assessments | E33: Lower | I33: X | K33: SNF only | L33: CMS RAI Manual; PDPM default rate exposure | M33: Target 0%. Each late ARD defaults the stay to the lowest PDPM rate | N33: Clinical / EHR MDS report (Screen 09) | O33: MDS-derived and SNF only | P33: Pure unforced revenue loss: every late ARD defaults the stay to the lowest PDPM rate. A direct read on MDS staffing capacity. | Q33: {=IFERROR(INDEX('Benchmark Source Map'!$A$5:$A$13,MATCH(TRUE,(ISNUMBER(SEARCH('Benchmark Source Map'!$E$5:$E$13,$L33))+ISNUMBER(SEARCH('Benchmark Source Map'!$F$5:$F$13,$L33)))>0,0)),"Other named sources")} -> CMS and regulatory requirements (Five-Star Technical Users' Guide, RAI Manual, 42 CFR, Life Safety Code, state regulation)
A34: NUR-11 | B34: Nursing | C34: PDPM Case Mix Index by Component | D34: Case mix index computed for each PDPM component: PT, OT, SLP, Nursing, NTA | E34: Trend | I34: X | K34: SNF only | L34: CMS FY2024 SNF PPS Final Rule nursing CMIs (ES3 3.84 down to PA1 0.62) | M34: Compare to national and state PDPM CMI distribution | N34: Clinical / EHR MDS report (Screen 09) | O34: Same nursing CMI set CMS uses to case-mix adjust the Five-Star staffing measures, so it reads directly against SNF-S1 and SNF-S2 | P34: Reveals whether documentation matches the care actually delivered. A CMI well below the state distribution against visibly high acuity means under-documentation, not light residents. | Q34: {=IFERROR(INDEX('Benchmark Source Map'!$A$5:$A$13,MATCH(TRUE,(ISNUMBER(SEARCH('Benchmark Source Map'!$E$5:$E$13,$L34))+ISNUMBER(SEARCH('Benchmark Source Map'!$F$5:$F$13,$L34)))>0,0)),"Other named sources")} -> CMS and regulatory requirements (Five-Star Technical Users' Guide, RAI Manual, 42 CFR, Life Safety Code, state regulation)
A35: NUR-12 | B35: Nursing | C35: Care Plan Completion and Update Timeliness | D35: Comprehensive care plans completed within 7 days of the comprehensive assessment / plans due | E35: Higher | I35: X | K35: SNF only | L35: CMS 42 CFR 483.21 (F656) | M35: 100% | N35: Clinical / EHR report (Screen 09) | O35: SNF only. AL/MC equivalent is NUR-04 | P35: F656 exposure. Below 100% signals that admission volume has outrun clinical capacity. | Q35: {=IFERROR(INDEX('Benchmark Source Map'!$A$5:$A$13,MATCH(TRUE,(ISNUMBER(SEARCH('Benchmark Source Map'!$E$5:$E$13,$L35))+ISNUMBER(SEARCH('Benchmark Source Map'!$F$5:$F$13,$L35)))>0,0)),"Other named sources")} -> CMS and regulatory requirements (Five-Star Technical Users' Guide, RAI Manual, 42 CFR, Life Safety Code, state regulation)
A36: SNF-00 | B36: Skilled Nursing | C36: Overall Five-Star Rating | D36: Health inspection star as the base; +1 if staffing = 5 stars, -1 if staffing = 1 star; +1 if QM = 5 stars, -1 if QM = 1 star. Bounded 1-5 | E36: Higher | I36: X | K36: SNF only | L36: CMS Five-Star Technical Users Guide, September 2026 | M36: Caps: if health inspection = 1 star the overall cannot rise more than one star (max 2). Abuse icon caps health inspection at 2, so overall maxes at 4. Current SFF participants receive no ratings in any domain | N36: Tool-fetched from CMS. No operator upload | P36: The number families and referral sources actually see. One star of movement changes referral volume more than any marketing spend. | Q36: {=IFERROR(INDEX('Benchmark Source Map'!$A$5:$A$13,MATCH(TRUE,(ISNUMBER(SEARCH('Benchmark Source Map'!$E$5:$E$13,$L36))+ISNUMBER(SEARCH('Benchmark Source Map'!$F$5:$F$13,$L36)))>0,0)),"Other named sources")} -> CMS and regulatory requirements (Five-Star Technical Users' Guide, RAI Manual, 42 CFR, Life Safety Code, state regulation)
A37: SNF-01 | B37: Skilled Nursing | C37: Health Inspection Star Rating | D37: State percentile rank of the weighted health inspection score | E37: Higher | I37: X | K37: SNF only | L37: CMS TUG September 2026; state cut-point tables (August 2026) | M37: Top 10% of the state = 5 stars; middle 70% split into three bands of 23.33% = 4, 3, 2 stars; bottom 20% = 1 star. Recalibrated monthly | N37: Tool-fetched from CMS | P37: Relative, not absolute: it is a rank against other facilities in the same state, so standing still while the state improves is a decline. | Q37: {=IFERROR(INDEX('Benchmark Source Map'!$A$5:$A$13,MATCH(TRUE,(ISNUMBER(SEARCH('Benchmark Source Map'!$E$5:$E$13,$L37))+ISNUMBER(SEARCH('Benchmark Source Map'!$F$5:$F$13,$L37)))>0,0)),"Other named sources")} -> CMS and regulatory requirements (Five-Star Technical Users' Guide, RAI Manual, 42 CFR, Life Safety Code, state regulation)
A38: SNF-02 | B38: Skilled Nursing | C38: Staffing Star Rating | D38: Star assigned from the 380-point staffing score | E38: Higher | I38: X | K38: SNF only | L38: CMS TUG September 2026 Table 3 | M38: 1 star < 155 | 2 stars 155-204 | 3 stars 205-254 | 4 stars 255-319 | 5 stars 320-380 | N38: Tool-fetched from CMS PBJ | P38: Almost entirely a function of dollars committed to nursing hours. The most directly controllable of the three domains. | Q38: {=IFERROR(INDEX('Benchmark Source Map'!$A$5:$A$13,MATCH(TRUE,(ISNUMBER(SEARCH('Benchmark Source Map'!$E$5:$E$13,$L38))+ISNUMBER(SEARCH('Benchmark Source Map'!$F$5:$F$13,$L38)))>0,0)),"Other named sources")} -> CMS and regulatory requirements (Five-Star Technical Users' Guide, RAI Manual, 42 CFR, Life Safety Code, state regulation)
A39: SNF-03 | B39: Skilled Nursing | C39: Quality Measure Star Rating | D39: Star assigned from the combined long-stay and short-stay QM score; sub-ratings reported for each stay type | E39: Higher | I39: X | K39: SNF only | L39: CMS TUG September 2026 Table 5 (thresholds raised July 2026) | M39: Overall QM: 1 star 299-927 | 2 stars 928-1120 | 3 stars 1121-1299 | 4 stars 1300-1493 | 5 stars 1494-2300. Thresholds rise every six months by half the observed score gain; next increase expected January 2027 | N39: Tool-fetched from CMS | P39: Thresholds rise every six months by half the observed sector gain, so a flat score loses ground by design. | Q39: {=IFERROR(INDEX('Benchmark Source Map'!$A$5:$A$13,MATCH(TRUE,(ISNUMBER(SEARCH('Benchmark Source Map'!$E$5:$E$13,$L39))+ISNUMBER(SEARCH('Benchmark Source Map'!$F$5:$F$13,$L39)))>0,0)),"Other named sources")} -> CMS and regulatory requirements (Five-Star Technical Users' Guide, RAI Manual, 42 CFR, Life Safety Code, state regulation)
A40: SNF-H1 | B40: Skilled Nursing | C40: Weighted Health Inspection Score | D40: Cycle 1 points x 0.75 + cycle 2 points x 0.25, where each cycle sums standard, complaint, infection control and revisit points | E40: Lower | I40: X | K40: SNF only | L40: CMS TUG September 2026 | M40: Two standard survey cycles only, weighted 3/4 and 1/4. Cycle 3 is still displayed on Care Compare but is no longer scored (changed July 2025 from three cycles at 1/2, 1/3, 1/6) | N40: Tool-fetched from CMS | O40: CORRECTION from v8: the 50/33/17 three-cycle weighting is obsolete as of the July 2025 refresh | P40: Concentrates 75% of the weight on the most recent cycle - one bad recent survey outweighs two clean older ones. | Q40: {=IFERROR(INDEX('Benchmark Source Map'!$A$5:$A$13,MATCH(TRUE,(ISNUMBER(SEARCH('Benchmark Source Map'!$E$5:$E$13,$L40))+ISNUMBER(SEARCH('Benchmark Source Map'!$F$5:$F$13,$L40)))>0,0)),"Other named sources")} -> CMS and regulatory requirements (Five-Star Technical Users' Guide, RAI Manual, 42 CFR, Life Safety Code, state regulation)
A41: SNF-H2 | B41: Skilled Nursing | C41: Standard Survey Deficiency Points by Scope and Severity | D41: Sum of Table 1 point values for every cited deficiency on the two most recent standard surveys | E41: Lower | I41: X | K41: SNF only | L41: CMS TUG September 2026 Table 1 | M41: A/B/C 0 | D 4 | E 8 | F 16 (20 if SQC) | G 20 | H 35 (40) | I 45 (50) | J 50 (75) | K 100 (125) | L 150 (175). Past non-compliance at J/K/L scores at the G value of 20 | N41: Tool-fetched from CMS | P41: Scope and severity drive the score, not the count. Ten D-level tags cost less than a single G. | Q41: {=IFERROR(INDEX('Benchmark Source Map'!$A$5:$A$13,MATCH(TRUE,(ISNUMBER(SEARCH('Benchmark Source Map'!$E$5:$E$13,$L41))+ISNUMBER(SEARCH('Benchmark Source Map'!$F$5:$F$13,$L41)))>0,0)),"Other named sources")} -> CMS and regulatory requirements (Five-Star Technical Users' Guide, RAI Manual, 42 CFR, Life Safety Code, state regulation)
...

Sheet SNF Five-Star Coverage
A1: CMS Five-Star Coverage Check
A2: Verified against the CMS Five-Star Quality Rating System Technical Users Guide, September 2026 (retrieved 2026-09-22). Every contributing component is mapped to a v9 code.
A4: Domain | B4: Contributing Component | C4: v9 Code | D4: Weight or Points | E4: Note
A5: Overall | B5: Composite of the three domain stars | C5: SNF-00 | D5: Health inspection base, +/-1 for staffing, +/-1 for QM | E5: If health inspection is 1 star the overall cannot rise above 2. Abuse icon caps the overall at 4.
A6: Domain 1 Health Inspection | B6: Domain star rating | C6: SNF-01 | D6: State percentile: top 10% = 5 stars, bottom 20% = 1 star | E6: Middle 70% split into three bands of 23.33%. Recalibrated monthly.
A7: Domain 1 Health Inspection | B7: Weighted health inspection score | C7: SNF-H1 | D7: Cycle 1 x 3/4 + cycle 2 x 1/4 | E7: Two cycles only since the July 2025 refresh. Cycle 3 is displayed but not scored.
A8: Domain 1 Health Inspection | B8: Standard survey deficiency points | C8: SNF-H2 | D8: Table 1 scale, D=4 through L=150 (175 with SQC) | E8: Past non-compliance at J/K/L scores at the G value of 20.
A9: Domain 1 Health Inspection | B9: Complaint survey deficiency points | C9: SNF-H3 | D9: 36 months, 0-12 mo at 3/4 and 13-36 mo at 1/4 | E9: Deduplicated against recertification citations within 15 days.
A10: Domain 1 Health Inspection | B10: Focused infection control survey points | C10: SNF-H4 | D10: 36 months, same 3/4 and 1/4 weighting | E10: Where an ICS citation overlaps another within 15 days, only the ICS citation counts.
A11: Domain 1 Health Inspection | B11: Revisit points | C11: SNF-H5 | D11: 1st 0, 2nd 50%, 3rd 70%, 4th 85% of cycle score
A12: Domain 1 Health Inspection | B12: Substandard quality of care citations | C12: SNF-H6 | D12: Raises point values at F, H, I, J, K, L | E12: No separate cap. G has no SQC variant.
A13: Domain 1 Health Inspection | B13: Immediate jeopardy citations | C13: SNF-H7 | D13: Enters only through J, K, L point values | E13: No separate cap or downgrade.
A14: Domain 1 Health Inspection | B14: Abuse icon | C14: SNF-H8 | D14: Caps health inspection at 2 stars | E14: Set from F600, F602, F603 citations. Caps overall at 4 stars.
A15: Domain 1 Health Inspection | B15: Special Focus Facility status | C15: SNF-H9 | D15: SFF participants receive no ratings at all | E15: SFF candidates are rated normally.
A16: Domain 2 Staffing | B16: Domain star rating | C16: SNF-02 | D16: 380-point scale: 5 stars at 320-380, 1 star below 155
A17: Domain 2 Staffing | B17: Case-mix adjusted total nurse HPRD | C17: SNF-S1 | D17: 100 points, deciles | E17: Case-mix adjusted on PDPM nursing CMIs from the FY2024 SNF PPS Final Rule, not RUG-IV.
A18: Domain 2 Staffing | B18: Case-mix adjusted RN HPRD | C18: SNF-S2 | D18: 100 points, deciles | E18: Job codes 5, 6, 7.
A19: Domain 2 Staffing | B19: Case-mix adjusted weekend total nurse HPRD | C19: SNF-S3 | D19: 50 points, deciles | E19: Saturdays and Sundays.
A20: Domain 2 Staffing | B20: Total nurse staffing turnover | C20: SNF-S4 | D20: 50 points, deciles | E20: Requires six consecutive quarters of PBJ. 90-day zero-hours gap definition.
A21: Domain 2 Staffing | B21: RN turnover | C21: SNF-S5 | D21: 50 points, deciles | E21: ADDED in v9. This measure was absent from the v8 catalog.
A22: Domain 2 Staffing | B22: Administrator departures | C22: SNF-S6 | D22: 30 points: 0 departures = 30, 1 = 25, 2+ = 10 | E22: Job code 1.
A23: Domain 2 Staffing | B23: Scoring exceptions | C23: SNF-S7 | D23: Automatic 1 star | E23: Non-submission by the 45-day deadline; 4+ days with zero RN hours; failed or unanswered PBJ audit.
A24: Domain 3 QM | B24: Domain star rating | C24: SNF-03 | D24: Overall QM 299-2,300; 5 stars at 1,494+ | E24: Long-stay 155-1,150; short-stay rescaled by 1,150/800 to 144-1,150.
A25: Domain 3 QM Long-Stay | B25: Need for help with daily activities has increased | C25: SNF-Q1 | D25: 150 points, deciles | E25: MDS-based.
A26: Domain 3 QM Long-Stay | B26: Ability to walk independently worsened | C26: SNF-Q2 | D26: 150 points, deciles | E26: MDS, risk-adjusted. Respecified January 2025 from 'move independently'.
A27: Domain 3 QM Long-Stay | B27: Residents with pressure ulcers | C27: SNF-Q3 | D27: 100 points, quintiles | E27: MDS, risk-adjusted. Respecified January 2025 from high-risk-only to all residents.
A28: Domain 3 QM Long-Stay | B28: Catheter inserted and left in bladder | C28: SNF-Q4 | D28: 100 points, quintiles | E28: MDS, risk-adjusted.
... A45: REMOVED from v8 | B45: Short-stay self-report moderate to severe pain | C45: none | D45: Retired by CMS October 2019 | E45: Was carried in the v8 catalog as SNF-5.04. Must be removed.

Sheet SBC Boundary
A1: Staffing Base Calculator Boundary
A2: The SBC owns staffing efficiency at every level of care. No KPI duplicates an SBC output. One deliberate exception is noted at the bottom.
A4: SBC Output (excluded from the KPI set) | B4: Why the SBC owns it | C4: What the KPI set measures instead
A5: FTEs per occupied unit, by department | B5: SBC computes recommended FTE by level of care and reports variance to current | C5: No KPI
A6: CNA and nurse HPPD for AL and MC | B6: SBC derives AL/MC HPPD from the three-shift ratio model (AL 12/15/20, MC 8/8/12) | C6: No KPI
A7: Meals per labor hour (MPLH) | B7: SBC dining model, target MPLH IL 2.2 / AL 2.5 / MC 3.0 / SNF 3.5 | C7: DIN-01 and DIN-02 measure cost, not productivity
A8: Housekeeping square feet per FTE | B8: SBC housekeeping model: IL 25,000 / AL 20,000 / MC 8,000 / SNF 8,000 sq ft per FTE | C8: No KPI
A9: Laundry pounds per labor hour | B9: SBC laundry model at 50 lbs/hr processing rate | C9: No KPI
A10: Security coverage hours | B10: SBC coverage schedule model, gated on CCRC registration or optional security | C10: No KPI
A11: Plant ops FTE per square foot | B11: SBC plant model: campus square footage / 50,000 | C11: PLT-03 measures labor hours per resident unit, which is work volume rather than headcount
A12: Variance of current staffing to recommended | B12: SBC variance columns for rental and entrance fee scenarios | C12: No KPI
A13: SNF RN HPRD, total nurse HPRD, weekend HPRD | B13: EXCEPTION. These stay in the SNF block as SNF-S1, SNF-S2 and SNF-S3 | C13: These are CMS Five-Star rating inputs computed from PBJ, not outputs of the SBC staffing model. They are scored because they move the star rating

Sheet Care Level Filter
A1: Care Level Filter - what an operator actually gets
A2: KPI counts by department for the care level combinations an operator can select on Community Profile (Screen 03).
A4: Care Levels Selected | B4: Operations | C4: Sales and Marketing | D4: Nursing | E4: Skilled Nursing | F4: Finance | G4: Human Resources | H4: Plant and Maintenance | I4: Life Enrichment | J4: Dining Services | K4: TOTAL
A5: IL only | B5: 8 | C5: 9 | D5: 0 | E5: 0 | F5: 6 | G5: 10 | H5: 10 | I5: 5 | J5: 5 | K5: 53
A6: AL only | B6: 8 | C6: 9 | D6: 8 | E6: 0 | F6: 6 | G6: 10 | H6: 10 | I6: 5 | J6: 7 | K6: 63
A7: MC only | B7: 8 | C7: 9 | D7: 8 | E7: 0 | F7: 6 | G7: 10 | H7: 10 | I7: 6 | J7: 7 | K7: 64
A8: SNF only | B8: 7 | C8: 1 | D8: 5 | E8: 36 | F8: 4 | G8: 10 | H8: 9 | I8: 4 | J8: 6 | K8: 82
A9: AL + MC | B9: 8 | C9: 9 | D9: 8 | E9: 0 | F9: 6 | G9: 10 | H9: 10 | I9: 6 | J9: 7 | K9: 64
A10: IL + AL + MC | B10: 8 | C10: 9 | D10: 8 | E10: 0 | F10: 6 | G10: 10 | H10: 10 | I10: 6 | J10: 7 | K10: 64
A11: AL + MC + SNF | B11: 8 | C11: 9 | D11: 12 | E11: 36 | F11: 6 | G11: 10 | H11: 10 | I11: 6 | J11: 7 | K11: 104
A12: IL + AL + MC + SNF | B12: 8 | C12: 9 | D12: 12 | E12: 36 | F12: 6 | G12: 10 | H12: 10 | I12: 6 | J12: 7 | K12: 104
A13: CCRC (all + entity) | B13: 8 | C13: 9 | D13: 12 | E13: 36 | F13: 10 | G13: 10 | H13: 10 | I13: 6 | J13: 7 | K13: 108
A15: A standalone SNF scores 36 CMS measures plus the universal people, plant, life enrichment and dining measures, plus the SNF-only MDS block. It does NOT receive Days Cash on Hand, Debt Service Coverage or any other entity balance-sheet measure, and it does not receive the Aline sales funnel.
A16: An IL-only community scores no nursing measures at all and no care-delivering dining measures. The AL/MC clinical block is fully suppressed.
A17: General entity measures (Days in AR, Average Age of Plant) switch on whenever a trial balance or balance sheet is uploaded (Screen 07). The four CCRC-gated entity measures - Entity Operating Margin, Days Cash on Hand, Debt Service Coverage and Entrance Fee Refund Funding - stay suppressed unless a CCRC or Life Plan entity is designated, because both their construct and their CARF / RC 2025 benchmarks are CCRC specific.
A18: Universal (yellow) measures are in scope for every combination above. There are 32 of them.

Sheet Retired from v8
A1: Retired, Merged and Relocated from v8
A2: 37 v8 entries are removed, merged or moved. Codes below are v8 codes and do not correspond to v9 codes of the same name.
A4: v8 Code | B4: v8 KPI | C4: Disposition in v9
A5: OPS-05 | B5: Resident Engagement Index | C5: Folded into LE-01 weekly participation and OPS-05 resident satisfaction. A composite index is not a measured data point
A6: OPS-10 | B6: Move-Out Reason Distribution | C6: No benchmark exists for the reason breakdown. Belongs in the report narrative as analysis, not in the KPI set
A7: SAL-01 | B7: Lead Volume by Source | C7: Split into SAL-01 (volume, Aline-benchmarked) and SAL-06 (channel mix, Aline-benchmarked)
A8: SAL-04 | B8: Deposit-to-Move-In Conversion Rate | C8: Aline does not benchmark this step. The funnel is fully covered by SAL-04 and SAL-05 || SUPERSEDED 22 Sep 2026: reinstated in the live catalog as SAL-10 Deposit-to-Move-In Conversion Rate, benchmarked to Rob Clark and Kushant Shah at 80-90% rather than to Aline, so the original rationale no longer applies. The Gap Matrix v9 workbook never retired this measure - it carries the same Aline observation as the reason to use an internal standard. Do not read this entry as excluding the measure.
A9: SAL-05 | B9: Inquiry-to-Move-In Conversion Rate | C9: Arithmetic product of SAL-04 and SAL-05. Redundant
A10: SAL-06 | B10: Active Pipeline Depth by Stage | C10: No published benchmark. Operator target only
A11: SAL-07 | B11: Referral Source Mix and Conversion | C11: Replaced by SAL-06 (mix) and SAL-07 (conversion by channel), both on Aline data
A12: NUR-01 | B12: MDS Assessment Completion Timeliness | C12: Retained but rescoped to SNF only as NUR-09
A13: NUR-02 | B13: ARD Accuracy Rate | C13: Retained but rescoped to SNF only as NUR-10
A14: NUR-03 | B14: Care Plan Completion and Update Timeliness | C14: Retained but rescoped to SNF only as NUR-12
A15: NUR-07 | B15: 30-Day Hospital Readmission Rate | C15: AL/MC replaced by NUR-03 unplanned transfer rate. SNF is covered by CMS QMs SNF-Q8, Q9, Q13, Q14
... A41: DIN-10 | B41: Cost per Meal Served | C41: Derived from DIN-01 and DIN-02, and brushes the SBC meals-per-labor-hour model
A43: Removed after v9 publication
A44: v9 Code | B44: v9 KPI | C44: Disposition
A45: LE-03 | B45: Memory Care Structured Engagement Hours per Resident per Day | C45: DELETED 22 Sep 2026. The 4-6 hour target could not be sourced: the row cited the Alzheimer's Association with no title, year or page, and no link existed in this workbook or in the Gap Matrix v9. The Gap Matrix recorded the same measure as 4-6 hours per WEEK on a Rob Clark internal standard and noted that the Alzheimer's Association publishes dementia care practice recommendations, not an hours-per-resident benchmark - a 7x ambiguity with no documented basis either way. The owner already holds a life enrichment staffing coverage expectation, now carried as LE-06 Life Enrichment Programming Coverage (minimum 8 hours per day, 7 days per week, Rob Clark). LE-04 to LE-07 were renumbered to LE-03 to LE-06. Consequence to note: no per-resident engagement INTENSITY measure now exists - LE-06 measures availability, LE-01 measures attendance. If an intensity measure is wanted later it needs a real citation first.

Sheet Benchmark Source Map
A1: Benchmark Source Map
A2: Which published source sets the target for which department and care level.
A4: Source | B4: Applies To | C4: Supplies | D4: Vintage / Note | E4: Match Key | F4: Alt Match Key | G4: KPIs Mapped | H4: KPI Codes | I4: Where the Data Is Found (Gap Matrix v9)
A5: State of Seniors Housing (SOSH) 2025 | B5: IL, AL, MC, CCRC | C5: Occupancy, annual turnover, revenue and expense per occupied unit, labor percent of revenue, community operating margin, dietary cost per resident day, workers compensation percent of wages | D5: 2025 edition. All dollar measures pass through the CPI toggle. | E5: SOSH | F5: State of Seniors | G5: {=SUMPRODUCT(--((ISNUMBER(SEARCH($E5,'KPI Catalog'!$L$5:$L$119))+ISNUMBER(SEARCH($F5,'KPI Catalog'!$L$5:$L$119)))>0))} -> 14 | H5: {=_xlfn.TEXTJOIN(", ",TRUE,IF((ISNUMBER(SEARCH($E5,'KPI Catalog'!$L$5:$L$119))+ISNUMBER(SEARCH($F5,'KPI Catalog'!$L$5:$L$119)))>0,'KPI Catalog'!$A$5:$A$119,""))} -> OPS-01, OPS-03, OPS-04, SAL-08, NUR-05, FIN-01, FIN-03, FIN-04, FIN-05, FIN-06, HR-05, HR-10, DIN-01, DIN-02 | I5: Gap Matrix v9: 'Benchmark Sources' row 6 (name A6, link I6). Link: https://ashaliving.org/research-and-analytics/ - publisher landing page, NOT a deep link; report is purchasable (ASHA member or paid). Locations cited: Tables 2.7, 2.15, 2.18-2.19, 3.1-3.7, 3.20-3.21, 3.22-3.24, 3.27, 4.1. URL verified 22 Sep 2026. Matrix does not hold the PDF.
