Workbook

Sheet KPI_Master
A1: Sr. No. | B1: KPI ID | C1: Department | D1: KPI Name | E1: Formula | F1: Source System | G1: Source Documents / Records | H1: Frequency | I1: Direction | J1: Dashboard Tier | K1: Adoption Priority | L1: Priority Rationale | M1: Found in Other Files
A2: 1 | B2: DINF-01 | C2: Dining / Food Service | D2: Raw Food Cost per Resident Day (PRD) | E2: Total Raw Food Purchase Cost / Total Resident Days | F2: Dining/Food service system, Finance GL | G2: Vendor invoices; Inventory count sheets; Daily census report | H2: Monthly | I2: Lower is better | J2: Executive | K2: 1 - Core | L2: Largest controllable non-labour cost | M2: Both files
A3: 2 | B3: DINF-02 | C3: Dining / Food Service | D3: Total Dining Cost per Resident Day | E3: (Food Cost + Dining Labor + Supplies) / Total Resident Days | F3: Finance GL, Payroll | G3: GL department expense report; Payroll register; Census report | H3: Monthly | I3: Lower is better | J3: Executive | K3: 2 - Standard | L3: Explains movement in a Tier 1 KPI - add in phase 2 | M3: Both files
A4: 3 | B4: DINF-03 | C4: Dining / Food Service | D4: Dining Labor as % of Dining Expense | E4: (Dining Labor Cost / Total Dining Department Cost) * 100 | F4: Payroll, Finance GL | G4: Payroll register; Department P&L | H4: Monthly | I4: Lower is better | J4: Operational | K4: 2 - Standard | L4: Explains movement in a Tier 1 KPI - add in phase 2 | M4: Cross-Source only
A5: 4 | B5: DINF-04 | C5: Dining / Food Service | D5: Meal Participation Rate | E5: (Meals Actually Served / Meals Forecast for Census) * 100 | F5: Dining POS / meal tracking system | G5: Meal count sheets; POS transaction log; Census report | H5: Weekly | I5: Higher is better | J5: Operational | K5: 2 - Standard | L5: Explains movement in a Tier 1 KPI - add in phase 2 | M5: Advantedge only
A6: 5 | B6: DINF-06 | C6: Dining / Food Service | D6: Resident Dining Satisfaction Score | E6: Sum of Dining Satisfaction Ratings / Number of Responses | F6: Survey platform, Resident engagement system | G6: Resident satisfaction survey; Food committee minutes; Comment cards | H6: Quarterly | I6: Higher is better | J6: Executive | K6: 1 - Core | L6: Drives referrals and retention | M6: Advantedge only
A7: 6 | B7: DINF-07 | C7: Dining / Food Service | D7: Therapeutic Diet Accuracy Rate | E7: (Trays Matching Prescribed Diet Order / Total Trays Audited) * 100 | F7: PCC (diet orders), Dining system | G7: Diet order report; Tray line audit sheet; Dietitian audit log | H7: Monthly | I7: Higher is better | J7: Operational | K7: 2 - Standard | L7: Explains movement in a Tier 1 KPI - add in phase 2 | M7: Advantedge only
A8: 7 | B8: DINF-08 | C8: Dining / Food Service | D8: Food Safety / Sanitation Audit Score | E8: (Points Earned on Sanitation Audit / Total Possible Points) * 100 | F8: Compliance/QAPI system | G8: Health department inspection report; Internal sanitation audit; Temperature logs | H8: Monthly | I8: Higher is better | J8: Operational | K8: 2 - Standard | L8: Explains movement in a Tier 1 KPI - add in phase 2 | M8: Advantedge only
A9: 8 | B9: DINF-12 | C9: Dining / Food Service | D9: Nutritional Assessment Completion Rate | E9: (Nutritional Assessments Completed On Time / Nutritional Assessments Due) * 100 | F9: PCC (dietitian assessments), Dining system | G9: Dietitian assessment records; MDS Section K; Admission nutrition screen | H9: Monthly | I9: Higher is better | J9: Operational | K9: 2 - Standard | L9: Regulatory - survey exposure (F-692) | M9: Advantedge KPI Matrix v8
A10: 9 | B10: DINF-13 | C10: Dining / Food Service | D10: Hydration Monitoring Compliance Rate | E10: (At-Risk Residents Monitored per Protocol / Residents Requiring Hydration Monitoring) * 100 | F10: PCC, Dining system | G10: Intake & output records; Hydration risk list; Care plans | H10: Monthly | I10: Higher is better | J10: Operational | K10: 2 - Standard | L10: Regulatory - survey exposure (F-692) | M10: Advantedge KPI Matrix v8
A11: 10 | B11: DINF-14 | C11: Dining / Food Service | D11: Raw Food Cost per Meal | E11: Total Raw Food Purchase Cost / Total Meals Served | F11: Dining/Food service system, Finance GL | G11: Food purchase invoices; Meal count / POS report | H11: Monthly | I11: Target range | J11: Operational | K11: 2 - Standard | L11: Largest controllable non-labour cost (per-meal view of DINF-01) | M11: Cross-Source Benchmark 2025
A12: 11 | B12: DINF-15 | C12: Dining / Food Service | D12: Meals per Labor Hour | E12: Total Meals Served / Total Dining Labor Hours | F12: Payroll / Time & Attendance, Dining POS | G12: Dining timecards; Meal count / POS report | H12: Monthly | I12: Higher is better | J12: Operational | K12: 2 - Standard | L12: Explains movement in a Tier 1 KPI - add in phase 2 (DINF-03) | M12: Cross-Source Benchmark 2025
A13: 12 | B13: FINA-01 | C13: Finance / Accounting | D13: Occupancy Rate | E13: (Occupied Units / Total Available Units) * 100 | F13: CRM, Finance / Billing system | G13: Daily census report; Unit inventory schedule; Rent roll | H13: Daily | I13: Higher is better | J13: Executive | K13: 1 - Core | L13: The single number the business runs on | M13: Both files
... A172: 171 | B172: TRA-07 | C172: Transportation | D172: Vehicle Preventive Maintenance Compliance | E172: (Vehicle PM Services Completed On Time / PM Services Due) * 100 | F172: MicroMain CMMS, Fleet records | G172: Vehicle service records; Fleet PM schedule | H172: Quarterly | I172: Higher is better | J172: Operational | K172: 2 - Standard | L172: Explains movement in a Tier 1 KPI - add in phase 2 | M172: Advantedge only

Sheet Common_Formula_Elements
A1: Common Formula Elements - which formula inputs are shared, and by which Sr. Nos.
A2: Each row is one input that appears in KPI formulas. "Used in Sr. No." lists the KPI_Master serial numbers that use it. Each element is fed by ONE document (column G, blue = editable). Change a Doc ID here and the map, matrix and document counts all update. Click any Sr. No. in columns J onward to jump straight to that KPI's row (formula, sources, documents) in KPI_Master.
A4: Element ID | B4: Common Data Element (formula input) | C4: Standard Definition (use the same everywhere) | D4: Used in Sr. No. | E4: No. of KPIs Using It | F4: Of which Tier 1 - Core | G4: Doc ID | H4: Single Source Document | J4: Go to KPI_Master - click a Sr. No. to jump to that KPI row
A5: E01 | B5: Total Resident Days | C5: Sum of daily (midnight) census over the period | D5: {=_xlfn.TEXTJOIN(", ",TRUE(),IF(KPI_Element_Map!$E$2:$E$287=$A5,KPI_Element_Map!$A$2:$A$287,""))} -> 1, 2, 4, 22, 52, 81, 84, 87, 88, 89, 95, 98, 115, 144, 169 | E5: =COUNTIF(KPI_Element_Map!$E$2:$E$287,$A5) -> 15 | F5: =COUNTIFS(KPI_Element_Map!$E$2:$E$287,$A5,KPI_Element_Map!$D$2:$D$287,"1 - Core") -> 3 | G5: D01 | H5: =INDEX(Minimum_Documents!$B:$B,MATCH($G5,Minimum_Documents!$A:$A,0)) -> Census & ADT Register | J5: {=IFERROR(HYPERLINK("#KPI_Master!A"&MATCH(SMALL(IF(KPI_Element_Map!$E$2:$E$287=$A5,KPI_Element_Map!$A$2:$A$287),COLUMNS($J5:J5)),KPI_Master!$A:$A,0)&":P"&MATCH(SMALL(IF(KPI_Element_Map!$E$2:$E$287=$A5,KPI_Element_Map!$A$2:$A$287),COLUMNS($J5:J5)),KPI_Master!$A:$A,0),SMALL(IF(KPI_Element_Map!$E$2:$E$287=$A5,KPI_Element_Map!$A$2:$A$287),COLUMNS($J5:J5))),"")} -> 1 | K5: {=IFERROR(HYPERLINK("#KPI_Master!A"&MATCH(SMALL(IF(KPI_Element_Map!$E$2:$E$287=$A5,KPI_Element_Map!$A$2:$A$287),COLUMNS($J5:K5)),KPI_Master!$A:$A,0)&":P"&MATCH(SMALL(IF(KPI_Element_Map!$E$2:$E$287=$A5,KPI_Element_Map!$A$2:$A$287),COLUMNS($J5:K5)),KPI_Master!$A:$A,0),SMALL(IF(KPI_Element_Map!$E$2:$E$287=$A5,KPI_Element_Map!$A$2:$A$287),COLUMNS($J5:K5))),"")} -> 2 | L5: {=IFERROR(HYPERLINK("#KPI_Master!A"&MATCH(SMALL(IF(KPI_Element_Map!$E$2:$E$287=$A5,KPI_Element_Map!$A$2:$A$287),COLUMNS($J5:L5)),KPI_Master!$A:$A,0)&":P"&MATCH(SMALL(IF(KPI_Element_Map!$E$2:$E$287=$A5,KPI_Element_Map!$A$2:$A$287),COLUMNS($J5:L5)),KPI_Master!$A:$A,0),SMALL(IF(KPI_Element_Map!$E$2:$E$287=$A5,KPI_Element_Map!$A$2:$A$287),COLUMNS($J5:L5))),"")} -> 4 | M5: {=IFERROR(HYPERLINK("#KPI_Master!A"&MATCH(SMALL(IF(KPI_Element_Map!$E$2:$E$287=$A5,KPI_Element_Map!$A$2:$A$287),COLUMNS($J5:M5)),KPI_Master!$A:$A,0)&":P"&MATCH(SMALL(IF(KPI_Element_Map!$E$2:$E$287=$A5,KPI_Element_Map!$A$2:$A$287),COLUMNS($J5:M5)),KPI_Master!$A:$A,0),SMALL(IF(KPI_Element_Map!$E$2:$E$287=$A5,KPI_Element_Map!$A$2:$A$287),COLUMNS($J5:M5))),"")} -> 22 | N5: {=IFERROR(HYPERLINK("#KPI_Master!A"&MATCH(SMALL(IF(KPI_Element_Map!$E$2:$E$287=$A5,KPI_Element_Map!$A$2:$A$287),COLUMNS($J5:N5)),KPI_Master!$A:$A,0)&":P"&MATCH(SMALL(IF(KPI_Element_Map!$E$2:$E$287=$A5,KPI_Element_Map!$A$2:$A$287),COLUMNS($J5:N5)),KPI_Master!$A:$A,0),SMALL(IF(KPI_Element_Map!$E$2:$E$287=$A5,KPI_Element_Map!$A$2:$A$287),COLUMNS($J5:N5))),"")} -> 52 | O5: {=IFERROR(HYPERLINK("#KPI_Master!A"&MATCH(SMALL(IF(KPI_Element_Map!$E$2:$E$287=$A5,KPI_Element_Map!$A$2:$A$287),COLUMNS($J5:O5)),KPI_Master!$A:$A,0)&":P"&MATCH(SMALL(IF(KPI_Element_Map!$E$2:$E$287=$A5,KPI_Element_Map!$A$2:$A$287),COLUMNS($J5:O5)),KPI_Master!$A:$A,0),SMALL(IF(KPI_Element_Map!$E$2:$E$287=$A5,KPI_Element_Map!$A$2:$A$287),COLUMNS($J5:O5))),"")} -> 81 | P5: {=IFERROR(HYPERLINK("#KPI_Master!A"&MATCH(SMALL(IF(KPI_Element_Map!$E$2:$E$287=$A5,KPI_Element_Map!$A$2:$A$287),COLUMNS($J5:P5)),KPI_Master!$A:$A,0)&":P"&MATCH(SMALL(IF(KPI_Element_Map!$E$2:$E$287=$A5,KPI_Element_Map!$A$2:$A$287),COLUMNS($J5:P5)),KPI_Master!$A:$A,0),SMALL(IF(KPI_Element_Map!$E$2:$E$287=$A5,KPI_Element_Map!$A$2:$A$287),COLUMNS($J5:P5))),"")} -> 84 | Q5: {=IFERROR(HYPERLINK("#KPI_Master!A"&MATCH(SMALL(IF(KPI_Element_Map!$E$2:$E$287=$A5,KPI_Element_Map!$A$2:$A$287),COLUMNS($J5:Q5)),KPI_Master!$A:$A,0)&":P"&MATCH(SMALL(IF(KPI_Element_Map!$E$2:$E$287=$A5,KPI_Element_Map!$A$2:$A$287),COLUMNS($J5:Q5)),KPI_Master!$A:$A,0),SMALL(IF(KPI_Element_Map!$E$2:$E$287=$A5,KPI_Element_Map!$A$2:$A$287),COLUMNS($J5:Q5))),"")} -> 87 | ... AH5: {=IFERROR(HYPERLINK("#KPI_Master!A"&MATCH(SMALL(IF(KPI_Element_Map!$E$2:$E$287=$A5,KPI_Element_Map!$A$2:$A$287),COLUMNS($J5:AH5)),KPI_Master!$A:$A,0)&":P"&MATCH(SMALL(IF(KPI_Element_Map!$E$2:$E$287=$A5,KPI_Element_Map!$A$2:$A$287),COLUMNS($J5:AH5)),KPI_Master!$A:$A,0),SMALL(IF(KPI_Element_Map!$E$2:$E$287=$A5,KPI_Element_Map!$A$2:$A$287),COLUMNS($J5:AH5))),"")}
A6: E02 | B6: Occupied Units / Beds | C6: Average occupied units (or beds) for the period, from daily census | D6: {=_xlfn.TEXTJOIN(", ",TRUE(),IF(KPI_Element_Map!$E$2:$E$287=$A6,KPI_Element_Map!$A$2:$A$287,""))} -> 12, 13, 24, 25, 78, 113, 153, 159, 160 | E6: =COUNTIF(KPI_Element_Map!$E$2:$E$287,$A6) -> 9 | F6: =COUNTIFS(KPI_Element_Map!$E$2:$E$287,$A6,KPI_Element_Map!$D$2:$D$287,"1 - Core") -> 3 | G6: D01 | H6: =INDEX(Minimum_Documents!$B:$B,MATCH($G6,Minimum_Documents!$A:$A,0)) -> Census & ADT Register | J6: {=IFERROR(HYPERLINK("#KPI_Master!A"&MATCH(SMALL(IF(KPI_Element_Map!$E$2:$E$287=$A6,KPI_Element_Map!$A$2:$A$287),COLUMNS($J6:J6)),KPI_Master!$A:$A,0)&":P"&MATCH(SMALL(IF(KPI_Element_Map!$E$2:$E$287=$A6,KPI_Element_Map!$A$2:$A$287),COLUMNS($J6:J6)),KPI_Master!$A:$A,0),SMALL(IF(KPI_Element_Map!$E$2:$E$287=$A6,KPI_Element_Map!$A$2:$A$287),COLUMNS($J6:J6))),"")} -> 12 | K6: {=IFERROR(HYPERLINK("#KPI_Master!A"&MATCH(SMALL(IF(KPI_Element_Map!$E$2:$E$287=$A6,KPI_Element_Map!$A$2:$A$287),COLUMNS($J6:K6)),KPI_Master!$A:$A,0)&":P"&MATCH(SMALL(IF(KPI_Element_Map!$E$2:$E$287=$A6,KPI_Element_Map!$A$2:$A$287),COLUMNS($J6:K6)),KPI_Master!$A:$A,0),SMALL(IF(KPI_Element_Map!$E$2:$E$287=$A6,KPI_Element_Map!$A$2:$A$287),COLUMNS($J6:K6))),"")} -> 13 | L6: {=IFERROR(HYPERLINK("#KPI_Master!A"&MATCH(SMALL(IF(KPI_Element_Map!$E$2:$E$287=$A6,KPI_Element_Map!$A$2:$A$287),COLUMNS($J6:L6)),KPI_Master!$A:$A,0)&":P"&MATCH(SMALL(IF(KPI_Element_Map!$E$2:$E$287=$A6,KPI_Element_Map!$A$2:$A$287),COLUMNS($J6:L6)),KPI_Master!$A:$A,0),SMALL(IF(KPI_Element_Map!$E$2:$E$287=$A6,KPI_Element_Map!$A$2:$A$287),COLUMNS($J6:L6))),"")} -> 24 | M6: {=IFERROR(HYPERLINK("#KPI_Master!A"&MATCH(SMALL(IF(KPI_Element_Map!$E$2:$E$287=$A6,KPI_Element_Map!$A$2:$A$287),COLUMNS($J6:M6)),KPI_Master!$A:$A,0)&":P"&MATCH(SMALL(IF(KPI_Element_Map!$E$2:$E$287=$A6,KPI_Element_Map!$A$2:$A$287),COLUMNS($J6:M6)),KPI_Master!$A:$A,0),SMALL(IF(KPI_Element_Map!$E$2:$E$287=$A6,KPI_Element_Map!$A$2:$A$287),COLUMNS($J6:M6))),"")} -> 25 | N6: {=IFERROR(HYPERLINK("#KPI_Master!A"&MATCH(SMALL(IF(KPI_Element_Map!$E$2:$E$287=$A6,KPI_Element_Map!$A$2:$A$287),COLUMNS($J6:N6)),KPI_Master!$A:$A,0)&":P"&MATCH(SMALL(IF(KPI_Element_Map!$E$2:$E$287=$A6,KPI_Element_Map!$A$2:$A$287),COLUMNS($J6:N6)),KPI_Master!$A:$A,0),SMALL(IF(KPI_Element_Map!$E$2:$E$287=$A6,KPI_Element_Map!$A$2:$A$287),COLUMNS($J6:N6))),"")} -> 78 | O6: {=IFERROR(HYPERLINK("#KPI_Master!A"&MATCH(SMALL(IF(KPI_Element_Map!$E$2:$E$287=$A6,KPI_Element_Map!$A$2:$A$287),COLUMNS($J6:O6)),KPI_Master!$A:$A,0)&":P"&MATCH(SMALL(IF(KPI_Element_Map!$E$2:$E$287=$A6,KPI_Element_Map!$A$2:$A$287),COLUMNS($J6:O6)),KPI_Master!$A:$A,0),SMALL(IF(KPI_Element_Map!$E$2:$E$287=$A6,KPI_Element_Map!$A$2:$A$287),COLUMNS($J6:O6))),"")} -> 113 | P6: {=IFERROR(HYPERLINK("#KPI_Master!A"&MATCH(SMALL(IF(KPI_Element_Map!$E$2:$E$287=$A6,KPI_Element_Map!$A$2:$A$287),COLUMNS($J6:P6)),KPI_Master!$A:$A,0)&":P"&MATCH(SMALL(IF(KPI_Element_Map!$E$2:$E$287=$A6,KPI_Element_Map!$A$2:$A$287),COLUMNS($J6:P6)),KPI_Master!$A:$A,0),SMALL(IF(KPI_Element_Map!$E$2:$E$287=$A6,KPI_Element_Map!$A$2:$A$287),COLUMNS($J6:P6))),"")} -> 153 | Q6: {=IFERROR(HYPERLINK("#KPI_Master!A"&MATCH(SMALL(IF(KPI_Element_Map!$E$2:$E$287=$A6,KPI_Element_Map!$A$2:$A$287),COLUMNS($J6:Q6)),KPI_Master!$A:$A,0)&":P"&MATCH(SMALL(IF(KPI_Element_Map!$E$2:$E$287=$A6,KPI_Element_Map!$A$2:$A$287),COLUMNS($J6:Q6)),KPI_Master!$A:$A,0),SMALL(IF(KPI_Element_Map!$E$2:$E$287=$A6,KPI_Element_Map!$A$2:$A$287),COLUMNS($J6:Q6))),"")} -> 159 | ... AH6: {=IFERROR(HYPERLINK("#KPI_Master!A"&MATCH(SMALL(IF(KPI_Element_Map!$E$2:$E$287=$A6,KPI_Element_Map!$A$2:$A$287),COLUMNS($J6:AH6)),KPI_Master!$A:$A,0)&":P"&MATCH(SMALL(IF(KPI_Element_Map!$E$2:$E$287=$A6,KPI_Element_Map!$A$2:$A$287),COLUMNS($J6:AH6)),KPI_Master!$A:$A,0),SMALL(IF(KPI_Element_Map!$E$2:$E$287=$A6,KPI_Element_Map!$A$2:$A$287),COLUMNS($J6:AH6))),"")}
A7: E03 | B7: Total Residents (headcount) | C7: Residents in house (average or point-in-time, state which) | D7: {=_xlfn.TEXTJOIN(", ",TRUE(),IF(KPI_Element_Map!$E$2:$E$287=$A7,KPI_Element_Map!$A$2:$A$287,""))} -> 74, 75, 91, 94, 97, 110 | E7: =COUNTIF(KPI_Element_Map!$E$2:$E$287,$A7) -> 6 | F7: =COUNTIFS(KPI_Element_Map!$E$2:$E$287,$A7,KPI_Element_Map!$D$2:$D$287,"1 - Core") -> 1 | G7: D01 | H7: =INDEX(Minimum_Documents!$B:$B,MATCH($G7,Minimum_Documents!$A:$A,0)) -> Census & ADT Register | J7: {=IFERROR(HYPERLINK("#KPI_Master!A"&MATCH(SMALL(IF(KPI_Element_Map!$E$2:$E$287=$A7,KPI_Element_Map!$A$2:$A$287),COLUMNS($J7:J7)),KPI_Master!$A:$A,0)&":P"&MATCH(SMALL(IF(KPI_Element_Map!$E$2:$E$287=$A7,KPI_Element_Map!$A$2:$A$287),COLUMNS($J7:J7)),KPI_Master!$A:$A,0),SMALL(IF(KPI_Element_Map!$E$2:$E$287=$A7,KPI_Element_Map!$A$2:$A$287),COLUMNS($J7:J7))),"")} -> 74 | K7: {=IFERROR(HYPERLINK("#KPI_Master!A"&MATCH(SMALL(IF(KPI_Element_Map!$E$2:$E$287=$A7,KPI_Element_Map!$A$2:$A$287),COLUMNS($J7:K7)),KPI_Master!$A:$A,0)&":P"&MATCH(SMALL(IF(KPI_Element_Map!$E$2:$E$287=$A7,KPI_Element_Map!$A$2:$A$287),COLUMNS($J7:K7)),KPI_Master!$A:$A,0),SMALL(IF(KPI_Element_Map!$E$2:$E$287=$A7,KPI_Element_Map!$A$2:$A$287),COLUMNS($J7:K7))),"")} -> 75 | L7: {=IFERROR(HYPERLINK("#KPI_Master!A"&MATCH(SMALL(IF(KPI_Element_Map!$E$2:$E$287=$A7,KPI_Element_Map!$A$2:$A$287),COLUMNS($J7:L7)),KPI_Master!$A:$A,0)&":P"&MATCH(SMALL(IF(KPI_Element_Map!$E$2:$E$287=$A7,KPI_Element_Map!$A$2:$A$287),COLUMNS($J7:L7)),KPI_Master!$A:$A,0),SMALL(IF(KPI_Element_Map!$E$2:$E$287=$A7,KPI_Element_Map!$A$2:$A$287),COLUMNS($J7:L7))),"")} -> 91 | M7: {=IFERROR(HYPERLINK("#KPI_Master!A"&MATCH(SMALL(IF(KPI_Element_Map!$E$2:$E$287=$A7,KPI_Element_Map!$A$2:$A$287),COLUMNS($J7:M7)),KPI_Master!$A:$A,0)&":P"&MATCH(SMALL(IF(KPI_Element_Map!$E$2:$E$287=$A7,KPI_Element_Map!$A$2:$A$287),COLUMNS($J7:M7)),KPI_Master!$A:$A,0),SMALL(IF(KPI_Element_Map!$E$2:$E$287=$A7,KPI_Element_Map!$A$2:$A$287),COLUMNS($J7:M7))),"")} -> 94 | N7: {=IFERROR(HYPERLINK("#KPI_Master!A"&MATCH(SMALL(IF(KPI_Element_Map!$E$2:$E$287=$A7,KPI_Element_Map!$A$2:$A$287),COLUMNS($J7:N7)),KPI_Master!$A:$A,0)&":P"&MATCH(SMALL(IF(KPI_Element_Map!$E$2:$E$287=$A7,KPI_Element_Map!$A$2:$A$287),COLUMNS($J7:N7)),KPI_Master!$A:$A,0),SMALL(IF(KPI_Element_Map!$E$2:$E$287=$A7,KPI_Element_Map!$A$2:$A$287),COLUMNS($J7:N7))),"")} -> 97 | O7: {=IFERROR(HYPERLINK("#KPI_Master!A"&MATCH(SMALL(IF(KPI_Element_Map!$E$2:$E$287=$A7,KPI_Element_Map!$A$2:$A$287),COLUMNS($J7:O7)),KPI_Master!$A:$A,0)&":P"&MATCH(SMALL(IF(KPI_Element_Map!$E$2:$E$287=$A7,KPI_Element_Map!$A$2:$A$287),COLUMNS($J7:O7)),KPI_Master!$A:$A,0),SMALL(IF(KPI_Element_Map!$E$2:$E$287=$A7,KPI_Element_Map!$A$2:$A$287),COLUMNS($J7:O7))),"")} -> 110 | P7: {=IFERROR(HYPERLINK("#KPI_Master!A"&MATCH(SMALL(IF(KPI_Element_Map!$E$2:$E$287=$A7,KPI_Element_Map!$A$2:$A$287),COLUMNS($J7:P7)),KPI_Master!$A:$A,0)&":P"&MATCH(SMALL(IF(KPI_Element_Map!$E$2:$E$287=$A7,KPI_Element_Map!$A$2:$A$287),COLUMNS($J7:P7)),KPI_Master!$A:$A,0),SMALL(IF(KPI_Element_Map!$E$2:$E$287=$A7,KPI_Element_Map!$A$2:$A$287),COLUMNS($J7:P7))),"")} | Q7: {=IFERROR(HYPERLINK("#KPI_Master!A"&MATCH(SMALL(IF(KPI_Element_Map!$E$2:$E$287=$A7,KPI_Element_Map!$A$2:$A$287),COLUMNS($J7:Q7)),KPI_Master!$A:$A,0)&":P"&MATCH(SMALL(IF(KPI_Element_Map!$E$2:$E$287=$A7,KPI_Element_Map!$A$2:$A$287),COLUMNS($J7:Q7)),KPI_Master!$A:$A,0),SMALL(IF(KPI_Element_Map!$E$2:$E$287=$A7,KPI_Element_Map!$A$2:$A$287),COLUMNS($J7:Q7))),"")} | ... AH7: {=IFERROR(HYPERLINK("#KPI_Master!A"&MATCH(SMALL(IF(KPI_Element_Map!$E$2:$E$287=$A7,KPI_Element_Map!$A$2:$A$287),COLUMNS($J7:AH7)),KPI_Master!$A:$A,0)&":P"&MATCH(SMALL(IF(KPI_Element_Map!$E$2:$E$287=$A7,KPI_Element_Map!$A$2:$A$287),COLUMNS($J7:AH7)),KPI_Master!$A:$A,0),SMALL(IF(KPI_Element_Map!$E$2:$E$287=$A7,KPI_Element_Map!$A$2:$A$287),COLUMNS($J7:AH7))),"")}
A8: E04 | B8: Resident Days by Payer | C8: Resident days split by payer type | D8: {=_xlfn.TEXTJOIN(", ",TRUE(),IF(KPI_Element_Map!$E$2:$E$287=$A8,KPI_Element_Map!$A$2:$A$287,""))} -> 22 | E8: =COUNTIF(KPI_Element_Map!$E$2:$E$287,$A8) -> 1 | F8: =COUNTIFS(KPI_Element_Map!$E$2:$E$287,$A8,KPI_Element_Map!$D$2:$D$287,"1 - Core") -> 0 | G8: D01 | H8: =INDEX(Minimum_Documents!$B:$B,MATCH($G8,Minimum_Documents!$A:$A,0)) -> Census & ADT Register | J8: {=IFERROR(HYPERLINK("#KPI_Master!A"&MATCH(SMALL(IF(KPI_Element_Map!$E$2:$E$287=$A8,KPI_Element_Map!$A$2:$A$287),COLUMNS($J8:J8)),KPI_Master!$A:$A,0)&":P"&MATCH(SMALL(IF(KPI_Element_Map!$E$2:$E$287=$A8,KPI_Element_Map!$A$2:$A$287),COLUMNS($J8:J8)),KPI_Master!$A:$A,0),SMALL(IF(KPI_Element_Map!$E$2:$E$287=$A8,KPI_Element_Map!$A$2:$A$287),COLUMNS($J8:J8))),"")} -> 22 | K8: {=IFERROR(HYPERLINK("#KPI_Master!A"&MATCH(SMALL(IF(KPI_Element_Map!$E$2:$E$287=$A8,KPI_Element_Map!$A$2:$A$287),COLUMNS($J8:K8)),KPI_Master!$A:$A,0)&":P"&MATCH(SMALL(IF(KPI_Element_Map!$E$2:$E$287=$A8,KPI_Element_Map!$A$2:$A$287),COLUMNS($J8:K8)),KPI_Master!$A:$A,0),SMALL(IF(KPI_Element_Map!$E$2:$E$287=$A8,KPI_Element_Map!$A$2:$A$287),COLUMNS($J8:K8))),"")} | L8: {=IFERROR(HYPERLINK("#KPI_Master!A"&MATCH(SMALL(IF(KPI_Element_Map!$E$2:$E$287=$A8,KPI_Element_Map!$A$2:$A$287),COLUMNS($J8:L8)),KPI_Master!$A:$A,0)&":P"&MATCH(SMALL(IF(KPI_Element_Map!$E$2:$E$287=$A8,KPI_Element_Map!$A$2:$A$287),COLUMNS($J8:L8)),KPI_Master!$A:$A,0),SMALL(IF(KPI_Element_Map!$E$2:$E$287=$A8,KPI_Element_Map!$A$2:$A$287),COLUMNS($J8:L8))),"")} | M8: {=IFERROR(HYPERLINK("#KPI_Master!A"&MATCH(SMALL(IF(KPI_Element_Map!$E$2:$E$287=$A8,KPI_Element_Map!$A$2:$A$287),COLUMNS($J8:M8)),KPI_Master!$A:$A,0)&":P"&MATCH(SMALL(IF(KPI_Element_Map!$E$2:$E$287=$A8,KPI_Element_Map!$A$2:$A$287),COLUMNS($J8:M8)),KPI_Master!$A:$A,0),SMALL(IF(KPI_Element_Map!$E$2:$E$287=$A8,KPI_Element_Map!$A$2:$A$287),COLUMNS($J8:M8))),"")} | N8: {=IFERROR(HYPERLINK("#KPI_Master!A"&MATCH(SMALL(IF(KPI_Element_Map!$E$2:$E$287=$A8,KPI_Element_Map!$A$2:$A$287),COLUMNS($J8:N8)),KPI_Master!$A:$A,0)&":P"&MATCH(SMALL(IF(KPI_Element_Map!$E$2:$E$287=$A8,KPI_Element_Map!$A$2:$A$287),COLUMNS($J8:N8)),KPI_Master!$A:$A,0),SMALL(IF(KPI_Element_Map!$E$2:$E$287=$A8,KPI_Element_Map!$A$2:$A$287),COLUMNS($J8:N8))),"")} | O8: {=IFERROR(HYPERLINK("#KPI_Master!A"&MATCH(SMALL(IF(KPI_Element_Map!$E$2:$E$287=$A8,KPI_Element_Map!$A$2:$A$287),COLUMNS($J8:O8)),KPI_Master!$A:$A,0)&":P"&MATCH(SMALL(IF(KPI_Element_Map!$E$2:$E$287=$A8,KPI_Element_Map!$A$2:$A$287),COLUMNS($J8:O8)),KPI_Master!$A:$A,0),SMALL(IF(KPI_Element_Map!$E$2:$E$287=$A8,KPI_Element_Map!$A$2:$A$287),COLUMNS($J8:O8))),"")} | P8: {=IFERROR(HYPERLINK("#KPI_Master!A"&MATCH(SMALL(IF(KPI_Element_Map!$E$2:$E$287=$A8,KPI_Element_Map!$A$2:$A$287),COLUMNS($J8:P8)),KPI_Master!$A:$A,0)&":P"&MATCH(SMALL(IF(KPI_Element_Map!$E$2:$E$287=$A8,KPI_Element_Map!$A$2:$A$287),COLUMNS($J8:P8)),KPI_Master!$A:$A,0),SMALL(IF(KPI_Element_Map!$E$2:$E$287=$A8,KPI_Element_Map!$A$2:$A$287),COLUMNS($J8:P8))),"")} | Q8: {=IFERROR(HYPERLINK("#KPI_Master!A"&MATCH(SMALL(IF(KPI_Element_Map!$E$2:$E$287=$A8,KPI_Element_Map!$A$2:$A$287),COLUMNS($J8:Q8)),KPI_Master!$A:$A,0)&":P"&MATCH(SMALL(IF(KPI_Element_Map!$E$2:$E$287=$A8,KPI_Element_Map!$A$2:$A$287),COLUMNS($J8:Q8)),KPI_Master!$A:$A,0),SMALL(IF(KPI_Element_Map!$E$2:$E$287=$A8,KPI_Element_Map!$A$2:$A$287),COLUMNS($J8:Q8))),"")} | ... AH8: {=IFERROR(HYPERLINK("#KPI_Master!A"&MATCH(SMALL(IF(KPI_Element_Map!$E$2:$E$287=$A8,KPI_Element_Map!$A$2:$A$287),COLUMNS($J8:AH8)),KPI_Master!$A:$A,0)&":P"&MATCH(SMALL(IF(KPI_Element_Map!$E$2:$E$287=$A8,KPI_Element_Map!$A$2:$A$287),COLUMNS($J8:AH8)),KPI_Master!$A:$A,0),SMALL(IF(KPI_Element_Map!$E$2:$E$287=$A8,KPI_Element_Map!$A$2:$A$287),COLUMNS($J8:AH8))),"")}
A9: E05 | B9: Skilled / Medicare Part A Days & Census | C9: Skilled patient days and Part A census | D9: {=_xlfn.TEXTJOIN(", ",TRUE(),IF(KPI_Element_Map!$E$2:$E$287=$A9,KPI_Element_Map!$A$2:$A$287,""))} -> 23, 104 | E9: =COUNTIF(KPI_Element_Map!$E$2:$E$287,$A9) -> 2 | F9: =COUNTIFS(KPI_Element_Map!$E$2:$E$287,$A9,KPI_Element_Map!$D$2:$D$287,"1 - Core") -> 1 | G9: D01 | H9: =INDEX(Minimum_Documents!$B:$B,MATCH($G9,Minimum_Documents!$A:$A,0)) -> Census & ADT Register | J9: {=IFERROR(HYPERLINK("#KPI_Master!A"&MATCH(SMALL(IF(KPI_Element_Map!$E$2:$E$287=$A9,KPI_Element_Map!$A$2:$A$287),COLUMNS($J9:J9)),KPI_Master!$A:$A,0)&":P"&MATCH(SMALL(IF(KPI_Element_Map!$E$2:$E$287=$A9,KPI_Element_Map!$A$2:$A$287),COLUMNS($J9:J9)),KPI_Master!$A:$A,0),SMALL(IF(KPI_Element_Map!$E$2:$E$287=$A9,KPI_Element_Map!$A$2:$A$287),COLUMNS($J9:J9))),"")} -> 23 | K9: {=IFERROR(HYPERLINK("#KPI_Master!A"&MATCH(SMALL(IF(KPI_Element_Map!$E$2:$E$287=$A9,KPI_Element_Map!$A$2:$A$287),COLUMNS($J9:K9)),KPI_Master!$A:$A,0)&":P"&MATCH(SMALL(IF(KPI_Element_Map!$E$2:$E$287=$A9,KPI_Element_Map!$A$2:$A$287),COLUMNS($J9:K9)),KPI_Master!$A:$A,0),SMALL(IF(KPI_Element_Map!$E$2:$E$287=$A9,KPI_Element_Map!$A$2:$A$287),COLUMNS($J9:K9))),"")} -> 104 | L9: {=IFERROR(HYPERLINK("#KPI_Master!A"&MATCH(SMALL(IF(KPI_Element_Map!$E$2:$E$287=$A9,KPI_Element_Map!$A$2:$A$287),COLUMNS($J9:L9)),KPI_Master!$A:$A,0)&":P"&MATCH(SMALL(IF(KPI_Element_Map!$E$2:$E$287=$A9,KPI_Element_Map!$A$2:$A$287),COLUMNS($J9:L9)),KPI_Master!$A:$A,0),SMALL(IF(KPI_Element_Map!$E$2:$E$287=$A9,KPI_Element_Map!$A$2:$A$287),COLUMNS($J9:L9))),"")} | M9: {=IFERROR(HYPERLINK("#KPI_Master!A"&MATCH(SMALL(IF(KPI_Element_Map!$E$2:$E$287=$A9,KPI_Element_Map!$A$2:$A$287),COLUMNS($J9:M9)),KPI_Master!$A:$A,0)&":P"&MATCH(SMALL(IF(KPI_Element_Map!$E$2:$E$287=$A9,KPI_Element_Map!$A$2:$A$287),COLUMNS($J9:M9)),KPI_Master!$A:$A,0),SMALL(IF(KPI_Element_Map!$E$2:$E$287=$A9,KPI_Element_Map!$A$2:$A$287),COLUMNS($J9:M9))),"")} | N9: {=IFERROR(HYPERLINK("#KPI_Master!A"&MATCH(SMALL(IF(KPI_Element_Map!$E$2:$E$287=$A9,KPI_Element_Map!$A$2:$A$287),COLUMNS($J9:N9)),KPI_Master!$A:$A,0)&":P"&MATCH(SMALL(IF(KPI_Element_Map!$E$2:$E$287=$A9,KPI_Element_Map!$A$2:$A$287),COLUMNS($J9:N9)),KPI_Master!$A:$A,0),SMALL(IF(KPI_Element_Map!$E$2:$E$287=$A9,KPI_Element_Map!$A$2:$A$287),COLUMNS($J9:N9))),"")} | O9: {=IFERROR(HYPERLINK("#KPI_Master!A"&MATCH(SMALL(IF(KPI_Element_Map!$E$2:$E$287=$A9,KPI_Element_Map!$A$2:$A$287),COLUMNS($J9:O9)),KPI_Master!$A:$A,0)&":P"&MATCH(SMALL(IF(KPI_Element_Map!$E$2:$E$287=$A9,KPI_Element_Map!$A$2:$A$287),COLUMNS($J9:O9)),KPI_Master!$A:$A,0),SMALL(IF(KPI_Element_Map!$E$2:$E$287=$A9,KPI_Element_Map!$A$2:$A$287),COLUMNS($J9:O9))),"")} | P9: {=IFERROR(HYPERLINK("#KPI_Master!A"&MATCH(SMALL(IF(KPI_Element_Map!$E$2:$E$287=$A9,KPI_Element_Map!$A$2:$A$287),COLUMNS($J9:P9)),KPI_Master!$A:$A,0)&":P"&MATCH(SMALL(IF(KPI_Element_Map!$E$2:$E$287=$A9,KPI_Element_Map!$A$2:$A$287),COLUMNS($J9:P9)),KPI_Master!$A:$A,0),SMALL(IF(KPI_Element_Map!$E$2:$E$287=$A9,KPI_Element_Map!$A$2:$A$287),COLUMNS($J9:P9))),"")} | Q9: {=IFERROR(HYPERLINK("#KPI_Master!A"&MATCH(SMALL(IF(KPI_Element_Map!$E$2:$E$287=$A9,KPI_Element_Map!$A$2:$A$287),COLUMNS($J9:Q9)),KPI_Master!$A:$A,0)&":P"&MATCH(SMALL(IF(KPI_Element_Map!$E$2:$E$287=$A9,KPI_Element_Map!$A$2:$A$287),COLUMNS($J9:Q9)),KPI_Master!$A:$A,0),SMALL(IF(KPI_Element_Map!$E$2:$E$287=$A9,KPI_Element_Map!$A$2:$A$287),COLUMNS($J9:Q9))),"")} | ... AH9: {=IFERROR(HYPERLINK("#KPI_Master!A"&MATCH(SMALL(IF(KPI_Element_Map!$E$2:$E$287=$A9,KPI_Element_Map!$A$2:$A$287),COLUMNS($J9:AH9)),KPI_Master!$A:$A,0)&":P"&MATCH(SMALL(IF(KPI_Element_Map!$E$2:$E$287=$A9,KPI_Element_Map!$A$2:$A$287),COLUMNS($J9:AH9)),KPI_Master!$A:$A,0),SMALL(IF(KPI_Element_Map!$E$2:$E$287=$A9,KPI_Element_Map!$A$2:$A$287),COLUMNS($J9:AH9))),"")}
A10: E06 | B10: Census by Level of Care (AL / MC / SNF) | C10: Occupied units and resident days by care level | D10: {=_xlfn.TEXTJOIN(", ",TRUE(),IF(KPI_Element_Map!$E$2:$E$287=$A10,KPI_Element_Map!$A$2:$A$287,""))} -> 41, 77 | E10: =COUNTIF(KPI_Element_Map!$E$2:$E$287,$A10) -> 2 | F10: =COUNTIFS(KPI_Element_Map!$E$2:$E$287,$A10,KPI_Element_Map!$D$2:$D$287,"1 - Core") -> 0 | G10: D01 | H10: =INDEX(Minimum_Documents!$B:$B,MATCH($G10,Minimum_Documents!$A:$A,0)) -> Census & ADT Register | J10: {=IFERROR(HYPERLINK("#KPI_Master!A"&MATCH(SMALL(IF(KPI_Element_Map!$E$2:$E$287=$A10,KPI_Element_Map!$A$2:$A$287),COLUMNS($J10:J10)),KPI_Master!$A:$A,0)&":P"&MATCH(SMALL(IF(KPI_Element_Map!$E$2:$E$287=$A10,KPI_Element_Map!$A$2:$A$287),COLUMNS($J10:J10)),KPI_Master!$A:$A,0),SMALL(IF(KPI_Element_Map!$E$2:$E$287=$A10,KPI_Element_Map!$A$2:$A$287),COLUMNS($J10:J10))),"")} -> 41 | K10: {=IFERROR(HYPERLINK("#KPI_Master!A"&MATCH(SMALL(IF(KPI_Element_Map!$E$2:$E$287=$A10,KPI_Element_Map!$A$2:$A$287),COLUMNS($J10:K10)),KPI_Master!$A:$A,0)&":P"&MATCH(SMALL(IF(KPI_Element_Map!$E$2:$E$287=$A10,KPI_Element_Map!$A$2:$A$287),COLUMNS($J10:K10)),KPI_Master!$A:$A,0),SMALL(IF(KPI_Element_Map!$E$2:$E$287=$A10,KPI_Element_Map!$A$2:$A$287),COLUMNS($J10:K10))),"")} -> 77 | L10: {=IFERROR(HYPERLINK("#KPI_Master!A"&MATCH(SMALL(IF(KPI_Element_Map!$E$2:$E$287=$A10,KPI_Element_Map!$A$2:$A$287),COLUMNS($J10:L10)),KPI_Master!$A:$A,0)&":P"&MATCH(SMALL(IF(KPI_Element_Map!$E$2:$E$287=$A10,KPI_Element_Map!$A$2:$A$287),COLUMNS($J10:L10)),KPI_Master!$A:$A,0),SMALL(IF(KPI_Element_Map!$E$2:$E$287=$A10,KPI_Element_Map!$A$2:$A$287),COLUMNS($J10:L10))),"")} | M10: {=IFERROR(HYPERLINK("#KPI_Master!A"&MATCH(SMALL(IF(KPI_Element_Map!$E$2:$E$287=$A10,KPI_Element_Map!$A$2:$A$287),COLUMNS($J10:M10)),KPI_Master!$A:$A,0)&":P"&MATCH(SMALL(IF(KPI_Element_Map!$E$2:$E$287=$A10,KPI_Element_Map!$A$2:$A$287),COLUMNS($J10:M10)),KPI_Master!$A:$A,0),SMALL(IF(KPI_Element_Map!$E$2:$E$287=$A10,KPI_Element_Map!$A$2:$A$287),COLUMNS($J10:M10))),"")} | N10: {=IFERROR(HYPERLINK("#KPI_Master!A"&MATCH(SMALL(IF(KPI_Element_Map!$E$2:$E$287=$A10,KPI_Element_Map!$A$2:$A$287),COLUMNS($J10:N10)),KPI_Master!$A:$A,0)&":P"&MATCH(SMALL(IF(KPI_Element_Map!$E$2:$E$287=$A10,KPI_Element_Map!$A$2:$A$287),COLUMNS($J10:N10)),KPI_Master!$A:$A,0),SMALL(IF(KPI_Element_Map!$E$2:$E$287=$A10,KPI_Element_Map!$A$2:$A$287),COLUMNS($J10:N10))),"")} | O10: {=IFERROR(HYPERLINK("#KPI_Master!A"&MATCH(SMALL(IF(KPI_Element_Map!$E$2:$E$287=$A10,KPI_Element_Map!$A$2:$A$287),COLUMNS($J10:O10)),KPI_Master!$A:$A,0)&":P"&MATCH(SMALL(IF(KPI_Element_Map!$E$2:$E$287=$A10,KPI_Element_Map!$A$2:$A$287),COLUMNS($J10:O10)),KPI_Master!$A:$A,0),SMALL(IF(KPI_Element_Map!$E$2:$E$287=$A10,KPI_Element_Map!$A$2:$A$287),COLUMNS($J10:O10))),"")} | P10: {=IFERROR(HYPERLINK("#KPI_Master!A"&MATCH(SMALL(IF(KPI_Element_Map!$E$2:$E$287=$A10,KPI_Element_Map!$A$2:$A$287),COLUMNS($J10:P10)),KPI_Master!$A:$A,0)&":P"&MATCH(SMALL(IF(KPI_Element_Map!$E$2:$E$287=$A10,KPI_Element_Map!$A$2:$A$287),COLUMNS($J10:P10)),KPI_Master!$A:$A,0),SMALL(IF(KPI_Element_Map!$E$2:$E$287=$A10,KPI_Element_Map!$A$2:$A$287),COLUMNS($J10:P10))),"")} | Q10: {=IFERROR(HYPERLINK("#KPI_Master!A"&MATCH(SMALL(IF(KPI_Element_Map!$E$2:$E$287=$A10,KPI_Element_Map!$A$2:$A$287),COLUMNS($J10:Q10)),KPI_Master!$A:$A,0)&":P"&MATCH(SMALL(IF(KPI_Element_Map!$E$2:$E$287=$A10,KPI_Element_Map!$A$2:$A$287),COLUMNS($J10:Q10)),KPI_Master!$A:$A,0),SMALL(IF(KPI_Element_Map!$E$2:$E$287=$A10,KPI_Element_Map!$A$2:$A$287),COLUMNS($J10:Q10))),"")} | ... AH10: {=IFERROR(HYPERLINK("#KPI_Master!A"&MATCH(SMALL(IF(KPI_Element_Map!$E$2:$E$287=$A10,KPI_Element_Map!$A$2:$A$287),COLUMNS($J10:AH10)),KPI_Master!$A:$A,0)&":P"&MATCH(SMALL(IF(KPI_Element_Map!$E$2:$E$287=$A10,KPI_Element_Map!$A$2:$A$287),COLUMNS($J10:AH10)),KPI_Master!$A:$A,0),SMALL(IF(KPI_Element_Map!$E$2:$E$287=$A10,KPI_Element_Map!$A$2:$A$287),COLUMNS($J10:AH10))),"")}
A11: E07 | B11: Move-Ins / Admissions | C11: Count and dates of move-ins / admissions (incl. admission source) | D11: {=_xlfn.TEXTJOIN(", ",TRUE(),IF(KPI_Element_Map!$E$2:$E$287=$A11,KPI_Element_Map!$A$2:$A$287,""))} -> 86, 103, 151, 157, 158, 161, 167 | E11: =COUNTIF(KPI_Element_Map!$E$2:$E$287,$A11) -> 7 | F11: =COUNTIFS(KPI_Element_Map!$E$2:$E$287,$A11,KPI_Element_Map!$D$2:$D$287,"1 - Core") -> 2 | G11: D01 | H11: =INDEX(Minimum_Documents!$B:$B,MATCH($G11,Minimum_Documents!$A:$A,0)) -> Census & ADT Register | J11: {=IFERROR(HYPERLINK("#KPI_Master!A"&MATCH(SMALL(IF(KPI_Element_Map!$E$2:$E$287=$A11,KPI_Element_Map!$A$2:$A$287),COLUMNS($J11:J11)),KPI_Master!$A:$A,0)&":P"&MATCH(SMALL(IF(KPI_Element_Map!$E$2:$E$287=$A11,KPI_Element_Map!$A$2:$A$287),COLUMNS($J11:J11)),KPI_Master!$A:$A,0),SMALL(IF(KPI_Element_Map!$E$2:$E$287=$A11,KPI_Element_Map!$A$2:$A$287),COLUMNS($J11:J11))),"")} -> 86 | K11: {=IFERROR(HYPERLINK("#KPI_Master!A"&MATCH(SMALL(IF(KPI_Element_Map!$E$2:$E$287=$A11,KPI_Element_Map!$A$2:$A$287),COLUMNS($J11:K11)),KPI_Master!$A:$A,0)&":P"&MATCH(SMALL(IF(KPI_Element_Map!$E$2:$E$287=$A11,KPI_Element_Map!$A$2:$A$287),COLUMNS($J11:K11)),KPI_Master!$A:$A,0),SMALL(IF(KPI_Element_Map!$E$2:$E$287=$A11,KPI_Element_Map!$A$2:$A$287),COLUMNS($J11:K11))),"")} -> 103 | L11: {=IFERROR(HYPERLINK("#KPI_Master!A"&MATCH(SMALL(IF(KPI_Element_Map!$E$2:$E$287=$A11,KPI_Element_Map!$A$2:$A$287),COLUMNS($J11:L11)),KPI_Master!$A:$A,0)&":P"&MATCH(SMALL(IF(KPI_Element_Map!$E$2:$E$287=$A11,KPI_Element_Map!$A$2:$A$287),COLUMNS($J11:L11)),KPI_Master!$A:$A,0),SMALL(IF(KPI_Element_Map!$E$2:$E$287=$A11,KPI_Element_Map!$A$2:$A$287),COLUMNS($J11:L11))),"")} -> 151 | M11: {=IFERROR(HYPERLINK("#KPI_Master!A"&MATCH(SMALL(IF(KPI_Element_Map!$E$2:$E$287=$A11,KPI_Element_Map!$A$2:$A$287),COLUMNS($J11:M11)),KPI_Master!$A:$A,0)&":P"&MATCH(SMALL(IF(KPI_Element_Map!$E$2:$E$287=$A11,KPI_Element_Map!$A$2:$A$287),COLUMNS($J11:M11)),KPI_Master!$A:$A,0),SMALL(IF(KPI_Element_Map!$E$2:$E$287=$A11,KPI_Element_Map!$A$2:$A$287),COLUMNS($J11:M11))),"")} -> 157 | N11: {=IFERROR(HYPERLINK("#KPI_Master!A"&MATCH(SMALL(IF(KPI_Element_Map!$E$2:$E$287=$A11,KPI_Element_Map!$A$2:$A$287),COLUMNS($J11:N11)),KPI_Master!$A:$A,0)&":P"&MATCH(SMALL(IF(KPI_Element_Map!$E$2:$E$287=$A11,KPI_Element_Map!$A$2:$A$287),COLUMNS($J11:N11)),KPI_Master!$A:$A,0),SMALL(IF(KPI_Element_Map!$E$2:$E$287=$A11,KPI_Element_Map!$A$2:$A$287),COLUMNS($J11:N11))),"")} -> 158 | O11: {=IFERROR(HYPERLINK("#KPI_Master!A"&MATCH(SMALL(IF(KPI_Element_Map!$E$2:$E$287=$A11,KPI_Element_Map!$A$2:$A$287),COLUMNS($J11:O11)),KPI_Master!$A:$A,0)&":P"&MATCH(SMALL(IF(KPI_Element_Map!$E$2:$E$287=$A11,KPI_Element_Map!$A$2:$A$287),COLUMNS($J11:O11)),KPI_Master!$A:$A,0),SMALL(IF(KPI_Element_Map!$E$2:$E$287=$A11,KPI_Element_Map!$A$2:$A$287),COLUMNS($J11:O11))),"")} -> 161 | P11: {=IFERROR(HYPERLINK("#KPI_Master!A"&MATCH(SMALL(IF(KPI_Element_Map!$E$2:$E$287=$A11,KPI_Element_Map!$A$2:$A$287),COLUMNS($J11:P11)),KPI_Master!$A:$A,0)&":P"&MATCH(SMALL(IF(KPI_Element_Map!$E$2:$E$287=$A11,KPI_Element_Map!$A$2:$A$287),COLUMNS($J11:P11)),KPI_Master!$A:$A,0),SMALL(IF(KPI_Element_Map!$E$2:$E$287=$A11,KPI_Element_Map!$A$2:$A$287),COLUMNS($J11:P11))),"")} -> 167 | Q11: {=IFERROR(HYPERLINK("#KPI_Master!A"&MATCH(SMALL(IF(KPI_Element_Map!$E$2:$E$287=$A11,KPI_Element_Map!$A$2:$A$287),COLUMNS($J11:Q11)),KPI_Master!$A:$A,0)&":P"&MATCH(SMALL(IF(KPI_Element_Map!$E$2:$E$287=$A11,KPI_Element_Map!$A$2:$A$287),COLUMNS($J11:Q11)),KPI_Master!$A:$A,0),SMALL(IF(KPI_Element_Map!$E$2:$E$287=$A11,KPI_Element_Map!$A$2:$A$287),COLUMNS($J11:Q11))),"")} | ... AH11: {=IFERROR(HYPERLINK("#KPI_Master!A"&MATCH(SMALL(IF(KPI_Element_Map!$E$2:$E$287=$A11,KPI_Element_Map!$A$2:$A$287),COLUMNS($J11:AH11)),KPI_Master!$A:$A,0)&":P"&MATCH(SMALL(IF(KPI_Element_Map!$E$2:$E$287=$A11,KPI_Element_Map!$A$2:$A$287),COLUMNS($J11:AH11)),KPI_Master!$A:$A,0),SMALL(IF(KPI_Element_Map!$E$2:$E$287=$A11,KPI_Element_Map!$A$2:$A$287),COLUMNS($J11:AH11))),"")}
A12: E08 | B12: Move-Outs / Discharges | C12: Count, dates, reason code, destination and payer of each departure | D12: {=_xlfn.TEXTJOIN(", ",TRUE(),IF(KPI_Element_Map!$E$2:$E$287=$A12,KPI_Element_Map!$A$2:$A$287,""))} -> 151, 152, 158, 159, 162 | E12: =COUNTIF(KPI_Element_Map!$E$2:$E$287,$A12) -> 5 | F12: =COUNTIFS(KPI_Element_Map!$E$2:$E$287,$A12,KPI_Element_Map!$D$2:$D$287,"1 - Core") -> 2 | G12: D01 | H12: =INDEX(Minimum_Documents!$B:$B,MATCH($G12,Minimum_Documents!$A:$A,0)) -> Census & ADT Register | J12: {=IFERROR(HYPERLINK("#KPI_Master!A"&MATCH(SMALL(IF(KPI_Element_Map!$E$2:$E$287=$A12,KPI_Element_Map!$A$2:$A$287),COLUMNS($J12:J12)),KPI_Master!$A:$A,0)&":P"&MATCH(SMALL(IF(KPI_Element_Map!$E$2:$E$287=$A12,KPI_Element_Map!$A$2:$A$287),COLUMNS($J12:J12)),KPI_Master!$A:$A,0),SMALL(IF(KPI_Element_Map!$E$2:$E$287=$A12,KPI_Element_Map!$A$2:$A$287),COLUMNS($J12:J12))),"")} -> 151 | K12: {=IFERROR(HYPERLINK("#KPI_Master!A"&MATCH(SMALL(IF(KPI_Element_Map!$E$2:$E$287=$A12,KPI_Element_Map!$A$2:$A$287),COLUMNS($J12:K12)),KPI_Master!$A:$A,0)&":P"&MATCH(SMALL(IF(KPI_Element_Map!$E$2:$E$287=$A12,KPI_Element_Map!$A$2:$A$287),COLUMNS($J12:K12)),KPI_Master!$A:$A,0),SMALL(IF(KPI_Element_Map!$E$2:$E$287=$A12,KPI_Element_Map!$A$2:$A$287),COLUMNS($J12:K12))),"")} -> 152 | L12: {=IFERROR(HYPERLINK("#KPI_Master!A"&MATCH(SMALL(IF(KPI_Element_Map!$E$2:$E$287=$A12,KPI_Element_Map!$A$2:$A$287),COLUMNS($J12:L12)),KPI_Master!$A:$A,0)&":P"&MATCH(SMALL(IF(KPI_Element_Map!$E$2:$E$287=$A12,KPI_Element_Map!$A$2:$A$287),COLUMNS($J12:L12)),KPI_Master!$A:$A,0),SMALL(IF(KPI_Element_Map!$E$2:$E$287=$A12,KPI_Element_Map!$A$2:$A$287),COLUMNS($J12:L12))),"")} -> 158 | M12: {=IFERROR(HYPERLINK("#KPI_Master!A"&MATCH(SMALL(IF(KPI_Element_Map!$E$2:$E$287=$A12,KPI_Element_Map!$A$2:$A$287),COLUMNS($J12:M12)),KPI_Master!$A:$A,0)&":P"&MATCH(SMALL(IF(KPI_Element_Map!$E$2:$E$287=$A12,KPI_Element_Map!$A$2:$A$287),COLUMNS($J12:M12)),KPI_Master!$A:$A,0),SMALL(IF(KPI_Element_Map!$E$2:$E$287=$A12,KPI_Element_Map!$A$2:$A$287),COLUMNS($J12:M12))),"")} -> 159 | N12: {=IFERROR(HYPERLINK("#KPI_Master!A"&MATCH(SMALL(IF(KPI_Element_Map!$E$2:$E$287=$A12,KPI_Element_Map!$A$2:$A$287),COLUMNS($J12:N12)),KPI_Master!$A:$A,0)&":P"&MATCH(SMALL(IF(KPI_Element_Map!$E$2:$E$287=$A12,KPI_Element_Map!$A$2:$A$287),COLUMNS($J12:N12)),KPI_Master!$A:$A,0),SMALL(IF(KPI_Element_Map!$E$2:$E$287=$A12,KPI_Element_Map!$A$2:$A$287),COLUMNS($J12:N12))),"")} -> 162 | O12: {=IFERROR(HYPERLINK("#KPI_Master!A"&MATCH(SMALL(IF(KPI_Element_Map!$E$2:$E$287=$A12,KPI_Element_Map!$A$2:$A$287),COLUMNS($J12:O12)),KPI_Master!$A:$A,0)&":P"&MATCH(SMALL(IF(KPI_Element_Map!$E$2:$E$287=$A12,KPI_Element_Map!$A$2:$A$287),COLUMNS($J12:O12)),KPI_Master!$A:$A,0),SMALL(IF(KPI_Element_Map!$E$2:$E$287=$A12,KPI_Element_Map!$A$2:$A$287),COLUMNS($J12:O12))),"")} | P12: {=IFERROR(HYPERLINK("#KPI_Master!A"&MATCH(SMALL(IF(KPI_Element_Map!$E$2:$E$287=$A12,KPI_Element_Map!$A$2:$A$287),COLUMNS($J12:P12)),KPI_Master!$A:$A,0)&":P"&MATCH(SMALL(IF(KPI_Element_Map!$E$2:$E$287=$A12,KPI_Element_Map!$A$2:$A$287),COLUMNS($J12:P12)),KPI_Master!$A:$A,0),SMALL(IF(KPI_Element_Map!$E$2:$E$287=$A12,KPI_Element_Map!$A$2:$A$287),COLUMNS($J12:P12))),"")} | Q12: {=IFERROR(HYPERLINK("#KPI_Master!A"&MATCH(SMALL(IF(KPI_Element_Map!$E$2:$E$287=$A12,KPI_Element_Map!$A$2:$A$287),COLUMNS($J12:Q12)),KPI_Master!$A:$A,0)&":P"&MATCH(SMALL(IF(KPI_Element_Map!$E$2:$E$287=$A12,KPI_Element_Map!$A$2:$A$287),COLUMNS($J12:Q12)),KPI_Master!$A:$A,0),SMALL(IF(KPI_Element_Map!$E$2:$E$287=$A12,KPI_Element_Map!$A$2:$A$287),COLUMNS($J12:Q12))),"")} | ... AH12: {=IFERROR(HYPERLINK("#KPI_Master!A"&MATCH(SMALL(IF(KPI_Element_Map!$E$2:$E$287=$A12,KPI_Element_Map!$A$2:$A$287),COLUMNS($J12:AH12)),KPI_Master!$A:$A,0)&":P"&MATCH(SMALL(IF(KPI_Element_Map!$E$2:$E$287=$A12,KPI_Element_Map!$A$2:$A$287),COLUMNS($J12:AH12)),KPI_Master!$A:$A,0),SMALL(IF(KPI_Element_Map!$E$2:$E$287=$A12,KPI_Element_Map!$A$2:$A$287),COLUMNS($J12:AH12))),"")}
A13: E09 | B13: Hospital Transfers & Readmissions | C13: Transfer-to-hospital events with date, planned / unplanned flag and return | D13: {=_xlfn.TEXTJOIN(", ",TRUE(),IF(KPI_Element_Map!$E$2:$E$287=$A13,KPI_Element_Map!$A$2:$A$287,""))} -> 86, 87 | E13: =COUNTIF(KPI_Element_Map!$E$2:$E$287,$A13) -> 2 | F13: =COUNTIFS(KPI_Element_Map!$E$2:$E$287,$A13,KPI_Element_Map!$D$2:$D$287,"1 - Core") -> 1 | G13: D01 | H13: =INDEX(Minimum_Documents!$B:$B,MATCH($G13,Minimum_Documents!$A:$A,0)) -> Census & ADT Register | J13: {=IFERROR(HYPERLINK("#KPI_Master!A"&MATCH(SMALL(IF(KPI_Element_Map!$E$2:$E$287=$A13,KPI_Element_Map!$A$2:$A$287),COLUMNS($J13:J13)),KPI_Master!$A:$A,0)&":P"&MATCH(SMALL(IF(KPI_Element_Map!$E$2:$E$287=$A13,KPI_Element_Map!$A$2:$A$287),COLUMNS($J13:J13)),KPI_Master!$A:$A,0),SMALL(IF(KPI_Element_Map!$E$2:$E$287=$A13,KPI_Element_Map!$A$2:$A$287),COLUMNS($J13:J13))),"")} -> 86 | K13: {=IFERROR(HYPERLINK("#KPI_Master!A"&MATCH(SMALL(IF(KPI_Element_Map!$E$2:$E$287=$A13,KPI_Element_Map!$A$2:$A$287),COLUMNS($J13:K13)),KPI_Master!$A:$A,0)&":P"&MATCH(SMALL(IF(KPI_Element_Map!$E$2:$E$287=$A13,KPI_Element_Map!$A$2:$A$287),COLUMNS($J13:K13)),KPI_Master!$A:$A,0),SMALL(IF(KPI_Element_Map!$E$2:$E$287=$A13,KPI_Element_Map!$A$2:$A$287),COLUMNS($J13:K13))),"")} -> 87 | L13: {=IFERROR(HYPERLINK("#KPI_Master!A"&MATCH(SMALL(IF(KPI_Element_Map!$E$2:$E$287=$A13,KPI_Element_Map!$A$2:$A$287),COLUMNS($J13:L13)),KPI_Master!$A:$A,0)&":P"&MATCH(SMALL(IF(KPI_Element_Map!$E$2:$E$287=$A13,KPI_Element_Map!$A$2:$A$287),COLUMNS($J13:L13)),KPI_Master!$A:$A,0),SMALL(IF(KPI_Element_Map!$E$2:$E$287=$A13,KPI_Element_Map!$A$2:$A$287),COLUMNS($J13:L13))),"")} | M13: {=IFERROR(HYPERLINK("#KPI_Master!A"&MATCH(SMALL(IF(KPI_Element_Map!$E$2:$E$287=$A13,KPI_Element_Map!$A$2:$A$287),COLUMNS($J13:M13)),KPI_Master!$A:$A,0)&":P"&MATCH(SMALL(IF(KPI_Element_Map!$E$2:$E$287=$A13,KPI_Element_Map!$A$2:$A$287),COLUMNS($J13:M13)),KPI_Master!$A:$A,0),SMALL(IF(KPI_Element_Map!$E$2:$E$287=$A13,KPI_Element_Map!$A$2:$A$287),COLUMNS($J13:M13))),"")} | N13: {=IFERROR(HYPERLINK("#KPI_Master!A"&MATCH(SMALL(IF(KPI_Element_Map!$E$2:$E$287=$A13,KPI_Element_Map!$A$2:$A$287),COLUMNS($J13:N13)),KPI_Master!$A:$A,0)&":P"&MATCH(SMALL(IF(KPI_Element_Map!$E$2:$E$287=$A13,KPI_Element_Map!$A$2:$A$287),COLUMNS($J13:N13)),KPI_Master!$A:$A,0),SMALL(IF(KPI_Element_Map!$E$2:$E$287=$A13,KPI_Element_Map!$A$2:$A$287),COLUMNS($J13:N13))),"")} | O13: {=IFERROR(HYPERLINK("#KPI_Master!A"&MATCH(SMALL(IF(KPI_Element_Map!$E$2:$E$287=$A13,KPI_Element_Map!$A$2:$A$287),COLUMNS($J13:O13)),KPI_Master!$A:$A,0)&":P"&MATCH(SMALL(IF(KPI_Element_Map!$E$2:$E$287=$A13,KPI_Element_Map!$A$2:$A$287),COLUMNS($J13:O13)),KPI_Master!$A:$A,0),SMALL(IF(KPI_Element_Map!$E$2:$E$287=$A13,KPI_Element_Map!$A$2:$A$287),COLUMNS($J13:O13))),"")} | P13: {=IFERROR(HYPERLINK("#KPI_Master!A"&MATCH(SMALL(IF(KPI_Element_Map!$E$2:$E$287=$A13,KPI_Element_Map!$A$2:$A$287),COLUMNS($J13:P13)),KPI_Master!$A:$A,0)&":P"&MATCH(SMALL(IF(KPI_Element_Map!$E$2:$E$287=$A13,KPI_Element_Map!$A$2:$A$287),COLUMNS($J13:P13)),KPI_Master!$A:$A,0),SMALL(IF(KPI_Element_Map!$E$2:$E$287=$A13,KPI_Element_Map!$A$2:$A$287),COLUMNS($J13:P13))),"")} | Q13: {=IFERROR(HYPERLINK("#KPI_Master!A"&MATCH(SMALL(IF(KPI_Element_Map!$E$2:$E$287=$A13,KPI_Element_Map!$A$2:$A$287),COLUMNS($J13:Q13)),KPI_Master!$A:$A,0)&":P"&MATCH(SMALL(IF(KPI_Element_Map!$E$2:$E$287=$A13,KPI_Element_Map!$A$2:$A$287),COLUMNS($J13:Q13)),KPI_Master!$A:$A,0),SMALL(IF(KPI_Element_Map!$E$2:$E$287=$A13,KPI_Element_Map!$A$2:$A$287),COLUMNS($J13:Q13))),"")} | ... AH13: {=IFERROR(HYPERLINK("#KPI_Master!A"&MATCH(SMALL(IF(KPI_Element_Map!$E$2:$E$287=$A13,KPI_Element_Map!$A$2:$A$287),COLUMNS($J13:AH13)),KPI_Master!$A:$A,0)&":P"&MATCH(SMALL(IF(KPI_Element_Map!$E$2:$E$287=$A13,KPI_Element_Map!$A$2:$A$287),COLUMNS($J13:AH13)),KPI_Master!$A:$A,0),SMALL(IF(KPI_Element_Map!$E$2:$E$287=$A13,KPI_Element_Map!$A$2:$A$287),COLUMNS($J13:AH13))),"")}
A14: E10 | B14: Prior Hospital Stay Dates | C14: Hospital admit / discharge dates captured on the admission record | D14: {=_xlfn.TEXTJOIN(", ",TRUE(),IF(KPI_Element_Map!$E$2:$E$287=$A14,KPI_Element_Map!$A$2:$A$287,""))} -> 103 | E14: =COUNTIF(KPI_Element_Map!$E$2:$E$287,$A14) -> 1 | F14: =COUNTIFS(KPI_Element_Map!$E$2:$E$287,$A14,KPI_Element_Map!$D$2:$D$287,"1 - Core") -> 0 | G14: D01 | H14: =INDEX(Minimum_Documents!$B:$B,MATCH($G14,Minimum_Documents!$A:$A,0)) -> Census & ADT Register | J14: {=IFERROR(HYPERLINK("#KPI_Master!A"&MATCH(SMALL(IF(KPI_Element_Map!$E$2:$E$287=$A14,KPI_Element_Map!$A$2:$A$287),COLUMNS($J14:J14)),KPI_Master!$A:$A,0)&":P"&MATCH(SMALL(IF(KPI_Element_Map!$E$2:$E$287=$A14,KPI_Element_Map!$A$2:$A$287),COLUMNS($J14:J14)),KPI_Master!$A:$A,0),SMALL(IF(KPI_Element_Map!$E$2:$E$287=$A14,KPI_Element_Map!$A$2:$A$287),COLUMNS($J14:J14))),"")} -> 103 | K14: {=IFERROR(HYPERLINK("#KPI_Master!A"&MATCH(SMALL(IF(KPI_Element_Map!$E$2:$E$287=$A14,KPI_Element_Map!$A$2:$A$287),COLUMNS($J14:K14)),KPI_Master!$A:$A,0)&":P"&MATCH(SMALL(IF(KPI_Element_Map!$E$2:$E$287=$A14,KPI_Element_Map!$A$2:$A$287),COLUMNS($J14:K14)),KPI_Master!$A:$A,0),SMALL(IF(KPI_Element_Map!$E$2:$E$287=$A14,KPI_Element_Map!$A$2:$A$287),COLUMNS($J14:K14))),"")} | L14: {=IFERROR(HYPERLINK("#KPI_Master!A"&MATCH(SMALL(IF(KPI_Element_Map!$E$2:$E$287=$A14,KPI_Element_Map!$A$2:$A$287),COLUMNS($J14:L14)),KPI_Master!$A:$A,0)&":P"&MATCH(SMALL(IF(KPI_Element_Map!$E$2:$E$287=$A14,KPI_Element_Map!$A$2:$A$287),COLUMNS($J14:L14)),KPI_Master!$A:$A,0),SMALL(IF(KPI_Element_Map!$E$2:$E$287=$A14,KPI_Element_Map!$A$2:$A$287),COLUMNS($J14:L14))),"")} | M14: {=IFERROR(HYPERLINK("#KPI_Master!A"&MATCH(SMALL(IF(KPI_Element_Map!$E$2:$E$287=$A14,KPI_Element_Map!$A$2:$A$287),COLUMNS($J14:M14)),KPI_Master!$A:$A,0)&":P"&MATCH(SMALL(IF(KPI_Element_Map!$E$2:$E$287=$A14,KPI_Element_Map!$A$2:$A$287),COLUMNS($J14:M14)),KPI_Master!$A:$A,0),SMALL(IF(KPI_Element_Map!$E$2:$E$287=$A14,KPI_Element_Map!$A$2:$A$287),COLUMNS($J14:M14))),"")} | N14: {=IFERROR(HYPERLINK("#KPI_Master!A"&MATCH(SMALL(IF(KPI_Element_Map!$E$2:$E$287=$A14,KPI_Element_Map!$A$2:$A$287),COLUMNS($J14:N14)),KPI_Master!$A:$A,0)&":P"&MATCH(SMALL(IF(KPI_Element_Map!$E$2:$E$287=$A14,KPI_Element_Map!$A$2:$A$287),COLUMNS($J14:N14)),KPI_Master!$A:$A,0),SMALL(IF(KPI_Element_Map!$E$2:$E$287=$A14,KPI_Element_Map!$A$2:$A$287),COLUMNS($J14:N14))),"")} | O14: {=IFERROR(HYPERLINK("#KPI_Master!A"&MATCH(SMALL(IF(KPI_Element_Map!$E$2:$E$287=$A14,KPI_Element_Map!$A$2:$A$287),COLUMNS($J14:O14)),KPI_Master!$A:$A,0)&":P"&MATCH(SMALL(IF(KPI_Element_Map!$E$2:$E$287=$A14,KPI_Element_Map!$A$2:$A$287),COLUMNS($J14:O14)),KPI_Master!$A:$A,0),SMALL(IF(KPI_Element_Map!$E$2:$E$287=$A14,KPI_Element_Map!$A$2:$A$287),COLUMNS($J14:O14))),"")} | P14: {=IFERROR(HYPERLINK("#KPI_Master!A"&MATCH(SMALL(IF(KPI_Element_Map!$E$2:$E$287=$A14,KPI_Element_Map!$A$2:$A$287),COLUMNS($J14:P14)),KPI_Master!$A:$A,0)&":P"&MATCH(SMALL(IF(KPI_Element_Map!$E$2:$E$287=$A14,KPI_Element_Map!$A$2:$A$287),COLUMNS($J14:P14)),KPI_Master!$A:$A,0),SMALL(IF(KPI_Element_Map!$E$2:$E$287=$A14,KPI_Element_Map!$A$2:$A$287),COLUMNS($J14:P14))),"")} | Q14: {=IFERROR(HYPERLINK("#KPI_Master!A"&MATCH(SMALL(IF(KPI_Element_Map!$E$2:$E$287=$A14,KPI_Element_Map!$A$2:$A$287),COLUMNS($J14:Q14)),KPI_Master!$A:$A,0)&":P"&MATCH(SMALL(IF(KPI_Element_Map!$E$2:$E$287=$A14,KPI_Element_Map!$A$2:$A$287),COLUMNS($J14:Q14)),KPI_Master!$A:$A,0),SMALL(IF(KPI_Element_Map!$E$2:$E$287=$A14,KPI_Element_Map!$A$2:$A$287),COLUMNS($J14:Q14))),"")} | ... AH14: {=IFERROR(HYPERLINK("#KPI_Master!A"&MATCH(SMALL(IF(KPI_Element_Map!$E$2:$E$287=$A14,KPI_Element_Map!$A$2:$A$287),COLUMNS($J14:AH14)),KPI_Master!$A:$A,0)&":P"&MATCH(SMALL(IF(KPI_Element_Map!$E$2:$E$287=$A14,KPI_Element_Map!$A$2:$A$287),COLUMNS($J14:AH14)),KPI_Master!$A:$A,0),SMALL(IF(KPI_Element_Map!$E$2:$E$287=$A14,KPI_Element_Map!$A$2:$A$287),COLUMNS($J14:AH14))),"")}
A15: E11 | B15: Total Available Units / Licensed Beds | C15: Units (or licensed beds) available to occupy | D15: {=_xlfn.TEXTJOIN(", ",TRUE(),IF(KPI_Element_Map!$E$2:$E$287=$A15,KPI_Element_Map!$A$2:$A$287,""))} -> 12, 24, 25, 32, 39, 40, 121, 123, 126, 160, 166, 167 | E15: =COUNTIF(KPI_Element_Map!$E$2:$E$287,$A15) -> 12 | F15: =COUNTIFS(KPI_Element_Map!$E$2:$E$287,$A15,KPI_Element_Map!$D$2:$D$287,"1 - Core") -> 1 | G15: D02 | H15: =INDEX(Minimum_Documents!$B:$B,MATCH($G15,Minimum_Documents!$A:$A,0)) -> Property & Unit Master Schedule | J15: {=IFERROR(HYPERLINK("#KPI_Master!A"&MATCH(SMALL(IF(KPI_Element_Map!$E$2:$E$287=$A15,KPI_Element_Map!$A$2:$A$287),COLUMNS($J15:J15)),KPI_Master!$A:$A,0)&":P"&MATCH(SMALL(IF(KPI_Element_Map!$E$2:$E$287=$A15,KPI_Element_Map!$A$2:$A$287),COLUMNS($J15:J15)),KPI_Master!$A:$A,0),SMALL(IF(KPI_Element_Map!$E$2:$E$287=$A15,KPI_Element_Map!$A$2:$A$287),COLUMNS($J15:J15))),"")} -> 12 | K15: {=IFERROR(HYPERLINK("#KPI_Master!A"&MATCH(SMALL(IF(KPI_Element_Map!$E$2:$E$287=$A15,KPI_Element_Map!$A$2:$A$287),COLUMNS($J15:K15)),KPI_Master!$A:$A,0)&":P"&MATCH(SMALL(IF(KPI_Element_Map!$E$2:$E$287=$A15,KPI_Element_Map!$A$2:$A$287),COLUMNS($J15:K15)),KPI_Master!$A:$A,0),SMALL(IF(KPI_Element_Map!$E$2:$E$287=$A15,KPI_Element_Map!$A$2:$A$287),COLUMNS($J15:K15))),"")} -> 24 | L15: {=IFERROR(HYPERLINK("#KPI_Master!A"&MATCH(SMALL(IF(KPI_Element_Map!$E$2:$E$287=$A15,KPI_Element_Map!$A$2:$A$287),COLUMNS($J15:L15)),KPI_Master!$A:$A,0)&":P"&MATCH(SMALL(IF(KPI_Element_Map!$E$2:$E$287=$A15,KPI_Element_Map!$A$2:$A$287),COLUMNS($J15:L15)),KPI_Master!$A:$A,0),SMALL(IF(KPI_Element_Map!$E$2:$E$287=$A15,KPI_Element_Map!$A$2:$A$287),COLUMNS($J15:L15))),"")} -> 25 | M15: {=IFERROR(HYPERLINK("#KPI_Master!A"&MATCH(SMALL(IF(KPI_Element_Map!$E$2:$E$287=$A15,KPI_Element_Map!$A$2:$A$287),COLUMNS($J15:M15)),KPI_Master!$A:$A,0)&":P"&MATCH(SMALL(IF(KPI_Element_Map!$E$2:$E$287=$A15,KPI_Element_Map!$A$2:$A$287),COLUMNS($J15:M15)),KPI_Master!$A:$A,0),SMALL(IF(KPI_Element_Map!$E$2:$E$287=$A15,KPI_Element_Map!$A$2:$A$287),COLUMNS($J15:M15))),"")} -> 32 | N15: {=IFERROR(HYPERLINK("#KPI_Master!A"&MATCH(SMALL(IF(KPI_Element_Map!$E$2:$E$287=$A15,KPI_Element_Map!$A$2:$A$287),COLUMNS($J15:N15)),KPI_Master!$A:$A,0)&":P"&MATCH(SMALL(IF(KPI_Element_Map!$E$2:$E$287=$A15,KPI_Element_Map!$A$2:$A$287),COLUMNS($J15:N15)),KPI_Master!$A:$A,0),SMALL(IF(KPI_Element_Map!$E$2:$E$287=$A15,KPI_Element_Map!$A$2:$A$287),COLUMNS($J15:N15))),"")} -> 39 | O15: {=IFERROR(HYPERLINK("#KPI_Master!A"&MATCH(SMALL(IF(KPI_Element_Map!$E$2:$E$287=$A15,KPI_Element_Map!$A$2:$A$287),COLUMNS($J15:O15)),KPI_Master!$A:$A,0)&":P"&MATCH(SMALL(IF(KPI_Element_Map!$E$2:$E$287=$A15,KPI_Element_Map!$A$2:$A$287),COLUMNS($J15:O15)),KPI_Master!$A:$A,0),SMALL(IF(KPI_Element_Map!$E$2:$E$287=$A15,KPI_Element_Map!$A$2:$A$287),COLUMNS($J15:O15))),"")} -> 40 | P15: {=IFERROR(HYPERLINK("#KPI_Master!A"&MATCH(SMALL(IF(KPI_Element_Map!$E$2:$E$287=$A15,KPI_Element_Map!$A$2:$A$287),COLUMNS($J15:P15)),KPI_Master!$A:$A,0)&":P"&MATCH(SMALL(IF(KPI_Element_Map!$E$2:$E$287=$A15,KPI_Element_Map!$A$2:$A$287),COLUMNS($J15:P15)),KPI_Master!$A:$A,0),SMALL(IF(KPI_Element_Map!$E$2:$E$287=$A15,KPI_Element_Map!$A$2:$A$287),COLUMNS($J15:P15))),"")} -> 121 | Q15: {=IFERROR(HYPERLINK("#KPI_Master!A"&MATCH(SMALL(IF(KPI_Element_Map!$E$2:$E$287=$A15,KPI_Element_Map!$A$2:$A$287),COLUMNS($J15:Q15)),KPI_Master!$A:$A,0)&":P"&MATCH(SMALL(IF(KPI_Element_Map!$E$2:$E$287=$A15,KPI_Element_Map!$A$2:$A$287),COLUMNS($J15:Q15)),KPI_Master!$A:$A,0),SMALL(IF(KPI_Element_Map!$E$2:$E$287=$A15,KPI_Element_Map!$A$2:$A$287),COLUMNS($J15:Q15))),"")} -> 123 | ... AH15: {=IFERROR(HYPERLINK("#KPI_Master!A"&MATCH(SMALL(IF(KPI_Element_Map!$E$2:$E$287=$A15,KPI_Element_Map!$A$2:$A$287),COLUMNS($J15:AH15)),KPI_Master!$A:$A,0)&":P"&MATCH(SMALL(IF(KPI_Element_Map!$E$2:$E$287=$A15,KPI_Element_Map!$A$2:$A$287),COLUMNS($J15:AH15)),KPI_Master!$A:$A,0),SMALL(IF(KPI_Element_Map!$E$2:$E$287=$A15,KPI_Element_Map!$A$2:$A$287),COLUMNS($J15:AH15))),"")}
A16: E12 | B16: Square Footage (building / cleanable) | C16: Gross building and cleanable square feet | D16: {=_xlfn.TEXTJOIN(", ",TRUE(),IF(KPI_Element_Map!$E$2:$E$287=$A16,KPI_Element_Map!$A$2:$A$287,""))} -> 42, 114, 119 | E16: =COUNTIF(KPI_Element_Map!$E$2:$E$287,$A16) -> 3 | F16: =COUNTIFS(KPI_Element_Map!$E$2:$E$287,$A16,KPI_Element_Map!$D$2:$D$287,"1 - Core") -> 0 | G16: D02 | H16: =INDEX(Minimum_Documents!$B:$B,MATCH($G16,Minimum_Documents!$A:$A,0)) -> Property & Unit Master Schedule | J16: {=IFERROR(HYPERLINK("#KPI_Master!A"&MATCH(SMALL(IF(KPI_Element_Map!$E$2:$E$287=$A16,KPI_Element_Map!$A$2:$A$287),COLUMNS($J16:J16)),KPI_Master!$A:$A,0)&":P"&MATCH(SMALL(IF(KPI_Element_Map!$E$2:$E$287=$A16,KPI_Element_Map!$A$2:$A$287),COLUMNS($J16:J16)),KPI_Master!$A:$A,0),SMALL(IF(KPI_Element_Map!$E$2:$E$287=$A16,KPI_Element_Map!$A$2:$A$287),COLUMNS($J16:J16))),"")} -> 42 | K16: {=IFERROR(HYPERLINK("#KPI_Master!A"&MATCH(SMALL(IF(KPI_Element_Map!$E$2:$E$287=$A16,KPI_Element_Map!$A$2:$A$287),COLUMNS($J16:K16)),KPI_Master!$A:$A,0)&":P"&MATCH(SMALL(IF(KPI_Element_Map!$E$2:$E$287=$A16,KPI_Element_Map!$A$2:$A$287),COLUMNS($J16:K16)),KPI_Master!$A:$A,0),SMALL(IF(KPI_Element_Map!$E$2:$E$287=$A16,KPI_Element_Map!$A$2:$A$287),COLUMNS($J16:K16))),"")} -> 114 | L16: {=IFERROR(HYPERLINK("#KPI_Master!A"&MATCH(SMALL(IF(KPI_Element_Map!$E$2:$E$287=$A16,KPI_Element_Map!$A$2:$A$287),COLUMNS($J16:L16)),KPI_Master!$A:$A,0)&":P"&MATCH(SMALL(IF(KPI_Element_Map!$E$2:$E$287=$A16,KPI_Element_Map!$A$2:$A$287),COLUMNS($J16:L16)),KPI_Master!$A:$A,0),SMALL(IF(KPI_Element_Map!$E$2:$E$287=$A16,KPI_Element_Map!$A$2:$A$287),COLUMNS($J16:L16))),"")} -> 119 | M16: {=IFERROR(HYPERLINK("#KPI_Master!A"&MATCH(SMALL(IF(KPI_Element_Map!$E$2:$E$287=$A16,KPI_Element_Map!$A$2:$A$287),COLUMNS($J16:M16)),KPI_Master!$A:$A,0)&":P"&MATCH(SMALL(IF(KPI_Element_Map!$E$2:$E$287=$A16,KPI_Element_Map!$A$2:$A$287),COLUMNS($J16:M16)),KPI_Master!$A:$A,0),SMALL(IF(KPI_Element_Map!$E$2:$E$287=$A16,KPI_Element_Map!$A$2:$A$287),COLUMNS($J16:M16))),"")} | N16: {=IFERROR(HYPERLINK("#KPI_Master!A"&MATCH(SMALL(IF(KPI_Element_Map!$E$2:$E$287=$A16,KPI_Element_Map!$A$2:$A$287),COLUMNS($J16:N16)),KPI_Master!$A:$A,0)&":P"&MATCH(SMALL(IF(KPI_Element_Map!$E$2:$E$287=$A16,KPI_Element_Map!$A$2:$A$287),COLUMNS($J16:N16)),KPI_Master!$A:$A,0),SMALL(IF(KPI_Element_Map!$E$2:$E$287=$A16,KPI_Element_Map!$A$2:$A$287),COLUMNS($J16:N16))),"")} | O16: {=IFERROR(HYPERLINK("#KPI_Master!A"&MATCH(SMALL(IF(KPI_Element_Map!$E$2:$E$287=$A16,KPI_Element_Map!$A$2:$A$287),COLUMNS($J16:O16)),KPI_Master!$A:$A,0)&":P"&MATCH(SMALL(IF(KPI_Element_Map!$E$2:$E$287=$A16,KPI_Element_Map!$A$2:$A$287),COLUMNS($J16:O16)),KPI_Master!$A:$A,0),SMALL(IF(KPI_Element_Map!$E$2:$E$287=$A16,KPI_Element_Map!$A$2:$A$287),COLUMNS($J16:O16))),"")} | P16: {=IFERROR(HYPERLINK("#KPI_Master!A"&MATCH(SMALL(IF(KPI_Element_Map!$E$2:$E$287=$A16,KPI_Element_Map!$A$2:$A$287),COLUMNS($J16:P16)),KPI_Master!$A:$A,0)&":P"&MATCH(SMALL(IF(KPI_Element_Map!$E$2:$E$287=$A16,KPI_Element_Map!$A$2:$A$287),COLUMNS($J16:P16)),KPI_Master!$A:$A,0),SMALL(IF(KPI_Element_Map!$E$2:$E$287=$A16,KPI_Element_Map!$A$2:$A$287),COLUMNS($J16:P16))),"")} | Q16: {=IFERROR(HYPERLINK("#KPI_Master!A"&MATCH(SMALL(IF(KPI_Element_Map!$E$2:$E$287=$A16,KPI_Element_Map!$A$2:$A$287),COLUMNS($J16:Q16)),KPI_Master!$A:$A,0)&":P"&MATCH(SMALL(IF(KPI_Element_Map!$E$2:$E$287=$A16,KPI_Element_Map!$A$2:$A$287),COLUMNS($J16:Q16)),KPI_Master!$A:$A,0),SMALL(IF(KPI_Element_Map!$E$2:$E$287=$A16,KPI_Element_Map!$A$2:$A$287),COLUMNS($J16:Q16))),"")} | ... AH16: {=IFERROR(HYPERLINK("#KPI_Master!A"&MATCH(SMALL(IF(KPI_Element_Map!$E$2:$E$287=$A16,KPI_Element_Map!$A$2:$A$287),COLUMNS($J16:AH16)),KPI_Master!$A:$A,0)&":P"&MATCH(SMALL(IF(KPI_Element_Map!$E$2:$E$287=$A16,KPI_Element_Map!$A$2:$A$287),COLUMNS($J16:AH16)),KPI_Master!$A:$A,0),SMALL(IF(KPI_Element_Map!$E$2:$E$287=$A16,KPI_Element_Map!$A$2:$A$287),COLUMNS($J16:AH16))),"")}
... A62: E58 | B62: Food Purchase Cost | C62: Raw food purchases. Kept on D03 because food is normally its own P&L account; if it is not, change this Doc ID to D31 | D62: {=_xlfn.TEXTJOIN(", ",TRUE(),IF(KPI_Element_Map!$E$2:$E$287=$A62,KPI_Element_Map!$A$2:$A$287,""))} -> 1, 2, 3, 10 | E62: =COUNTIF(KPI_Element_Map!$E$2:$E$287,$A62) -> 4 | F62: =COUNTIFS(KPI_Element_Map!$E$2:$E$287,$A62,KPI_Element_Map!$D$2:$D$287,"1 - Core") -> 1 | G62: D03 | H62: =INDEX(Minimum_Documents!$B:$B,MATCH($G62,Minimum_Documents!$A:$A,0)) -> Monthly Financial Statement Package - consolidated (P&L with budget, balance sheet, cash flow, trial balance; no department split needed) | J62: {=IFERROR(HYPERLINK("#KPI_Master!A"&MATCH(SMALL(IF(KPI_Element_Map!$E$2:$E$287=$A62,KPI_Element_Map!$A$2:$A$287),COLUMNS($J62:J62)),KPI_Master!$A:$A,0)&":P"&MATCH(SMALL(IF(KPI_Element_Map!$E$2:$E$287=$A62,KPI_Element_Map!$A$2:$A$287),COLUMNS($J62:J62)),KPI_Master!$A:$A,0),SMALL(IF(KPI_Element_Map!$E$2:$E$287=$A62,KPI_Element_Map!$A$2:$A$287),COLUMNS($J62:J62))),"")} -> 1 | K62: {=IFERROR(HYPERLINK("#KPI_Master!A"&MATCH(SMALL(IF(KPI_Element_Map!$E$2:$E$287=$A62,KPI_Element_Map!$A$2:$A$287),COLUMNS($J62:K62)),KPI_Master!$A:$A,0)&":P"&MATCH(SMALL(IF(KPI_Element_Map!$E$2:$E$287=$A62,KPI_Element_Map!$A$2:$A$287),COLUMNS($J62:K62)),KPI_Master!$A:$A,0),SMALL(IF(KPI_Element_Map!$E$2:$E$287=$A62,KPI_Element_Map!$A$2:$A$287),COLUMNS($J62:K62))),"")} -> 2 | L62: {=IFERROR(HYPERLINK("#KPI_Master!A"&MATCH(SMALL(IF(KPI_Element_Map!$E$2:$E$287=$A62,KPI_Element_Map!$A$2:$A$287),COLUMNS($J62:L62)),KPI_Master!$A:$A,0)&":P"&MATCH(SMALL(IF(KPI_Element_Map!$E$2:$E$287=$A62,KPI_Element_Map!$A$2:$A$287),COLUMNS($J62:L62)),KPI_Master!$A:$A,0),SMALL(IF(KPI_Element_Map!$E$2:$E$287=$A62,KPI_Element_Map!$A$2:$A$287),COLUMNS($J62:L62))),"")} -> 3 | M62: {=IFERROR(HYPERLINK("#KPI_Master!A"&MATCH(SMALL(IF(KPI_Element_Map!$E$2:$E$287=$A62,KPI_Element_Map!$A$2:$A$287),COLUMNS($J62:M62)),KPI_Master!$A:$A,0)&":P"&MATCH(SMALL(IF(KPI_Element_Map!$E$2:$E$287=$A62,KPI_Element_Map!$A$2:$A$287),COLUMNS($J62:M62)),KPI_Master!$A:$A,0),SMALL(IF(KPI_Element_Map!$E$2:$E$287=$A62,KPI_Element_Map!$A$2:$A$287),COLUMNS($J62:M62))),"")} -> 10 | N62: {=IFERROR(HYPERLINK("#KPI_Master!A"&MATCH(SMALL(IF(KPI_Element_Map!$E$2:$E$287=$A62,KPI_Element_Map!$A$2:$A$287),COLUMNS($J62:N62)),KPI_Master!$A:$A,0)&":P"&MATCH(SMALL(IF(KPI_Element_Map!$E$2:$E$287=$A62,KPI_Element_Map!$A$2:$A$287),COLUMNS($J62:N62)),KPI_Master!$A:$A,0),SMALL(IF(KPI_Element_Map!$E$2:$E$287=$A62,KPI_Element_Map!$A$2:$A$287),COLUMNS($J62:N62))),"")} | O62: {=IFERROR(HYPERLINK("#KPI_Master!A"&MATCH(SMALL(IF(KPI_Element_Map!$E$2:$E$287=$A62,KPI_Element_Map!$A$2:$A$287),COLUMNS($J62:O62)),KPI_Master!$A:$A,0)&":P"&MATCH(SMALL(IF(KPI_Element_Map!$E$2:$E$287=$A62,KPI_Element_Map!$A$2:$A$287),COLUMNS($J62:O62)),KPI_Master!$A:$A,0),SMALL(IF(KPI_Element_Map!$E$2:$E$287=$A62,KPI_Element_Map!$A$2:$A$287),COLUMNS($J62:O62))),"")} | P62: {=IFERROR(HYPERLINK("#KPI_Master!A"&MATCH(SMALL(IF(KPI_Element_Map!$E$2:$E$287=$A62,KPI_Element_Map!$A$2:$A$287),COLUMNS($J62:P62)),KPI_Master!$A:$A,0)&":P"&MATCH(SMALL(IF(KPI_Element_Map!$E$2:$E$287=$A62,KPI_Element_Map!$A$2:$A$287),COLUMNS($J62:P62)),KPI_Master!$A:$A,0),SMALL(IF(KPI_Element_Map!$E$2:$E$287=$A62,KPI_Element_Map!$A$2:$A$287),COLUMNS($J62:P62))),"")} | Q62: {=IFERROR(HYPERLINK("#KPI_Master!A"&MATCH(SMALL(IF(KPI_Element_Map!$E$2:$E$287=$A62,KPI_Element_Map!$A$2:$A$287),COLUMNS($J62:Q62)),KPI_Master!$A:$A,0)&":P"&MATCH(SMALL(IF(KPI_Element_Map!$E$2:$E$287=$A62,KPI_Element_Map!$A$2:$A$287),COLUMNS($J62:Q62)),KPI_Master!$A:$A,0),SMALL(IF(KPI_Element_Map!$E$2:$E$287=$A62,KPI_Element_Map!$A$2:$A$287),COLUMNS($J62:Q62))),"")} | ... AH62: {=IFERROR(HYPERLINK("#KPI_Master!A"&MATCH(SMALL(IF(KPI_Element_Map!$E$2:$E$287=$A62,KPI_Element_Map!$A$2:$A$287),COLUMNS($J62:AH62)),KPI_Master!$A:$A,0)&":P"&MATCH(SMALL(IF(KPI_Element_Map!$E$2:$E$287=$A62,KPI_Element_Map!$A$2:$A$287),COLUMNS($J62:AH62)),KPI_Master!$A:$A,0),SMALL(IF(KPI_Element_Map!$E$2:$E$287=$A62,KPI_Element_Map!$A$2:$A$287),COLUMNS($J62:AH62))),"")}

Sheet Minimum_Documents
A1: Minimum Source Document Set - one document per data element, covering all 171 KPIs
A2: Distinct documents named in KPI_Master (Source Documents column) | F2: 281 | G2: Counted from KPI_Master column G at build time (split on ";", de-duplicated, case-insensitive)
A3: Minimum documents in this set | F3: =COUNTA(A7:A37) -> 31 | G3: KPIs not covered by any document (should be 0) | I3: =COUNTIF(KPI_Doc_Matrix!F2:F172,0) -> 0
A4: Of which needed to launch Tier 1 - Core KPIs | F4: =COUNTIF(H7:H37,"Yes") -> 19
A6: Doc ID | B6: Minimum Source Document | C6: Source System | D6: Data Elements It Supplies | E6: Replaces / Consolidates (from KPI_Master) | F6: KPIs Using It | G6: Tier 1 KPIs Using It | H6: Needed for Tier 1 Launch? | I6: Sr. Nos. Using It
A7: D01 | B7: Census & ADT Register | C7: EHR (PCC / MatrixCare / AL Advantage / Eldermark) | D7: E01 Total Resident Days; E02 Occupied Units / Beds; E03 Total Residents (headcount); E04 Resident Days by Payer; E05 Skilled / Medicare Part A Days & Census; E06 Census by Level of Care (AL / MC / SNF); E07 Move-Ins / Admissions; E08 Move-Outs / Discharges; E09 Hospital Transfers & Readmissions; E10 Prior Hospital Stay Dates | E7: Daily census report; Census register; Census by payer; Skilled census register; MC census; Occupancy report; Move-in / move-out logs; Discharge records; Transfer / discharge log; Admission face sheets; Discharge register by payer; Midnight census | F7: =KPI_Doc_Matrix!G174 -> 43 | G7: =KPI_Doc_Matrix!G175 -> 10 | H7: =IF(G7>0,"Yes","No - phase 2+") -> Yes | I7: {=_xlfn.TEXTJOIN(", ",TRUE(),IF(KPI_Doc_Matrix!G2:G172=1,KPI_Doc_Matrix!$A$2:$A$172,""))} -> 1, 2, 4, 12, 13, 22, 23, 24, 25, 41, 52, 74, 75, 77, 78, 81, 84, 86, 87, 88, 89, 91, 94, 95, 97, 98, 103, 104, 110, 113, 115, 144, 151, 152, 153, 157, 158, 159, 160, 161, 162, 167, 169
A8: D02 | B8: Property & Unit Master Schedule | C8: Property management / Finance | D8: E11 Total Available Units / Licensed Beds; E12 Square Footage (building / cleanable); E13 Developed Acreage; E14 Published Street Rates | E8: Unit inventory schedule; Licensed bed count; Building floor plan / area schedule; Cleanable square-footage schedule; Site plan (developed acreage); Published rate sheet | F8: =KPI_Doc_Matrix!H174 -> 17 | G8: =KPI_Doc_Matrix!H175 -> 1 | H8: =IF(G8>0,"Yes","No - phase 2+") -> Yes | I8: {=_xlfn.TEXTJOIN(", ",TRUE(),IF(KPI_Doc_Matrix!H2:H172=1,KPI_Doc_Matrix!$A$2:$A$172,""))} -> 12, 24, 25, 32, 39, 40, 42, 114, 119, 120, 121, 123, 126, 160, 165, 166, 167
