Workbook

Sheet Cover
B7: Operations Intelligence Report
B8: Occupancy-driven model - change occupancy, staffing and the scorecard follow
B10: Whitefield Commons
B11: Lakeshore Senior Living Group - Ada, Michigan
B12: Type B (Modified) Life Plan Community / CCRC
B13: 142 IL - 58 AL - 28 MC - 52 SNF - 280 units and beds
B14: MI LARA: Home for the Aged (AL+MC) - Nursing Home (SNF) - CCRC registration
B16: Reporting period | C16: Trailing 12 months ended 2026-08-31
B17: Prepared | C17: 2026-09-22
B18: KPI catalog | C18: Operations KPI Catalog v9 (2026-09-22) - 115 measures
B19: In scope for this community | C19: 115 of 115 - full continuum plus CCRC entity measures
B20: Staffing model | C20: Staffing Base Calculator rules, driven live off occupancy
B21: Screen grounding | C21: Onboarding Screen Analysis Catalog (2026-09-22)
A23: How to use this workbook
B24: 1. Open Inputs | C24: Every shaded cell on the Inputs sheet is editable. Occupancy is the headline driver.
B25: 2. Change occupancy | C25: Staffing Model, Financials, the KPI Scorecard and the Action Plan all recalculate.
B26: 3. Read Sensitivity | C26: Shows staffing and margin at seven occupancy levels side by side without touching Inputs.
B27: 4. Everything else | C27: Reported KPIs come from the uploaded operating reports and do not move with occupancy. Each row on the scorecard says which it is.
A29: MOCKUP - ILLUSTRATIVE OUTPUT. Whitefield Commons is a fictional community and every community-specific value in this workbook is fabricated sample data. The KPI set, benchmark targets and their published sources, the Michigan LARA and CMS regulatory references, the staffing rules and the report structure are all real.
B32: Advantedge Operations - A VMP Systems product - Prepared by Rob Clark

Sheet Executive Summary
A1: Executive Summary
A3: Whitefield Commons - trailing twelve months ended 2026-08-31. Every required report and manual entry was received. Figures marked model-linked below move with the occupancy set on Inputs; everything else is the reported trailing-twelve-month result.
A5: Campus occupancy | B5: Recommended FTE | C5: Staffing variance | D5: Operating margin | E5: Labour % of revenue | F5: Measures below
A6: =Inputs!F19 -> 0.91785714 | B6: ='Staffing Model'!G34 -> 173.36252 | C6: ='Staffing Model'!I34 -> -13.862522 | D6: =Financials!E20 -> 0.21472239 | E6: =Financials!E21 -> 0.48993492 | F6: =COUNTIF('KPI Scorecard'!$F$7:$F$140,"Below") -> 18
A7: of 280 units and beds | B7: at this occupancy | C7: vs current headcount | D7: CCRC benchmark 22.8% | E7: CCRC benchmark 40% | F7: of 115 in scope
A9: What the model says
A10: 1 | B10: The community is staffed for roughly 80% occupancy and running at 92%.
B11: Current headcount of 159.5 FTE is almost exactly what the model recommends at 80% occupancy. At the occupancy actually being run it is about 15 FTE short, and the shortfall is concentrated in direct care. That is the cleanest explanation available for agency at 9.4% and overtime at 7.2%: the building is carrying 92% census on an 80% staffing plan, and buying the difference at premium rates.
A13: 2 | B13: Occupancy is the lever, and the model prices it.
B14: The Sensitivity sheet runs the same model from 75% to 100%. Recommended FTE moves about 32 positions across that range while operating margin moves roughly nine points, because fixed campus expense and the occupancy-invariant roles do not follow census. Filling units is worth considerably more than trimming staff.
A16: 3 | B16: Labour is above benchmark at every occupancy the model runs.
B17: Labour lands near 49% of revenue at recommended staffing and does not reach the 40% CCRC benchmark even at full occupancy. That is a structural consequence of a 52-bed skilled centre inside a 280-unit campus, not a scheduling failure - but agency at 9.4% and overtime at 7.2% are the controllable part of it.
A19: 4 | B19: Seventeen open positions are the root of four separate findings.
B20: Vacancy 8.9%, time to fill 58 days, agency 9.4%, overtime 7.2%, frontline turnover 58.9%. The same gap drives the CMS staffing domain, the labour percentage, and the direct-care variance in the staffing model.
A22: 5 | B22: The skilled centre sits at three stars with the fixable domain underperforming.
B23: Health inspection is two stars and lags by survey cycle. Staffing is three. Weekend HPRD at 2.714 against a weekday 3.452 is the single largest recoverable gap, and it needs scheduling rather than hiring.
A25: 6 | B25: Preventive maintenance is being deferred into capital.
B26: PM completion 81.2% against a 90% standard, 19 days average overdue, on a 1994 campus with average age of plant at 14.8 years. Life safety is clean, so this is economics rather than compliance - for now.
A29: Scorecard rollup - live
A30: Result | B30: Count | C30: Share of scored
A31: On benchmark | B31: =COUNTIF('KPI Scorecard'!$F$7:$F$140,"On benchmark") -> 22 | C31: =IFERROR(B31/(COUNTIF('KPI Scorecard'!$F$7:$F$140,"On benchmark")+COUNTIF('KPI Scorecard'!$F$7:$F$140,"Watch")+COUNTIF('KPI Scorecard'!$F$7:$F$140,"Below")),0) -> 0.30985915
A32: Watch | B32: =COUNTIF('KPI Scorecard'!$F$7:$F$140,"Watch") -> 31 | C32: =IFERROR(B32/(COUNTIF('KPI Scorecard'!$F$7:$F$140,"On benchmark")+COUNTIF('KPI Scorecard'!$F$7:$F$140,"Watch")+COUNTIF('KPI Scorecard'!$F$7:$F$140,"Below")),0) -> 0.43661972
A33: Below benchmark | B33: =COUNTIF('KPI Scorecard'!$F$7:$F$140,"Below") -> 18 | C33: =IFERROR(B33/(COUNTIF('KPI Scorecard'!$F$7:$F$140,"On benchmark")+COUNTIF('KPI Scorecard'!$F$7:$F$140,"Watch")+COUNTIF('KPI Scorecard'!$F$7:$F$140,"Below")),0) -> 0.25352113
A34: Informational | B34: =COUNTIF('KPI Scorecard'!$F$7:$F$140,"Informational") -> 8 | C34: n/a
A35: CMS-fetched | B35: =COUNTIF('KPI Scorecard'!$F$7:$F$140,"CMS-fetched") -> 36 | C35: n/a
A36: Total measures in scope | B36: =COUNTA('KPI Scorecard'!$J$7:$J$140) -> 115
A38: Counts recompute from the scorecard, so the model-linked financial measures move the rollup when occupancy changes.

Sheet Inputs
A1: Inputs - the control panel
A3: Every shaded cell is editable. Nothing else in this workbook is typed in; the rest is formula. Occupancy on row 12 is the headline driver.
A5: Care levels and capacity
C6: IL | D6: AL | E6: MC | F6: SNF | G6: Note
A7: Care level offered? | C7: Yes | D7: Yes | E7: Yes | F7: Yes | G7: Set to No to drop a level. Scorecard scope follows.
A8: Capacity (units / beds) | C8: 142 | D8: 58 | E8: 28 | F8: 52 | G8: Licensed or built capacity
A9: Gross square feet | C9: 168000 | D9: 46400 | E9: 19600 | F9: 41600 | G9: Drives housekeeping and plant
A11: Occupancy - the driver
C12: IL | D12: AL | E12: MC | F12: SNF | G12: Note
A13: OCCUPANCY % | C13: 0.923 | D13: 0.914 | E13: 0.929 | F13: 0.904 | G13: CHANGE THESE. Everything downstream follows.
A14: Occupied units / census | C14: =ROUND(C8*C13,0) -> 131 | D14: =ROUND(D8*D13,0) -> 53 | E14: =ROUND(E8*E13,0) -> 26 | F14: =ROUND(F8*F13,0) -> 47 | G14: Computed - rounded to whole residents
A15: SNF short-stay share of census | C15: n/a | D15: n/a | E15: n/a | F15: 0.3 | G15: Splits SNF census into rehab and long-term care
A16: SNF short-stay census | F16: =ROUND(F14*F15,0) -> 14 | G16: Computed
A17: SNF long-term-care census | F17: =F14-F16 -> 33 | G17: Computed
A19: Total capacity | C19: =SUM(C8:F8) -> 280 | D19: Total occupied | E19: =SUM(C14:F14) -> 257 | F19: =IFERROR(E19/C19,0) -> 0.91785714 | G19: Campus occupancy
A21: Campus structure
A22: CCRC / Life Plan registered? | C22: Yes | G22: Turns on entity measures, security post and foundation role
A23: Ownership model | C23: Standalone | G23: System centralises HR off-site
A24: Tax status | C24: Nonprofit | G24: Drives the foundation / giving role
A25: Campus configuration | C25: Single | G25: Single or Multi-building
A26: Optional security (non-CCRC) | C26: No | G26: Only applies when not CCRC registered
A27: Total employees (headcount) | C27: 196 | G27: Drives HR ratio and employee dining
A29: Revenue and expense assumptions
C30: IL | D30: AL | E30: MC | F30: SNF | G30: Note
A31: Rate (IL/AL/MC per month, SNF per day) | C31: 4150 | D31: 7100 | E31: 8750 | F31: 398 | G31: Blended achieved rate net of concessions
A32: Non-labour opex per occupied unit (mo) / per patient day | C32: 340 | D32: 780 | E32: 980 | F32: 96 | G32: Dining food, supplies, variable utilities
A33: Fixed campus opex (annual) | C33: 3100000 | G33: Insurance, property, admin, base utilities - does not move with census
A34: Benefit / tax burden on wages | C34: 0.22 | G34: Applied to every wage below
A36: Staffing drivers - direct care
A37: Three-shift ratios (residents per caregiver) | C37: IL | D37: AL | E37: MC | F37: SNF | G37: Note
A38: CNA / aide - day shift | C38: n/a | D38: 12 | E38: 8 | F38: 8 | G38: SBC default AL 12 / MC 8 / SNF 8
A39: CNA / aide - evening shift | C39: n/a | D39: 15 | E39: 8 | F39: 8
A40: CNA / aide - night shift | C40: n/a | D40: 20 | E40: 12 | F40: 12
A41: Nurse / med aide - day shift | C41: n/a | D41: 30 | E41: 30 | F41: 20 | G41: SBC default AL/MC 30 / SNF 20
A42: Nurse / med aide - evening shift | C42: n/a | D42: 30 | E42: 30 | F42: 20
A43: Nurse / med aide - night shift | C43: n/a | D43: 30 | E43: 30 | F43: 20
A44: Minimum staff on night shift | C44: n/a | D44: 2 | E44: 2 | F44: 0 | G44: Michigan HFA requires awake staff 24/7. Set 0 to remove the floor.
A46: Staffing drivers - support services
C47: IL | D47: AL | E47: MC | F47: SNF | G47: Note
A48: Meals per resident per day | C48: 1 | D48: 3 | E48: 3 | F48: 3 | G48: IL 1.0 for a Type B one-meal plan. Set 3.0 for a full plan.
...

Sheet Sensitivity
A1: Occupancy Sensitivity
A3: The same staffing and financial model run at seven occupancy levels. Row 6 is the only input on this sheet - change any percentage and that column recalculates. Occupancy is applied uniformly to every care level here; the Inputs sheet lets you set each level separately.
A5: Occupancy applied to every care level | B5: 0.75 | C5: 0.8 | D5: 0.85 | E5: 0.9 | F5: 0.95 | G5: 0.98 | H5: 1 | I5: Editable
A6: Census at each occupancy
A7: IL occupied | B7: =ROUND(Inputs!$C$8*B$5,0) -> 107 | C7: =ROUND(Inputs!$C$8*C$5,0) -> 114 | D7: =ROUND(Inputs!$C$8*D$5,0) -> 121 | E7: =ROUND(Inputs!$C$8*E$5,0) -> 128 | F7: =ROUND(Inputs!$C$8*F$5,0) -> 135 | G7: =ROUND(Inputs!$C$8*G$5,0) -> 139 | H7: =ROUND(Inputs!$C$8*H$5,0) -> 142
A8: AL occupied | B8: =ROUND(Inputs!$D$8*B$5,0) -> 44 | C8: =ROUND(Inputs!$D$8*C$5,0) -> 46 | D8: =ROUND(Inputs!$D$8*D$5,0) -> 49 | E8: =ROUND(Inputs!$D$8*E$5,0) -> 52 | F8: =ROUND(Inputs!$D$8*F$5,0) -> 55 | G8: =ROUND(Inputs!$D$8*G$5,0) -> 57 | H8: =ROUND(Inputs!$D$8*H$5,0) -> 58
A9: MC occupied | B9: =ROUND(Inputs!$E$8*B$5,0) -> 21 | C9: =ROUND(Inputs!$E$8*C$5,0) -> 22 | D9: =ROUND(Inputs!$E$8*D$5,0) -> 24 | E9: =ROUND(Inputs!$E$8*E$5,0) -> 25 | F9: =ROUND(Inputs!$E$8*F$5,0) -> 27 | G9: =ROUND(Inputs!$E$8*G$5,0) -> 27 | H9: =ROUND(Inputs!$E$8*H$5,0) -> 28
A10: SNF census | B10: =ROUND(Inputs!$F$8*B$5,0) -> 39 | C10: =ROUND(Inputs!$F$8*C$5,0) -> 42 | D10: =ROUND(Inputs!$F$8*D$5,0) -> 44 | E10: =ROUND(Inputs!$F$8*E$5,0) -> 47 | F10: =ROUND(Inputs!$F$8*F$5,0) -> 49 | G10: =ROUND(Inputs!$F$8*G$5,0) -> 51 | H10: =ROUND(Inputs!$F$8*H$5,0) -> 52
A11: Total residents | B11: =(ROUND(Inputs!$C$8*B$5,0)+ROUND(Inputs!$D$8*B$5,0)+ROUND(Inputs!$E$8*B$5,0)+ROUND(Inputs!$F$8*B$5,0)) -> 211 | C11: =(ROUND(Inputs!$C$8*C$5,0)+ROUND(Inputs!$D$8*C$5,0)+ROUND(Inputs!$E$8*C$5,0)+ROUND(Inputs!$F$8*C$5,0)) -> 224 | D11: =(ROUND(Inputs!$C$8*D$5,0)+ROUND(Inputs!$D$8*D$5,0)+ROUND(Inputs!$E$8*D$5,0)+ROUND(Inputs!$F$8*D$5,0)) -> 238 | E11: =(ROUND(Inputs!$C$8*E$5,0)+ROUND(Inputs!$D$8*E$5,0)+ROUND(Inputs!$E$8*E$5,0)+ROUND(Inputs!$F$8*E$5,0)) -> 252 | F11: =(ROUND(Inputs!$C$8*F$5,0)+ROUND(Inputs!$D$8*F$5,0)+ROUND(Inputs!$E$8*F$5,0)+ROUND(Inputs!$F$8*F$5,0)) -> 266 | G11: =(ROUND(Inputs!$C$8*G$5,0)+ROUND(Inputs!$D$8*G$5,0)+ROUND(Inputs!$E$8*G$5,0)+ROUND(Inputs!$F$8*G$5,0)) -> 274 | H11: =(ROUND(Inputs!$C$8*H$5,0)+ROUND(Inputs!$D$8*H$5,0)+ROUND(Inputs!$E$8*H$5,0)+ROUND(Inputs!$F$8*H$5,0)) -> 280
A12: Recommended staffing (FTE)
A13: CNA / aide | B13: =IF(ROUND(Inputs!$D$8*B$5,0)=0,0,((ROUND(Inputs!$D$8*B$5,0)/Inputs!$D$38)+(ROUND(Inputs!$D$8*B$5,0)/Inputs!$D$39)+MAX(Inputs!$D$44,ROUND(Inputs!$D$8*B$5,0)/Inputs!$D$40))*8*7/40)+IF(ROUND(Inputs!$E$8*B$5,0)=0,0,((ROUND(Inputs!$E$8*B$5,0)/Inputs!$E$38)+(ROUND(Inputs!$E$8*B$5,0)/Inputs!$E$39)+MAX(Inputs!$E$44,ROUND(Inputs!$E$8*B$5,0)/Inputs!$E$40))*8*7/40)+IF(ROUND(Inputs!$F$8*B$5,0)=0,0,((ROUND(Inputs!$F$8*B$5,0)/Inputs!$F$38)+(ROUND(Inputs!$F$8*B$5,0)/Inputs!$F$39)+MAX(Inputs!$F$44,ROUND(Inputs!$F$8*B$5,0)/Inputs!$F$40))*8*7/40) -> 40.67 | C13: =IF(ROUND(Inputs!$D$8*C$5,0)=0,0,((ROUND(Inputs!$D$8*C$5,0)/Inputs!$D$38)+(ROUND(Inputs!$D$8*C$5,0)/Inputs!$D$39)+MAX(Inputs!$D$44,ROUND(Inputs!$D$8*C$5,0)/Inputs!$D$40))*8*7/40)+IF(ROUND(Inputs!$E$8*C$5,0)=0,0,((ROUND(Inputs!$E$8*C$5,0)/Inputs!$E$38)+(ROUND(Inputs!$E$8*C$5,0)/Inputs!$E$39)+MAX(Inputs!$E$44,ROUND(Inputs!$E$8*C$5,0)/Inputs!$E$40))*8*7/40)+IF(ROUND(Inputs!$F$8*C$5,0)=0,0,((ROUND(Inputs!$F$8*C$5,0)/Inputs!$F$38)+(ROUND(Inputs!$F$8*C$5,0)/Inputs!$F$39)+MAX(Inputs!$F$44,ROUND(Inputs!$F$8*C$5,0)/Inputs!$F$40))*8*7/40) -> 42.98 | D13: =IF(ROUND(Inputs!$D$8*D$5,0)=0,0,((ROUND(Inputs!$D$8*D$5,0)/Inputs!$D$38)+(ROUND(Inputs!$D$8*D$5,0)/Inputs!$D$39)+MAX(Inputs!$D$44,ROUND(Inputs!$D$8*D$5,0)/Inputs!$D$40))*8*7/40)+IF(ROUND(Inputs!$E$8*D$5,0)=0,0,((ROUND(Inputs!$E$8*D$5,0)/Inputs!$E$38)+(ROUND(Inputs!$E$8*D$5,0)/Inputs!$E$39)+MAX(Inputs!$E$44,ROUND(Inputs!$E$8*D$5,0)/Inputs!$E$40))*8*7/40)+IF(ROUND(Inputs!$F$8*D$5,0)=0,0,((ROUND(Inputs!$F$8*D$5,0)/Inputs!$F$38)+(ROUND(Inputs!$F$8*D$5,0)/Inputs!$F$39)+MAX(Inputs!$F$44,ROUND(Inputs!$F$8*D$5,0)/Inputs!$F$40))*8*7/40) -> 45.453333 | E13: =IF(ROUND(Inputs!$D$8*E$5,0)=0,0,((ROUND(Inputs!$D$8*E$5,0)/Inputs!$D$38)+(ROUND(Inputs!$D$8*E$5,0)/Inputs!$D$39)+MAX(Inputs!$D$44,ROUND(Inputs!$D$8*E$5,0)/Inputs!$D$40))*8*7/40)+IF(ROUND(Inputs!$E$8*E$5,0)=0,0,((ROUND(Inputs!$E$8*E$5,0)/Inputs!$E$38)+(ROUND(Inputs!$E$8*E$5,0)/Inputs!$E$39)+MAX(Inputs!$E$44,ROUND(Inputs!$E$8*E$5,0)/Inputs!$E$40))*8*7/40)+IF(ROUND(Inputs!$F$8*E$5,0)=0,0,((ROUND(Inputs!$F$8*E$5,0)/Inputs!$F$38)+(ROUND(Inputs!$F$8*E$5,0)/Inputs!$F$39)+MAX(Inputs!$F$44,ROUND(Inputs!$F$8*E$5,0)/Inputs!$F$40))*8*7/40) -> 48.16 | F13: =IF(ROUND(Inputs!$D$8*F$5,0)=0,0,((ROUND(Inputs!$D$8*F$5,0)/Inputs!$D$38)+(ROUND(Inputs!$D$8*F$5,0)/Inputs!$D$39)+MAX(Inputs!$D$44,ROUND(Inputs!$D$8*F$5,0)/Inputs!$D$40))*8*7/40)+IF(ROUND(Inputs!$E$8*F$5,0)=0,0,((ROUND(Inputs!$E$8*F$5,0)/Inputs!$E$38)+(ROUND(Inputs!$E$8*F$5,0)/Inputs!$E$39)+MAX(Inputs!$E$44,ROUND(Inputs!$E$8*F$5,0)/Inputs!$E$40))*8*7/40)+IF(ROUND(Inputs!$F$8*F$5,0)=0,0,((ROUND(Inputs!$F$8*F$5,0)/Inputs!$F$38)+(ROUND(Inputs!$F$8*F$5,0)/Inputs!$F$39)+MAX(Inputs!$F$44,ROUND(Inputs!$F$8*F$5,0)/Inputs!$F$40))*8*7/40) -> 50.866667 | G13: =IF(ROUND(Inputs!$D$8*G$5,0)=0,0,((ROUND(Inputs!$D$8*G$5,0)/Inputs!$D$38)+(ROUND(Inputs!$D$8*G$5,0)/Inputs!$D$39)+MAX(Inputs!$D$44,ROUND(Inputs!$D$8*G$5,0)/Inputs!$D$40))*8*7/40)+IF(ROUND(Inputs!$E$8*G$5,0)=0,0,((ROUND(Inputs!$E$8*G$5,0)/Inputs!$E$38)+(ROUND(Inputs!$E$8*G$5,0)/Inputs!$E$39)+MAX(Inputs!$E$44,ROUND(Inputs!$E$8*G$5,0)/Inputs!$E$40))*8*7/40)+IF(ROUND(Inputs!$F$8*G$5,0)=0,0,((ROUND(Inputs!$F$8*G$5,0)/Inputs!$F$38)+(ROUND(Inputs!$F$8*G$5,0)/Inputs!$F$39)+MAX(Inputs!$F$44,ROUND(Inputs!$F$8*G$5,0)/Inputs!$F$40))*8*7/40) -> 52.36 | H13: =IF(ROUND(Inputs!$D$8*H$5,0)=0,0,((ROUND(Inputs!$D$8*H$5,0)/Inputs!$D$38)+(ROUND(Inputs!$D$8*H$5,0)/Inputs!$D$39)+MAX(Inputs!$D$44,ROUND(Inputs!$D$8*H$5,0)/Inputs!$D$40))*8*7/40)+IF(ROUND(Inputs!$E$8*H$5,0)=0,0,((ROUND(Inputs!$E$8*H$5,0)/Inputs!$E$38)+(ROUND(Inputs!$E$8*H$5,0)/Inputs!$E$39)+MAX(Inputs!$E$44,ROUND(Inputs!$E$8*H$5,0)/Inputs!$E$40))*8*7/40)+IF(ROUND(Inputs!$F$8*H$5,0)=0,0,((ROUND(Inputs!$F$8*H$5,0)/Inputs!$F$38)+(ROUND(Inputs!$F$8*H$5,0)/Inputs!$F$39)+MAX(Inputs!$F$44,ROUND(Inputs!$F$8*H$5,0)/Inputs!$F$40))*8*7/40) -> 53.573333 | I13: Three-shift ratio model
A14: Nurse / med aide | B14: =IF(ROUND(Inputs!$D$8*B$5,0)=0,0,(MAX(1,ROUND(Inputs!$D$8*B$5,0)/Inputs!$D$41)+MAX(1,ROUND(Inputs!$D$8*B$5,0)/Inputs!$D$42)+MAX(1,ROUND(Inputs!$D$8*B$5,0)/Inputs!$D$43))*8*7/40)+IF(ROUND(Inputs!$E$8*B$5,0)=0,0,(MAX(1,ROUND(Inputs!$E$8*B$5,0)/Inputs!$E$41)+MAX(1,ROUND(Inputs!$E$8*B$5,0)/Inputs!$E$42)+MAX(1,ROUND(Inputs!$E$8*B$5,0)/Inputs!$E$43))*8*7/40)+IF(ROUND(Inputs!$F$8*B$5,0)=0,0,(MAX(1,ROUND(Inputs!$F$8*B$5,0)/Inputs!$F$41)+MAX(1,ROUND(Inputs!$F$8*B$5,0)/Inputs!$F$42)+MAX(1,ROUND(Inputs!$F$8*B$5,0)/Inputs!$F$43))*8*7/40) -> 18.55 | C14: =IF(ROUND(Inputs!$D$8*C$5,0)=0,0,(MAX(1,ROUND(Inputs!$D$8*C$5,0)/Inputs!$D$41)+MAX(1,ROUND(Inputs!$D$8*C$5,0)/Inputs!$D$42)+MAX(1,ROUND(Inputs!$D$8*C$5,0)/Inputs!$D$43))*8*7/40)+IF(ROUND(Inputs!$E$8*C$5,0)=0,0,(MAX(1,ROUND(Inputs!$E$8*C$5,0)/Inputs!$E$41)+MAX(1,ROUND(Inputs!$E$8*C$5,0)/Inputs!$E$42)+MAX(1,ROUND(Inputs!$E$8*C$5,0)/Inputs!$E$43))*8*7/40)+IF(ROUND(Inputs!$F$8*C$5,0)=0,0,(MAX(1,ROUND(Inputs!$F$8*C$5,0)/Inputs!$F$41)+MAX(1,ROUND(Inputs!$F$8*C$5,0)/Inputs!$F$42)+MAX(1,ROUND(Inputs!$F$8*C$5,0)/Inputs!$F$43))*8*7/40) -> 19.46 | D14: =IF(ROUND(Inputs!$D$8*D$5,0)=0,0,(MAX(1,ROUND(Inputs!$D$8*D$5,0)/Inputs!$D$41)+MAX(1,ROUND(Inputs!$D$8*D$5,0)/Inputs!$D$42)+MAX(1,ROUND(Inputs!$D$8*D$5,0)/Inputs!$D$43))*8*7/40)+IF(ROUND(Inputs!$E$8*D$5,0)=0,0,(MAX(1,ROUND(Inputs!$E$8*D$5,0)/Inputs!$E$41)+MAX(1,ROUND(Inputs!$E$8*D$5,0)/Inputs!$E$42)+MAX(1,ROUND(Inputs!$E$8*D$5,0)/Inputs!$E$43))*8*7/40)+IF(ROUND(Inputs!$F$8*D$5,0)=0,0,(MAX(1,ROUND(Inputs!$F$8*D$5,0)/Inputs!$F$41)+MAX(1,ROUND(Inputs!$F$8*D$5,0)/Inputs!$F$42)+MAX(1,ROUND(Inputs!$F$8*D$5,0)/Inputs!$F$43))*8*7/40) -> 20.3 | E14: =IF(ROUND(Inputs!$D$8*E$5,0)=0,0,(MAX(1,ROUND(Inputs!$D$8*E$5,0)/Inputs!$D$41)+MAX(1,ROUND(Inputs!$D$8*E$5,0)/Inputs!$D$42)+MAX(1,ROUND(Inputs!$D$8*E$5,0)/Inputs!$D$43))*8*7/40)+IF(ROUND(Inputs!$E$8*E$5,0)=0,0,(MAX(1,ROUND(Inputs!$E$8*E$5,0)/Inputs!$E$41)+MAX(1,ROUND(Inputs!$E$8*E$5,0)/Inputs!$E$42)+MAX(1,ROUND(Inputs!$E$8*E$5,0)/Inputs!$E$43))*8*7/40)+IF(ROUND(Inputs!$F$8*E$5,0)=0,0,(MAX(1,ROUND(Inputs!$F$8*E$5,0)/Inputs!$F$41)+MAX(1,ROUND(Inputs!$F$8*E$5,0)/Inputs!$F$42)+MAX(1,ROUND(Inputs!$F$8*E$5,0)/Inputs!$F$43))*8*7/40) -> 21.35 | F14: =IF(ROUND(Inputs!$D$8*F$5,0)=0,0,(MAX(1,ROUND(Inputs!$D$8*F$5,0)/Inputs!$D$41)+MAX(1,ROUND(Inputs!$D$8*F$5,0)/Inputs!$D$42)+MAX(1,ROUND(Inputs!$D$8*F$5,0)/Inputs!$D$43))*8*7/40)+IF(ROUND(Inputs!$E$8*F$5,0)=0,0,(MAX(1,ROUND(Inputs!$E$8*F$5,0)/Inputs!$E$41)+MAX(1,ROUND(Inputs!$E$8*F$5,0)/Inputs!$E$42)+MAX(1,ROUND(Inputs!$E$8*F$5,0)/Inputs!$E$43))*8*7/40)+IF(ROUND(Inputs!$F$8*F$5,0)=0,0,(MAX(1,ROUND(Inputs!$F$8*F$5,0)/Inputs!$F$41)+MAX(1,ROUND(Inputs!$F$8*F$5,0)/Inputs!$F$42)+MAX(1,ROUND(Inputs!$F$8*F$5,0)/Inputs!$F$43))*8*7/40) -> 22.19 | G14: =IF(ROUND(Inputs!$D$8*G$5,0)=0,0,(MAX(1,ROUND(Inputs!$D$8*G$5,0)/Inputs!$D$41)+MAX(1,ROUND(Inputs!$D$8*G$5,0)/Inputs!$D$42)+MAX(1,ROUND(Inputs!$D$8*G$5,0)/Inputs!$D$43))*8*7/40)+IF(ROUND(Inputs!$E$8*G$5,0)=0,0,(MAX(1,ROUND(Inputs!$E$8*G$5,0)/Inputs!$E$41)+MAX(1,ROUND(Inputs!$E$8*G$5,0)/Inputs!$E$42)+MAX(1,ROUND(Inputs!$E$8*G$5,0)/Inputs!$E$43))*8*7/40)+IF(ROUND(Inputs!$F$8*G$5,0)=0,0,(MAX(1,ROUND(Inputs!$F$8*G$5,0)/Inputs!$F$41)+MAX(1,ROUND(Inputs!$F$8*G$5,0)/Inputs!$F$42)+MAX(1,ROUND(Inputs!$F$8*G$5,0)/Inputs!$F$43))*8*7/40) -> 22.89 | H14: =IF(ROUND(Inputs!$D$8*H$5,0)=0,0,(MAX(1,ROUND(Inputs!$D$8*H$5,0)/Inputs!$D$41)+MAX(1,ROUND(Inputs!$D$8*H$5,0)/Inputs!$D$42)+MAX(1,ROUND(Inputs!$D$8*H$5,0)/Inputs!$D$43))*8*7/40)+IF(ROUND(Inputs!$E$8*H$5,0)=0,0,(MAX(1,ROUND(Inputs!$E$8*H$5,0)/Inputs!$E$41)+MAX(1,ROUND(Inputs!$E$8*H$5,0)/Inputs!$E$42)+MAX(1,ROUND(Inputs!$E$8*H$5,0)/Inputs!$E$43))*8*7/40)+IF(ROUND(Inputs!$F$8*H$5,0)=0,0,(MAX(1,ROUND(Inputs!$F$8*H$5,0)/Inputs!$F$41)+MAX(1,ROUND(Inputs!$F$8*H$5,0)/Inputs!$F$42)+MAX(1,ROUND(Inputs!$F$8*H$5,0)/Inputs!$F$43))*8*7/40) -> 23.24
A15: Dining | B15: =ROUND(Inputs!$C$8*B$5,0)*Inputs!$C$48*365/Inputs!$C$49/Inputs!$C$85+ROUND(Inputs!$D$8*B$5,0)*Inputs!$D$48*365/Inputs!$D$49/Inputs!$C$85+ROUND(Inputs!$E$8*B$5,0)*Inputs!$E$48*365/Inputs!$E$49/Inputs!$C$85+ROUND(Inputs!$F$8*B$5,0)*Inputs!$F$48*365/Inputs!$F$49/Inputs!$C$85 -> 27.351299 | C15: =ROUND(Inputs!$C$8*C$5,0)*Inputs!$C$48*365/Inputs!$C$49/Inputs!$C$85+ROUND(Inputs!$D$8*C$5,0)*Inputs!$D$48*365/Inputs!$D$49/Inputs!$C$85+ROUND(Inputs!$E$8*C$5,0)*Inputs!$E$48*365/Inputs!$E$49/Inputs!$C$85+ROUND(Inputs!$F$8*C$5,0)*Inputs!$F$48*365/Inputs!$F$49/Inputs!$C$85 -> 28.957517 | D15: =ROUND(Inputs!$C$8*D$5,0)*Inputs!$C$48*365/Inputs!$C$49/Inputs!$C$85+ROUND(Inputs!$D$8*D$5,0)*Inputs!$D$48*365/Inputs!$D$49/Inputs!$C$85+ROUND(Inputs!$E$8*D$5,0)*Inputs!$E$48*365/Inputs!$E$49/Inputs!$C$85+ROUND(Inputs!$F$8*D$5,0)*Inputs!$F$48*365/Inputs!$F$49/Inputs!$C$85 -> 30.799382 | E15: =ROUND(Inputs!$C$8*E$5,0)*Inputs!$C$48*365/Inputs!$C$49/Inputs!$C$85+ROUND(Inputs!$D$8*E$5,0)*Inputs!$D$48*365/Inputs!$D$49/Inputs!$C$85+ROUND(Inputs!$E$8*E$5,0)*Inputs!$E$48*365/Inputs!$E$49/Inputs!$C$85+ROUND(Inputs!$F$8*E$5,0)*Inputs!$F$48*365/Inputs!$F$49/Inputs!$C$85 -> 32.616178 | F15: =ROUND(Inputs!$C$8*F$5,0)*Inputs!$C$48*365/Inputs!$C$49/Inputs!$C$85+ROUND(Inputs!$D$8*F$5,0)*Inputs!$D$48*365/Inputs!$D$49/Inputs!$C$85+ROUND(Inputs!$E$8*F$5,0)*Inputs!$E$48*365/Inputs!$E$49/Inputs!$C$85+ROUND(Inputs!$F$8*F$5,0)*Inputs!$F$48*365/Inputs!$F$49/Inputs!$C$85 -> 34.458042 | G15: =ROUND(Inputs!$C$8*G$5,0)*Inputs!$C$48*365/Inputs!$C$49/Inputs!$C$85+ROUND(Inputs!$D$8*G$5,0)*Inputs!$D$48*365/Inputs!$D$49/Inputs!$C$85+ROUND(Inputs!$E$8*G$5,0)*Inputs!$E$48*365/Inputs!$E$49/Inputs!$C$85+ROUND(Inputs!$F$8*G$5,0)*Inputs!$F$48*365/Inputs!$F$49/Inputs!$C$85 -> 35.499076 | H15: =ROUND(Inputs!$C$8*H$5,0)*Inputs!$C$48*365/Inputs!$C$49/Inputs!$C$85+ROUND(Inputs!$D$8*H$5,0)*Inputs!$D$48*365/Inputs!$D$49/Inputs!$C$85+ROUND(Inputs!$E$8*H$5,0)*Inputs!$E$48*365/Inputs!$E$49/Inputs!$C$85+ROUND(Inputs!$F$8*H$5,0)*Inputs!$F$48*365/Inputs!$F$49/Inputs!$C$85 -> 36.274838
A16: Business office | B16: =IF(ROUND(Inputs!$C$8*B$5,0)=0,0,IF(ROUND(Inputs!$C$8*B$5,0)<125,1,ROUND(Inputs!$C$8*B$5,0)*0.005))+IF(ROUND(Inputs!$D$8*B$5,0)>75,1,ROUND(Inputs!$D$8*B$5,0)*0.005)+IF(ROUND(Inputs!$E$8*B$5,0)>75,1,ROUND(Inputs!$E$8*B$5,0)*0.005)+IF(ROUND(Inputs!$F$8*B$5,0)>0,1,0) -> 2.325 | C16: =IF(ROUND(Inputs!$C$8*C$5,0)=0,0,IF(ROUND(Inputs!$C$8*C$5,0)<125,1,ROUND(Inputs!$C$8*C$5,0)*0.005))+IF(ROUND(Inputs!$D$8*C$5,0)>75,1,ROUND(Inputs!$D$8*C$5,0)*0.005)+IF(ROUND(Inputs!$E$8*C$5,0)>75,1,ROUND(Inputs!$E$8*C$5,0)*0.005)+IF(ROUND(Inputs!$F$8*C$5,0)>0,1,0) -> 2.34 | D16: =IF(ROUND(Inputs!$C$8*D$5,0)=0,0,IF(ROUND(Inputs!$C$8*D$5,0)<125,1,ROUND(Inputs!$C$8*D$5,0)*0.005))+IF(ROUND(Inputs!$D$8*D$5,0)>75,1,ROUND(Inputs!$D$8*D$5,0)*0.005)+IF(ROUND(Inputs!$E$8*D$5,0)>75,1,ROUND(Inputs!$E$8*D$5,0)*0.005)+IF(ROUND(Inputs!$F$8*D$5,0)>0,1,0) -> 2.365 | E16: =IF(ROUND(Inputs!$C$8*E$5,0)=0,0,IF(ROUND(Inputs!$C$8*E$5,0)<125,1,ROUND(Inputs!$C$8*E$5,0)*0.005))+IF(ROUND(Inputs!$D$8*E$5,0)>75,1,ROUND(Inputs!$D$8*E$5,0)*0.005)+IF(ROUND(Inputs!$E$8*E$5,0)>75,1,ROUND(Inputs!$E$8*E$5,0)*0.005)+IF(ROUND(Inputs!$F$8*E$5,0)>0,1,0) -> 2.025 | F16: =IF(ROUND(Inputs!$C$8*F$5,0)=0,0,IF(ROUND(Inputs!$C$8*F$5,0)<125,1,ROUND(Inputs!$C$8*F$5,0)*0.005))+IF(ROUND(Inputs!$D$8*F$5,0)>75,1,ROUND(Inputs!$D$8*F$5,0)*0.005)+IF(ROUND(Inputs!$E$8*F$5,0)>75,1,ROUND(Inputs!$E$8*F$5,0)*0.005)+IF(ROUND(Inputs!$F$8*F$5,0)>0,1,0) -> 2.085 | G16: =IF(ROUND(Inputs!$C$8*G$5,0)=0,0,IF(ROUND(Inputs!$C$8*G$5,0)<125,1,ROUND(Inputs!$C$8*G$5,0)*0.005))+IF(ROUND(Inputs!$D$8*G$5,0)>75,1,ROUND(Inputs!$D$8*G$5,0)*0.005)+IF(ROUND(Inputs!$E$8*G$5,0)>75,1,ROUND(Inputs!$E$8*G$5,0)*0.005)+IF(ROUND(Inputs!$F$8*G$5,0)>0,1,0) -> 2.115 | H16: =IF(ROUND(Inputs!$C$8*H$5,0)=0,0,IF(ROUND(Inputs!$C$8*H$5,0)<125,1,ROUND(Inputs!$C$8*H$5,0)*0.005))+IF(ROUND(Inputs!$D$8*H$5,0)>75,1,ROUND(Inputs!$D$8*H$5,0)*0.005)+IF(ROUND(Inputs!$E$8*H$5,0)>75,1,ROUND(Inputs!$E$8*H$5,0)*0.005)+IF(ROUND(Inputs!$F$8*H$5,0)>0,1,0) -> 2.14
A17: Concierge / front desk | B17: =IF(ROUND(Inputs!$C$8*B$5,0)>0,4.2,0)+IF(ROUND(Inputs!$D$8*B$5,0)<45,ROUND(Inputs!$D$8*B$5,0)*0.005,1)+ROUND(Inputs!$E$8*B$5,0)*0.005+IF(ROUND(Inputs!$F$8*B$5,0)>40,2.1,0) -> 4.525 | C17: =IF(ROUND(Inputs!$C$8*C$5,0)>0,4.2,0)+IF(ROUND(Inputs!$D$8*C$5,0)<45,ROUND(Inputs!$D$8*C$5,0)*0.005,1)+ROUND(Inputs!$E$8*C$5,0)*0.005+IF(ROUND(Inputs!$F$8*C$5,0)>40,2.1,0) -> 7.41 | D17: =IF(ROUND(Inputs!$C$8*D$5,0)>0,4.2,0)+IF(ROUND(Inputs!$D$8*D$5,0)<45,ROUND(Inputs!$D$8*D$5,0)*0.005,1)+ROUND(Inputs!$E$8*D$5,0)*0.005+IF(ROUND(Inputs!$F$8*D$5,0)>40,2.1,0) -> 7.42 | E17: =IF(ROUND(Inputs!$C$8*E$5,0)>0,4.2,0)+IF(ROUND(Inputs!$D$8*E$5,0)<45,ROUND(Inputs!$D$8*E$5,0)*0.005,1)+ROUND(Inputs!$E$8*E$5,0)*0.005+IF(ROUND(Inputs!$F$8*E$5,0)>40,2.1,0) -> 7.425 | F17: =IF(ROUND(Inputs!$C$8*F$5,0)>0,4.2,0)+IF(ROUND(Inputs!$D$8*F$5,0)<45,ROUND(Inputs!$D$8*F$5,0)*0.005,1)+ROUND(Inputs!$E$8*F$5,0)*0.005+IF(ROUND(Inputs!$F$8*F$5,0)>40,2.1,0) -> 7.435 | G17: =IF(ROUND(Inputs!$C$8*G$5,0)>0,4.2,0)+IF(ROUND(Inputs!$D$8*G$5,0)<45,ROUND(Inputs!$D$8*G$5,0)*0.005,1)+ROUND(Inputs!$E$8*G$5,0)*0.005+IF(ROUND(Inputs!$F$8*G$5,0)>40,2.1,0) -> 7.435 | H17: =IF(ROUND(Inputs!$C$8*H$5,0)>0,4.2,0)+IF(ROUND(Inputs!$D$8*H$5,0)<45,ROUND(Inputs!$D$8*H$5,0)*0.005,1)+ROUND(Inputs!$E$8*H$5,0)*0.005+IF(ROUND(Inputs!$F$8*H$5,0)>40,2.1,0) -> 7.44
A18: Activities / life enrichment | B18: =ROUND(Inputs!$C$8*B$5,0)/100+IF(ROUND(Inputs!$D$8*B$5,0)=0,0,IF(ROUND(Inputs!$D$8*B$5,0)<60,1.4,ROUND(Inputs!$D$8*B$5,0)*0.05))+IF(ROUND(Inputs!$E$8*B$5,0)=0,0,IF(ROUND(Inputs!$E$8*B$5,0)<30,1.4,ROUND(Inputs!$E$8*B$5,0)*0.035))+IF(ROUND(Inputs!$F$8*B$5,0)=0,0,IF(ROUND(Inputs!$F$8*B$5,0)<30,1.4,ROUND(Inputs!$F$8*B$5,0)*0.035)) -> 5.235 | C18: =ROUND(Inputs!$C$8*C$5,0)/100+IF(ROUND(Inputs!$D$8*C$5,0)=0,0,IF(ROUND(Inputs!$D$8*C$5,0)<60,1.4,ROUND(Inputs!$D$8*C$5,0)*0.05))+IF(ROUND(Inputs!$E$8*C$5,0)=0,0,IF(ROUND(Inputs!$E$8*C$5,0)<30,1.4,ROUND(Inputs!$E$8*C$5,0)*0.035))+IF(ROUND(Inputs!$F$8*C$5,0)=0,0,IF(ROUND(Inputs!$F$8*C$5,0)<30,1.4,ROUND(Inputs!$F$8*C$5,0)*0.035)) -> 5.41 | D18: =ROUND(Inputs!$C$8*D$5,0)/100+IF(ROUND(Inputs!$D$8*D$5,0)=0,0,IF(ROUND(Inputs!$D$8*D$5,0)<60,1.4,ROUND(Inputs!$D$8*D$5,0)*0.05))+IF(ROUND(Inputs!$E$8*D$5,0)=0,0,IF(ROUND(Inputs!$E$8*D$5,0)<30,1.4,ROUND(Inputs!$E$8*D$5,0)*0.035))+IF(ROUND(Inputs!$F$8*D$5,0)=0,0,IF(ROUND(Inputs!$F$8*D$5,0)<30,1.4,ROUND(Inputs!$F$8*D$5,0)*0.035)) -> 5.55 | E18: =ROUND(Inputs!$C$8*E$5,0)/100+IF(ROUND(Inputs!$D$8*E$5,0)=0,0,IF(ROUND(Inputs!$D$8*E$5,0)<60,1.4,ROUND(Inputs!$D$8*E$5,0)*0.05))+IF(ROUND(Inputs!$E$8*E$5,0)=0,0,IF(ROUND(Inputs!$E$8*E$5,0)<30,1.4,ROUND(Inputs!$E$8*E$5,0)*0.035))+IF(ROUND(Inputs!$F$8*E$5,0)=0,0,IF(ROUND(Inputs!$F$8*E$5,0)<30,1.4,ROUND(Inputs!$F$8*E$5,0)*0.035)) -> 5.725 | F18: =ROUND(Inputs!$C$8*F$5,0)/100+IF(ROUND(Inputs!$D$8*F$5,0)=0,0,IF(ROUND(Inputs!$D$8*F$5,0)<60,1.4,ROUND(Inputs!$D$8*F$5,0)*0.05))+IF(ROUND(Inputs!$E$8*F$5,0)=0,0,IF(ROUND(Inputs!$E$8*F$5,0)<30,1.4,ROUND(Inputs!$E$8*F$5,0)*0.035))+IF(ROUND(Inputs!$F$8*F$5,0)=0,0,IF(ROUND(Inputs!$F$8*F$5,0)<30,1.4,ROUND(Inputs!$F$8*F$5,0)*0.035)) -> 5.865 | G18: =ROUND(Inputs!$C$8*G$5,0)/100+IF(ROUND(Inputs!$D$8*G$5,0)=0,0,IF(ROUND(Inputs!$D$8*G$5,0)<60,1.4,ROUND(Inputs!$D$8*G$5,0)*0.05))+IF(ROUND(Inputs!$E$8*G$5,0)=0,0,IF(ROUND(Inputs!$E$8*G$5,0)<30,1.4,ROUND(Inputs!$E$8*G$5,0)*0.035))+IF(ROUND(Inputs!$F$8*G$5,0)=0,0,IF(ROUND(Inputs!$F$8*G$5,0)<30,1.4,ROUND(Inputs!$F$8*G$5,0)*0.035)) -> 5.975 | H18: =ROUND(Inputs!$C$8*H$5,0)/100+IF(ROUND(Inputs!$D$8*H$5,0)=0,0,IF(ROUND(Inputs!$D$8*H$5,0)<60,1.4,ROUND(Inputs!$D$8*H$5,0)*0.05))+IF(ROUND(Inputs!$E$8*H$5,0)=0,0,IF(ROUND(Inputs!$E$8*H$5,0)<30,1.4,ROUND(Inputs!$E$8*H$5,0)*0.035))+IF(ROUND(Inputs!$F$8*H$5,0)=0,0,IF(ROUND(Inputs!$F$8*H$5,0)<30,1.4,ROUND(Inputs!$F$8*H$5,0)*0.035)) -> 6.04
A19: Social services | B19: =IF(ROUND(Inputs!$D$8*B$5,0)=0,0,ROUND(Inputs!$D$8*B$5,0)/120)+IF(ROUND(Inputs!$E$8*B$5,0)=0,0,ROUND(Inputs!$E$8*B$5,0)/80)+ROUND(ROUND(Inputs!$F$8*B$5,0)*Inputs!$F$15,0)/25+(ROUND(Inputs!$F$8*B$5,0)-ROUND(ROUND(Inputs!$F$8*B$5,0)*Inputs!$F$15,0))/50 -> 1.6491667 | C19: =IF(ROUND(Inputs!$D$8*C$5,0)=0,0,ROUND(Inputs!$D$8*C$5,0)/120)+IF(ROUND(Inputs!$E$8*C$5,0)=0,0,ROUND(Inputs!$E$8*C$5,0)/80)+ROUND(ROUND(Inputs!$F$8*C$5,0)*Inputs!$F$15,0)/25+(ROUND(Inputs!$F$8*C$5,0)-ROUND(ROUND(Inputs!$F$8*C$5,0)*Inputs!$F$15,0))/50 -> 1.7583333 | D19: =IF(ROUND(Inputs!$D$8*D$5,0)=0,0,ROUND(Inputs!$D$8*D$5,0)/120)+IF(ROUND(Inputs!$E$8*D$5,0)=0,0,ROUND(Inputs!$E$8*D$5,0)/80)+ROUND(ROUND(Inputs!$F$8*D$5,0)*Inputs!$F$15,0)/25+(ROUND(Inputs!$F$8*D$5,0)-ROUND(ROUND(Inputs!$F$8*D$5,0)*Inputs!$F$15,0))/50 -> 1.8483333 | E19: =IF(ROUND(Inputs!$D$8*E$5,0)=0,0,ROUND(Inputs!$D$8*E$5,0)/120)+IF(ROUND(Inputs!$E$8*E$5,0)=0,0,ROUND(Inputs!$E$8*E$5,0)/80)+ROUND(ROUND(Inputs!$F$8*E$5,0)*Inputs!$F$15,0)/25+(ROUND(Inputs!$F$8*E$5,0)-ROUND(ROUND(Inputs!$F$8*E$5,0)*Inputs!$F$15,0))/50 -> 1.9658333 | F19: =IF(ROUND(Inputs!$D$8*F$5,0)=0,0,ROUND(Inputs!$D$8*F$5,0)/120)+IF(ROUND(Inputs!$E$8*F$5,0)=0,0,ROUND(Inputs!$E$8*F$5,0)/80)+ROUND(ROUND(Inputs!$F$8*F$5,0)*Inputs!$F$15,0)/25+(ROUND(Inputs!$F$8*F$5,0)-ROUND(ROUND(Inputs!$F$8*F$5,0)*Inputs!$F$15,0))/50 -> 2.0758333 | G19: =IF(ROUND(Inputs!$D$8*G$5,0)=0,0,ROUND(Inputs!$D$8*G$5,0)/120)+IF(ROUND(Inputs!$E$8*G$5,0)=0,0,ROUND(Inputs!$E$8*G$5,0)/80)+ROUND(ROUND(Inputs!$F$8*G$5,0)*Inputs!$F$15,0)/25+(ROUND(Inputs!$F$8*G$5,0)-ROUND(ROUND(Inputs!$F$8*G$5,0)*Inputs!$F$15,0))/50 -> 2.1325 | H19: =IF(ROUND(Inputs!$D$8*H$5,0)=0,0,ROUND(Inputs!$D$8*H$5,0)/120)+IF(ROUND(Inputs!$E$8*H$5,0)=0,0,ROUND(Inputs!$E$8*H$5,0)/80)+ROUND(ROUND(Inputs!$F$8*H$5,0)*Inputs!$F$15,0)/25+(ROUND(Inputs!$F$8*H$5,0)-ROUND(ROUND(Inputs!$F$8*H$5,0)*Inputs!$F$15,0))/50 -> 2.1933333
A20: Laundry | B20: =ROUND(Inputs!$C$8*B$5,0)*Inputs!$C$51/Inputs!$C$52/40+ROUND(Inputs!$D$8*B$5,0)*Inputs!$D$51/Inputs!$C$52/40+ROUND(Inputs!$E$8*B$5,0)*Inputs!$E$51/Inputs!$C$52/40+ROUND(Inputs!$F$8*B$5,0)*Inputs!$F$51/Inputs!$C$52/40 -> 2.24365 | C20: =ROUND(Inputs!$C$8*C$5,0)*Inputs!$C$51/Inputs!$C$52/40+ROUND(Inputs!$D$8*C$5,0)*Inputs!$D$51/Inputs!$C$52/40+ROUND(Inputs!$E$8*C$5,0)*Inputs!$E$51/Inputs!$C$52/40+ROUND(Inputs!$F$8*C$5,0)*Inputs!$F$51/Inputs!$C$52/40 -> 2.3934 | D20: =ROUND(Inputs!$C$8*D$5,0)*Inputs!$C$51/Inputs!$C$52/40+ROUND(Inputs!$D$8*D$5,0)*Inputs!$D$51/Inputs!$C$52/40+ROUND(Inputs!$E$8*D$5,0)*Inputs!$E$51/Inputs!$C$52/40+ROUND(Inputs!$F$8*D$5,0)*Inputs!$F$51/Inputs!$C$52/40 -> 2.52905 | E20: =ROUND(Inputs!$C$8*E$5,0)*Inputs!$C$51/Inputs!$C$52/40+ROUND(Inputs!$D$8*E$5,0)*Inputs!$D$51/Inputs!$C$52/40+ROUND(Inputs!$E$8*E$5,0)*Inputs!$E$51/Inputs!$C$52/40+ROUND(Inputs!$F$8*E$5,0)*Inputs!$F$51/Inputs!$C$52/40 -> 2.68825 | F20: =ROUND(Inputs!$C$8*F$5,0)*Inputs!$C$51/Inputs!$C$52/40+ROUND(Inputs!$D$8*F$5,0)*Inputs!$D$51/Inputs!$C$52/40+ROUND(Inputs!$E$8*F$5,0)*Inputs!$E$51/Inputs!$C$52/40+ROUND(Inputs!$F$8*F$5,0)*Inputs!$F$51/Inputs!$C$52/40 -> 2.8239 | G20: =ROUND(Inputs!$C$8*G$5,0)*Inputs!$C$51/Inputs!$C$52/40+ROUND(Inputs!$D$8*G$5,0)*Inputs!$D$51/Inputs!$C$52/40+ROUND(Inputs!$E$8*G$5,0)*Inputs!$E$51/Inputs!$C$52/40+ROUND(Inputs!$F$8*G$5,0)*Inputs!$F$51/Inputs!$C$52/40 -> 2.9216 | H20: =ROUND(Inputs!$C$8*H$5,0)*Inputs!$C$51/Inputs!$C$52/40+ROUND(Inputs!$D$8*H$5,0)*Inputs!$D$51/Inputs!$C$52/40+ROUND(Inputs!$E$8*H$5,0)*Inputs!$E$51/Inputs!$C$52/40+ROUND(Inputs!$F$8*H$5,0)*Inputs!$F$51/Inputs!$C$52/40 -> 2.9831
A21: Transport | B21: =IF(ROUND(Inputs!$C$8*B$5,0)=0,0,ROUND(Inputs!$C$8*B$5,0)*0.006) -> 0.642 | C21: =IF(ROUND(Inputs!$C$8*C$5,0)=0,0,ROUND(Inputs!$C$8*C$5,0)*0.006) -> 0.684 | D21: =IF(ROUND(Inputs!$C$8*D$5,0)=0,0,ROUND(Inputs!$C$8*D$5,0)*0.006) -> 0.726 | E21: =IF(ROUND(Inputs!$C$8*E$5,0)=0,0,ROUND(Inputs!$C$8*E$5,0)*0.006) -> 0.768 | F21: =IF(ROUND(Inputs!$C$8*F$5,0)=0,0,ROUND(Inputs!$C$8*F$5,0)*0.006) -> 0.81 | G21: =IF(ROUND(Inputs!$C$8*G$5,0)=0,0,ROUND(Inputs!$C$8*G$5,0)*0.006) -> 0.834 | H21: =IF(ROUND(Inputs!$C$8*H$5,0)=0,0,ROUND(Inputs!$C$8*H$5,0)*0.006) -> 0.852
A22: MDS coordinator | B22: =IF(ROUND(Inputs!$F$8*B$5,0)=0,0,(ROUND(Inputs!$F$8*B$5,0)-ROUND(ROUND(Inputs!$F$8*B$5,0)*Inputs!$F$15,0))/45+ROUND(ROUND(Inputs!$F$8*B$5,0)*Inputs!$F$15,0)/30) -> 1 | C22: =IF(ROUND(Inputs!$F$8*C$5,0)=0,0,(ROUND(Inputs!$F$8*C$5,0)-ROUND(ROUND(Inputs!$F$8*C$5,0)*Inputs!$F$15,0))/45+ROUND(ROUND(Inputs!$F$8*C$5,0)*Inputs!$F$15,0)/30) -> 1.0777778 | D22: =IF(ROUND(Inputs!$F$8*D$5,0)=0,0,(ROUND(Inputs!$F$8*D$5,0)-ROUND(ROUND(Inputs!$F$8*D$5,0)*Inputs!$F$15,0))/45+ROUND(ROUND(Inputs!$F$8*D$5,0)*Inputs!$F$15,0)/30) -> 1.1222222 | E22: =IF(ROUND(Inputs!$F$8*E$5,0)=0,0,(ROUND(Inputs!$F$8*E$5,0)-ROUND(ROUND(Inputs!$F$8*E$5,0)*Inputs!$F$15,0))/45+ROUND(ROUND(Inputs!$F$8*E$5,0)*Inputs!$F$15,0)/30) -> 1.2 | F22: =IF(ROUND(Inputs!$F$8*F$5,0)=0,0,(ROUND(Inputs!$F$8*F$5,0)-ROUND(ROUND(Inputs!$F$8*F$5,0)*Inputs!$F$15,0))/45+ROUND(ROUND(Inputs!$F$8*F$5,0)*Inputs!$F$15,0)/30) -> 1.2555556 | G22: =IF(ROUND(Inputs!$F$8*G$5,0)=0,0,(ROUND(Inputs!$F$8*G$5,0)-ROUND(ROUND(Inputs!$F$8*G$5,0)*Inputs!$F$15,0))/45+ROUND(ROUND(Inputs!$F$8*G$5,0)*Inputs!$F$15,0)/30) -> 1.3 | H22: =IF(ROUND(Inputs!$F$8*H$5,0)=0,0,(ROUND(Inputs!$F$8*H$5,0)-ROUND(ROUND(Inputs!$F$8*H$5,0)*Inputs!$F$15,0))/45+ROUND(ROUND(Inputs!$F$8*H$5,0)*Inputs!$F$15,0)/30) -> 1.3333333
A23: Associate ED | B23: =IF((ROUND(Inputs!$C$8*B$5,0)+ROUND(Inputs!$D$8*B$5,0)+ROUND(Inputs!$E$8*B$5,0)+ROUND(Inputs!$F$8*B$5,0))>200,1,0) -> 1 | C23: =IF((ROUND(Inputs!$C$8*C$5,0)+ROUND(Inputs!$D$8*C$5,0)+ROUND(Inputs!$E$8*C$5,0)+ROUND(Inputs!$F$8*C$5,0))>200,1,0) -> 1 | D23: =IF((ROUND(Inputs!$C$8*D$5,0)+ROUND(Inputs!$D$8*D$5,0)+ROUND(Inputs!$E$8*D$5,0)+ROUND(Inputs!$F$8*D$5,0))>200,1,0) -> 1 | E23: =IF((ROUND(Inputs!$C$8*E$5,0)+ROUND(Inputs!$D$8*E$5,0)+ROUND(Inputs!$E$8*E$5,0)+ROUND(Inputs!$F$8*E$5,0))>200,1,0) -> 1 | F23: =IF((ROUND(Inputs!$C$8*F$5,0)+ROUND(Inputs!$D$8*F$5,0)+ROUND(Inputs!$E$8*F$5,0)+ROUND(Inputs!$F$8*F$5,0))>200,1,0) -> 1 | G23: =IF((ROUND(Inputs!$C$8*G$5,0)+ROUND(Inputs!$D$8*G$5,0)+ROUND(Inputs!$E$8*G$5,0)+ROUND(Inputs!$F$8*G$5,0))>200,1,0) -> 1 | H23: =IF((ROUND(Inputs!$C$8*H$5,0)+ROUND(Inputs!$D$8*H$5,0)+ROUND(Inputs!$E$8*H$5,0)+ROUND(Inputs!$F$8*H$5,0))>200,1,0) -> 1
A24: Occupancy-invariant roles | B24: ='Staffing Model'!G6+'Staffing Model'!G10+'Staffing Model'!G11+'Staffing Model'!G13+'Staffing Model'!G14+'Staffing Model'!G18+'Staffing Model'!G21+'Staffing Model'!G22+'Staffing Model'!G23+'Staffing Model'!G30+'Staffing Model'!G31 -> 44.358186 | C24: ='Staffing Model'!G6+'Staffing Model'!G10+'Staffing Model'!G11+'Staffing Model'!G13+'Staffing Model'!G14+'Staffing Model'!G18+'Staffing Model'!G21+'Staffing Model'!G22+'Staffing Model'!G23+'Staffing Model'!G30+'Staffing Model'!G31 -> 44.358186 | D24: ='Staffing Model'!G6+'Staffing Model'!G10+'Staffing Model'!G11+'Staffing Model'!G13+'Staffing Model'!G14+'Staffing Model'!G18+'Staffing Model'!G21+'Staffing Model'!G22+'Staffing Model'!G23+'Staffing Model'!G30+'Staffing Model'!G31 -> 44.358186 | E24: ='Staffing Model'!G6+'Staffing Model'!G10+'Staffing Model'!G11+'Staffing Model'!G13+'Staffing Model'!G14+'Staffing Model'!G18+'Staffing Model'!G21+'Staffing Model'!G22+'Staffing Model'!G23+'Staffing Model'!G30+'Staffing Model'!G31 -> 44.358186 | F24: ='Staffing Model'!G6+'Staffing Model'!G10+'Staffing Model'!G11+'Staffing Model'!G13+'Staffing Model'!G14+'Staffing Model'!G18+'Staffing Model'!G21+'Staffing Model'!G22+'Staffing Model'!G23+'Staffing Model'!G30+'Staffing Model'!G31 -> 44.358186 | G24: ='Staffing Model'!G6+'Staffing Model'!G10+'Staffing Model'!G11+'Staffing Model'!G13+'Staffing Model'!G14+'Staffing Model'!G18+'Staffing Model'!G21+'Staffing Model'!G22+'Staffing Model'!G23+'Staffing Model'!G30+'Staffing Model'!G31 -> 44.358186 | H24: ='Staffing Model'!G6+'Staffing Model'!G10+'Staffing Model'!G11+'Staffing Model'!G13+'Staffing Model'!G14+'Staffing Model'!G18+'Staffing Model'!G21+'Staffing Model'!G22+'Staffing Model'!G23+'Staffing Model'!G30+'Staffing Model'!G31 -> 44.358186 | I24: ED, sales, plant, housekeeping, DON, security, foundation, employee dining, shift supervisor
A25: TOTAL recommended FTE | B25: =B13+B14+B15+B16+B17+B18+B19+B20+B21+B22+B23+B24 -> 149.5493 | C25: =C13+C14+C15+C16+C17+C18+C19+C20+C21+C22+C23+C24 -> 157.82921 | D25: =D13+D14+D15+D16+D17+D18+D19+D20+D21+D22+D23+D24 -> 163.47151 | E25: =E13+E14+E15+E16+E17+E18+E19+E20+E21+E22+E23+E24 -> 169.28145 | F25: =F13+F14+F15+F16+F17+F18+F19+F20+F21+F22+F23+F24 -> 175.22318 | G25: =G13+G14+G15+G16+G17+G18+G19+G20+G21+G22+G23+G24 -> 178.82036 | H25: =H13+H14+H15+H16+H17+H18+H19+H20+H21+H22+H23+H24 -> 181.42812
A26: Current FTE (held constant) | B26: =Inputs!C113 -> 159.5 | C26: =Inputs!C113 -> 159.5 | D26: =Inputs!C113 -> 159.5 | E26: =Inputs!C113 -> 159.5 | F26: =Inputs!C113 -> 159.5 | G26: =Inputs!C113 -> 159.5 | H26: =Inputs!C113 -> 159.5 | I26: Today's headcount
A27: Variance to current | B27: =B26-B25 -> 9.9506987 | C27: =C26-C25 -> 1.6707855 | D27: =D26-D25 -> -3.9715067 | E27: =E26-E25 -> -9.7814468 | F27: =F26-F25 -> -15.723183 | G27: =G26-G25 -> -19.320362 | H27: =H26-H25 -> -21.928124 | I27: Negative = understaffed for that occupancy
A28: FTE per occupied unit | B28: =IFERROR(B25/B11,0) -> 0.70876446 | C28: =IFERROR(C25/C11,0) -> 0.70459471 | D28: =IFERROR(D25/D11,0) -> 0.68685507 | E28: =IFERROR(E25/E11,0) -> 0.67175177 | F28: =IFERROR(F25/F11,0) -> 0.65873377 | G28: =IFERROR(G25/G11,0) -> 0.65262906 | H28: =IFERROR(H25/H11,0) -> 0.64795758
A29: Financial result at each occupancy
A30: Revenue | B30: =ROUND(Inputs!$C$8*B$5,0)*Inputs!$C$31*12+ROUND(Inputs!$D$8*B$5,0)*Inputs!$D$31*12+ROUND(Inputs!$E$8*B$5,0)*Inputs!$E$31*12+ROUND(Inputs!$F$8*B$5,0)*Inputs!$F$31*365 -> 16947930 | C30: =ROUND(Inputs!$C$8*C$5,0)*Inputs!$C$31*12+ROUND(Inputs!$D$8*C$5,0)*Inputs!$D$31*12+ROUND(Inputs!$E$8*C$5,0)*Inputs!$E$31*12+ROUND(Inputs!$F$8*C$5,0)*Inputs!$F$31*365 -> 18007740 | D30: =ROUND(Inputs!$C$8*D$5,0)*Inputs!$C$31*12+ROUND(Inputs!$D$8*D$5,0)*Inputs!$D$31*12+ROUND(Inputs!$E$8*D$5,0)*Inputs!$E$31*12+ROUND(Inputs!$F$8*D$5,0)*Inputs!$F$31*365 -> 19112480 | E30: =ROUND(Inputs!$C$8*E$5,0)*Inputs!$C$31*12+ROUND(Inputs!$D$8*E$5,0)*Inputs!$D$31*12+ROUND(Inputs!$E$8*E$5,0)*Inputs!$E$31*12+ROUND(Inputs!$F$8*E$5,0)*Inputs!$F$31*365 -> 20257490 | F30: =ROUND(Inputs!$C$8*F$5,0)*Inputs!$C$31*12+ROUND(Inputs!$D$8*F$5,0)*Inputs!$D$31*12+ROUND(Inputs!$E$8*F$5,0)*Inputs!$E$31*12+ROUND(Inputs!$F$8*F$5,0)*Inputs!$F$31*365 -> 21362230 | G30: =ROUND(Inputs!$C$8*G$5,0)*Inputs!$C$31*12+ROUND(Inputs!$D$8*G$5,0)*Inputs!$D$31*12+ROUND(Inputs!$E$8*G$5,0)*Inputs!$E$31*12+ROUND(Inputs!$F$8*G$5,0)*Inputs!$F$31*365 -> 22022370 | H30: =ROUND(Inputs!$C$8*H$5,0)*Inputs!$C$31*12+ROUND(Inputs!$D$8*H$5,0)*Inputs!$D$31*12+ROUND(Inputs!$E$8*H$5,0)*Inputs!$E$31*12+ROUND(Inputs!$F$8*H$5,0)*Inputs!$F$31*365 -> 22507240
A31: Non-labour variable expense | B31: =ROUND(Inputs!$C$8*B$5,0)*Inputs!$C$32*12+ROUND(Inputs!$D$8*B$5,0)*Inputs!$D$32*12+ROUND(Inputs!$E$8*B$5,0)*Inputs!$E$32*12+ROUND(Inputs!$F$8*B$5,0)*Inputs!$F$32*365 -> 2461920 | C31: =ROUND(Inputs!$C$8*C$5,0)*Inputs!$C$32*12+ROUND(Inputs!$D$8*C$5,0)*Inputs!$D$32*12+ROUND(Inputs!$E$8*C$5,0)*Inputs!$E$32*12+ROUND(Inputs!$F$8*C$5,0)*Inputs!$F$32*365 -> 2626080 | D31: =ROUND(Inputs!$C$8*D$5,0)*Inputs!$C$32*12+ROUND(Inputs!$D$8*D$5,0)*Inputs!$D$32*12+ROUND(Inputs!$E$8*D$5,0)*Inputs!$E$32*12+ROUND(Inputs!$F$8*D$5,0)*Inputs!$F$32*365 -> 2776320 | E31: =ROUND(Inputs!$C$8*E$5,0)*Inputs!$C$32*12+ROUND(Inputs!$D$8*E$5,0)*Inputs!$D$32*12+ROUND(Inputs!$E$8*E$5,0)*Inputs!$E$32*12+ROUND(Inputs!$F$8*E$5,0)*Inputs!$F$32*365 -> 2949840 | F31: =ROUND(Inputs!$C$8*F$5,0)*Inputs!$C$32*12+ROUND(Inputs!$D$8*F$5,0)*Inputs!$D$32*12+ROUND(Inputs!$E$8*F$5,0)*Inputs!$E$32*12+ROUND(Inputs!$F$8*F$5,0)*Inputs!$F$32*365 -> 3100080 | G31: =ROUND(Inputs!$C$8*G$5,0)*Inputs!$C$32*12+ROUND(Inputs!$D$8*G$5,0)*Inputs!$D$32*12+ROUND(Inputs!$E$8*G$5,0)*Inputs!$E$32*12+ROUND(Inputs!$F$8*G$5,0)*Inputs!$F$32*365 -> 3205200 | H31: =ROUND(Inputs!$C$8*H$5,0)*Inputs!$C$32*12+ROUND(Inputs!$D$8*H$5,0)*Inputs!$D$32*12+ROUND(Inputs!$E$8*H$5,0)*Inputs!$E$32*12+ROUND(Inputs!$F$8*H$5,0)*Inputs!$F$32*365 -> 3273600
A32: Fixed campus expense | B32: =Inputs!$C$33 -> 3100000 | C32: =Inputs!$C$33 -> 3100000 | D32: =Inputs!$C$33 -> 3100000 | E32: =Inputs!$C$33 -> 3100000 | F32: =Inputs!$C$33 -> 3100000 | G32: =Inputs!$C$33 -> 3100000 | H32: =Inputs!$C$33 -> 3100000
A33: Labour at recommended staffing | B33: =B25*IFERROR('Staffing Model'!L34/'Staffing Model'!G34,0) -> 8705093.3 | C33: =C25*IFERROR('Staffing Model'!L34/'Staffing Model'!G34,0) -> 9187057.6 | D33: =D25*IFERROR('Staffing Model'!L34/'Staffing Model'!G34,0) -> 9515488.9 | E33: =E25*IFERROR('Staffing Model'!L34/'Staffing Model'!G34,0) -> 9853678.9 | F33: =F25*IFERROR('Staffing Model'!L34/'Staffing Model'!G34,0) -> 10199541 | G33: =G25*IFERROR('Staffing Model'!L34/'Staffing Model'!G34,0) -> 10408928 | H33: =H25*IFERROR('Staffing Model'!L34/'Staffing Model'!G34,0) -> 10560723 | I33: Recommended FTE at the blended loaded cost per FTE
A34: Net operating income | B34: =B30-B31-B32-B33 -> 2680916.7 | C34: =C30-C31-C32-C33 -> 3094602.4 | D34: =D30-D31-D32-D33 -> 3720671.1 | E34: =E30-E31-E32-E33 -> 4353971.1 | F34: =F30-F31-F32-F33 -> 4962609.5 | G34: =G30-G31-G32-G33 -> 5308241.8 | H34: =H30-H31-H32-H33 -> 5572917
A35: Operating margin | B35: =IFERROR(B34/B30,0) -> 0.15818549 | C35: =IFERROR(C34/C30,0) -> 0.17184846 | D35: =IFERROR(D34/D30,0) -> 0.19467233 | E35: =IFERROR(E34/E30,0) -> 0.21493142 | F35: =IFERROR(F34/F30,0) -> 0.23230765 | G35: =IFERROR(G34/G30,0) -> 0.24103863 | H35: =IFERROR(H34/H30,0) -> 0.24760553
A36: Labour as % of revenue | B36: =IFERROR(B33/B30,0) -> 0.51363755 | C36: =IFERROR(C33/C30,0) -> 0.51017271 | D36: =IFERROR(D33/D30,0) -> 0.49786783 | E36: =IFERROR(E33/E30,0) -> 0.48642151 | F36: =IFERROR(F33/F30,0) -> 0.47745673 | G36: =IFERROR(G33/G30,0) -> 0.4726525 | H36: =IFERROR(H33/H30,0) -> 0.46921448
A38: Read across: revenue rises faster than cost because fixed campus expense and the occupancy-invariant roles do not move with census. That spread is the entire economic case for filling units, and it is why the margin line steepens as occupancy climbs.
A39: Labour here is priced at the blended loaded cost per recommended FTE from the Staffing Model sheet, rather than position by position, so it will differ by a small amount from the Financials sheet where every role carries its own wage.

Sheet Staffing Model
A1: Staffing Model
A3: Recommended FTE computed live from the occupancy on the Inputs sheet. Change occupancy there and every figure on this sheet moves. Ratios, meals per labour hour, square feet per FTE and the night-shift floor are all editable on Inputs.
A5: Position | B5: IL | C5: AL | D5: MC | E5: SNF | F5: Campus | G5: Model FTE | H5: Current | I5: Variance | J5: Cost of gap | K5: Driver | L5: Model labour $ | M5: Current labour $
A6: Executive Director / SNF Administrator (NHA) | B6: 0 | C6: 0 | D6: 0 | E6: =IF(Inputs!F8>0,IF(AND(Inputs!$C$22="Yes",OR(Inputs!C14>0,Inputs!D14>0,Inputs!E14>0),Inputs!F8<60,Inputs!$C$25="Single"),0,1),0) -> 0 | F6: =IF(OR(Inputs!C14>0,Inputs!D14>0,Inputs!E14>0),1,0) -> 1 | G6: =SUM(B6:F6) -> 1 | H6: =Inputs!C90 -> 1 | I6: =H6-G6 -> 0 | J6: =IF(I6<0,-I6*Inputs!D57,0) -> 0 | K6: Campus ED plus a dedicated NHA unless CCRC consolidation applies | L6: =G6*Inputs!D57 -> 157331.2 | M6: =H6*Inputs!D57 -> 157331.2
A7: Associate ED | B7: 0 | C7: 0 | D7: 0 | E7: 0 | F7: =IF(Inputs!E19>200,1,0) -> 1 | G7: =SUM(B7:F7) -> 1 | H7: =Inputs!C91 -> 1 | I7: =H7-G7 -> 0 | J7: =IF(I7<0,-I7*Inputs!D58,0) -> 0 | K7: Fires above 200 total census | L7: =G7*Inputs!D58 -> 111654.4 | M7: =H7*Inputs!D58 -> 111654.4
A8: Business office / billing | B8: =IF(Inputs!C14=0,0,IF(Inputs!C14<125,1,Inputs!C14*0.005)) -> 0.655 | C8: =IF(Inputs!D14>75,1,Inputs!D14*0.005) -> 0.265 | D8: =IF(Inputs!E14>75,1,Inputs!E14*0.005) -> 0.13 | E8: =IF(Inputs!F14>0,1,0) -> 1 | F8: 0 | G8: =SUM(B8:F8) -> 2.05 | H8: =Inputs!C92 -> 3 | I8: =H8-G8 -> 0.95 | J8: =IF(I8<0,-I8*Inputs!D59,0) -> 0 | K8: 0.5% of occupancy per level; SNF binary | L8: =G8*Inputs!D59 -> 140456.16 | M8: =H8*Inputs!D59 -> 205545.6
A9: Concierge / front desk | B9: =IF(Inputs!C14>0,4.2,0) -> 4.2 | C9: =IF(Inputs!D14<45,Inputs!D14*0.005,1) -> 1 | D9: =Inputs!E14*0.005 -> 0.13 | E9: =IF(Inputs!F14>40,2.1,0) -> 2.1 | F9: 0 | G9: =SUM(B9:F9) -> 7.43 | H9: =Inputs!C93 -> 7 | I9: =H9-G9 -> -0.43 | J9: =IF(I9<0,-I9*Inputs!D60,0) -> 18549.856 | K9: IL desk is 24/7 cover at 4.2 FTE | L9: =G9*Inputs!D60 -> 320524.26 | M9: =H9*Inputs!D60 -> 301974.4
A10: Sales / marketing / admissions | B10: =IF(Inputs!C8=0,0,IF(Inputs!C8<100,1,Inputs!C8/100)) -> 1.42 | C10: =IF(Inputs!D8=0,0,IF(Inputs!D8<40,1,Inputs!D8/40)) -> 1.45 | D10: =IF(Inputs!E8=0,0,IF(Inputs!E8<30,1,Inputs!E8/30)) -> 1 | E10: =IF(Inputs!F16=0,0,IF(Inputs!F16<30,1,Inputs!F16/30))+IF(Inputs!F17=0,0,IF(Inputs!F17<30,1,Inputs!F17/30)) -> 2.1 | F10: 0 | G10: =SUM(B10:F10) -> 5.97 | H10: =Inputs!C94 -> 5 | I10: =H10-G10 -> -0.97 | J10: =IF(I10<0,-I10*Inputs!D61,0) -> 83690.048 | K10: Driven by CAPACITY not occupancy - sized to build census | L10: =G10*Inputs!D61 -> 515082.05 | M10: =H10*Inputs!D61 -> 431392
A11: Program director | B11: 0 | C11: 0 | D11: 0 | E11: 0 | F11: 0 | G11: =SUM(B11:F11) -> 0 | H11: =Inputs!C95 -> 1 | I11: =H11-G11 -> 1 | J11: =IF(I11<0,-I11*Inputs!D62,0) -> 0 | K11: Model default 0 - manual role | L11: =G11*Inputs!D62 -> 0 | M11: =H11*Inputs!D62 -> 86278.4
A12: Dining | B12: =IFERROR(Inputs!C14*Inputs!C48*365/Inputs!C49/52/Inputs!$C$85*52,0) -> 10.449082 | C12: =IFERROR(Inputs!D14*Inputs!D48*365/Inputs!D49/52/Inputs!$C$85*52,0) -> 11.160577 | D12: =IFERROR(Inputs!E14*Inputs!E48*365/Inputs!E49/52/Inputs!$C$85*52,0) -> 4.5625 | E12: =IFERROR(Inputs!F14*Inputs!F48*365/Inputs!F49/52/Inputs!$C$85*52,0) -> 7.0693681 | F12: 0 | G12: =SUM(B12:F12) -> 33.241527 | H12: =Inputs!C96 -> 30 | I12: =H12-G12 -> -3.2415272 | J12: =IF(I12<0,-I12*Inputs!D63,0) -> 141482.03 | K12: Annual meals / MPLH / hours per FTE | L12: =G12*Inputs!D63 -> 1450883.6 | M12: =H12*Inputs!D63 -> 1309401.6
A13: Plant operations | B13: 0 | C13: 0 | D13: 0 | E13: 0 | F13: =IFERROR(SUM(Inputs!C9,Inputs!D9,Inputs!E9,Inputs!F9)/Inputs!C53,0) -> 5.512 | G13: =SUM(B13:F13) -> 5.512 | H13: =Inputs!C97 -> 5 | I13: =H13-G13 -> -0.512 | J13: =IF(I13<0,-I13*Inputs!D64,0) -> 34430.157 | K13: Campus square feet per FTE; grounds outsourced | L13: =G13*Inputs!D64 -> 370662.16 | M13: =H13*Inputs!D64 -> 336232
A14: DON / head nurse / care manager | B14: 0 | C14: =IF(OR(Inputs!D14>0,Inputs!E14>0),1,0) -> 1 | D14: 0 | E14: =IF(Inputs!F14>0,1,0) -> 1 | F14: 0 | G14: =SUM(B14:F14) -> 2 | H14: =Inputs!C98 -> 2 | I14: =H14-G14 -> 0 | J14: =IF(I14<0,-I14*Inputs!D65,0) -> 0 | K14: One care director covers AL+MC; SNF keeps its own DON | L14: =G14*Inputs!D65 -> 213158.4 | M14: =H14*Inputs!D65 -> 213158.4
A15: Human resources | B15: 0 | C15: 0 | D15: 0 | E15: 0 | F15: =IF(Inputs!$C$23="System",MAX(0.25,(SUM(G6:G14)+SUM(G16:G23)+G33)/70*0.25),IF((SUM(G6:G14)+SUM(G16:G23)+G33)>40,MAX(0.5,(SUM(G6:G14)+SUM(G16:G23)+G33)/70),(SUM(G6:G14)+SUM(G16:G23)+G33)/70)) -> 2.4417257 | G15: =SUM(B15:F15) -> 2.4417257 | H15: =Inputs!C99 -> 2 | I15: =H15-G15 -> -0.44172566 | J15: =IF(I15<0,-I15*Inputs!D66,0) -> 33627.691 | K15: Headcount driven; excludes itself from its own base | L15: =G15*Inputs!D66 -> 185883.69 | M15: =H15*Inputs!D66 -> 152256
A16: Activities / life enrichment | B16: =Inputs!C14/100 -> 1.31 | C16: =IF(Inputs!D14=0,0,IF(Inputs!D14<60,1.4,Inputs!D14*0.05)) -> 1.4 | D16: =IF(Inputs!E14=0,0,IF(Inputs!E14<30,1.4,Inputs!E14*0.035)) -> 1.4 | E16: =IF(Inputs!F14=0,0,IF(Inputs!F14<30,1.4,Inputs!F14*0.035)) -> 1.645 | F16: 0 | G16: =SUM(B16:F16) -> 5.755 | H16: =Inputs!C100 -> 5.4 | I16: =H16-G16 -> -0.355 | J16: =IF(I16<0,-I16*Inputs!D67,0) -> 17116.112 | K16: Floors of 1.4 keep programming alive in small levels | L16: =G16*Inputs!D67 -> 277473.87 | M16: =H16*Inputs!D67 -> 260357.76
A17: Social services | B17: 0 | C17: =IF(Inputs!D14=0,0,Inputs!D14/120) -> 0.44166667 | D17: =IF(Inputs!E14=0,0,Inputs!E14/80) -> 0.325 | E17: =IFERROR(Inputs!F16/25+Inputs!F17/50,0) -> 1.22 | F17: 0 | G17: =SUM(B17:F17) -> 1.9866667 | H17: =Inputs!C101 -> 2 | I17: =H17-G17 -> 0.013333333 | J17: =IF(I17<0,-I17*Inputs!D68,0) -> 0 | K17: Short-stay weighted heavier than long-term care | L17: =G17*Inputs!D68 -> 120992.77 | M17: =H17*Inputs!D68 -> 121804.8
A18: Housekeeping | B18: =IFERROR(Inputs!C9/Inputs!C50,0) -> 6.72 | C18: =IFERROR(Inputs!D9/Inputs!D50,0) -> 2.32 | D18: =IFERROR(Inputs!E9/Inputs!E50,0) -> 2.45 | E18: =IFERROR(Inputs!F9/Inputs!F50,0) -> 5.2 | F18: 0 | G18: =SUM(B18:F18) -> 16.69 | H18: =Inputs!C102 -> 15 | I18: =H18-G18 -> -1.69 | J18: =IF(I18<0,-I18*Inputs!D69,0) -> 70332.122 | K18: Square-foot driven - does not move with occupancy | L18: =G18*Inputs!D69 -> 694581.72 | M18: =H18*Inputs!D69 -> 624249.6
A19: Laundry | B19: =IFERROR(Inputs!C14*Inputs!C51/Inputs!C52/40,0) -> 0.4192 | C19: =IFERROR(Inputs!D14*Inputs!D51/Inputs!C52/40,0) -> 0.50085 | D19: =IFERROR(Inputs!E14*Inputs!E51/Inputs!C52/40,0) -> 0.2457 | E19: =IFERROR(Inputs!F14*Inputs!F51/Inputs!C52/40,0) -> 1.551 | F19: 0 | G19: =SUM(B19:F19) -> 2.71675 | H19: =Inputs!C103 -> 3 | I19: =H19-G19 -> 0.28325 | J19: =IF(I19<0,-I19*Inputs!D70,0) -> 0 | K19: Pounds per resident week at the processing rate | L19: =G19*Inputs!D70 -> 110304.4 | M19: =H19*Inputs!D70 -> 121804.8
A20: Transport | B20: 0 | C20: 0 | D20: 0 | E20: 0 | F20: =IF(Inputs!C14=0,0,Inputs!C14*0.006) -> 0.786 | G20: =SUM(B20:F20) -> 0.786 | H20: =Inputs!C104 -> 0.8 | I20: =H20-G20 -> 0.014 | J20: =IF(I20<0,-I20*Inputs!D71,0) -> 0 | K20: Scales with IL residents | L20: =G20*Inputs!D71 -> 35901.965 | M20: =H20*Inputs!D71 -> 36541.44
A21: Security | B21: 0 | C21: 0 | D21: 0 | E21: 0 | F21: =IF(Inputs!$C$22="Yes",Inputs!C82,IF(AND(Inputs!C8>0,Inputs!$C$26="Yes"),Inputs!C82,0)) -> 5.12 | G21: =SUM(B21:F21) -> 5.12 | H21: =Inputs!C105 -> 4.6 | I21: =H21-G21 -> -0.52 | J21: =IF(I21<0,-I21*Inputs!D72,0) -> 25731.264 | K21: CCRC registration turns the post on | L21: =G21*Inputs!D72 -> 253353.98 | M21: =H21*Inputs!D72 -> 227622.72
A22: Foundation / giving | B22: 0 | C22: 0 | D22: 0 | E22: 0 | F22: =IF(AND(Inputs!$C$22="Yes",Inputs!$C$24="Nonprofit"),1,0) -> 1 | G22: =SUM(B22:F22) -> 1 | H22: =Inputs!C106 -> 1 | I22: =H22-G22 -> 0 | J22: =IF(I22<0,-I22*Inputs!D73,0) -> 0 | K22: Nonprofit CCRC only | L22: =G22*Inputs!D73 -> 91353.6 | M22: =H22*Inputs!D73 -> 91353.6
A23: Dining - employee meals | B23: 0 | C23: 0 | D23: 0 | E23: 0 | F23: =IFERROR(Inputs!$C$27*Inputs!C83*365/Inputs!C84/Inputs!$C$85,0) -> 2.8661859 | G23: =SUM(B23:F23) -> 2.8661859 | H23: =Inputs!C107 -> 2.5 | I23: =H23-G23 -> -0.3661859 | J23: =IF(I23<0,-I23*Inputs!D63,0) -> 15982.813 | K23: Employee meal volume at its own MPLH | L23: =G23*Inputs!D63 -> 125099.61 | M23: =H23*Inputs!D63 -> 109116.8
A24: Non-direct care subtotal | G24: =SUM(G6:G23) -> 97.565855 | H24: =SUM(H6:H23) -> 91.3 | I24: =SUM(I6:I23) -> -6.2658555 | J24: =SUM(J6:J23) -> 440942.09 | L24: =SUM(L6:L23) -> 5174697.9 | M24: =SUM(M6:M23) -> 4898075.5
A26: Direct care
A27: Position | B27: IL | C27: AL | D27: MC | E27: SNF | F27: Campus | G27: Model FTE | H27: Current | I27: Variance | J27: Cost of gap | K27: Driver
A28: CNA / aide | B28: 0 | C28: =IF(Inputs!D14=0,0,((Inputs!D14/Inputs!D38)+(Inputs!D14/Inputs!D39)+MAX(Inputs!D44,Inputs!D14/Inputs!D40))*8*7/40) -> 14.84 | D28: =IF(Inputs!E14=0,0,((Inputs!E14/Inputs!E38)+(Inputs!E14/Inputs!E39)+MAX(Inputs!E44,Inputs!E14/Inputs!E40))*8*7/40) -> 12.133333 | E28: =IF(Inputs!F14=0,0,((Inputs!F14/Inputs!F38)+(Inputs!F14/Inputs!F39)+MAX(Inputs!F44,Inputs!F14/Inputs!F40))*8*7/40) -> 21.933333 | F28: 0 | G28: =SUM(B28:F28) -> 48.906667 | H28: =Inputs!C108 -> 43 | I28: =H28-G28 -> -5.9066667 | J28: =IF(I28<0,-I28*Inputs!D74,0) -> 320759.41 | K28: Three-shift ratio model with the night floor from Inputs | L28: =G28*Inputs!D74 -> 2655858.9 | M28: =H28*Inputs!D74 -> 2335099.5
A29: Nurse / med aide | B29: 0 | C29: =IF(Inputs!D14=0,0,(MAX(1,Inputs!D14/Inputs!D41)+MAX(1,Inputs!D14/Inputs!D42)+MAX(1,Inputs!D14/Inputs!D43))*8*7/40) -> 7.42 | D29: =IF(Inputs!E14=0,0,(MAX(1,Inputs!E14/Inputs!E41)+MAX(1,Inputs!E14/Inputs!E42)+MAX(1,Inputs!E14/Inputs!E43))*8*7/40) -> 4.2 | E29: =IF(Inputs!F14=0,0,(MAX(1,Inputs!F14/Inputs!F41)+MAX(1,Inputs!F14/Inputs!F42)+MAX(1,Inputs!F14/Inputs!F43))*8*7/40) -> 9.87 | F29: 0 | G29: =SUM(B29:F29) -> 21.49 | H29: =Inputs!C109 -> 19.6 | I29: =H29-G29 -> -1.89 | J29: =IF(I29<0,-I29*Inputs!D75,0) -> 157310.9 | K29: Minimum one nurse per shift at any occupied level | L29: =G29*Inputs!D75 -> 1788683.2 | M29: =H29*Inputs!D75 -> 1631372.3
A30: Specialty / GCM | B30: 0 | C30: 0 | D30: 0 | E30: 0 | F30: 0 | G30: =SUM(B30:F30) -> 0 | H30: =Inputs!C110 -> 0 | I30: =H30-G30 -> 0 | J30: =IF(I30<0,-I30*Inputs!D75,0) -> 0 | K30: Model default 0 - manual role | L30: =G30*Inputs!D75 -> 0 | M30: =H30*Inputs!D75 -> 0
A31: Shift supervisor | B31: 0 | C31: 0 | D31: 0 | E31: =IF(Inputs!F14>0,4.2,0) -> 4.2 | F31: 0 | G31: =SUM(B31:F31) -> 4.2 | H31: =Inputs!C111 -> 4.2 | I31: =H31-G31 -> 0 | J31: =IF(I31<0,-I31*Inputs!D76,0) -> 0 | K31: 24/7 SNF shift supervision | L31: =G31*Inputs!D76 -> 362369.28 | M31: =H31*Inputs!D76 -> 362369.28
A32: MDS coordinator | B32: 0 | C32: 0 | D32: 0 | E32: =IF(Inputs!F14=0,0,Inputs!F17/45+Inputs!F16/30) -> 1.2 | F32: 0 | G32: =SUM(B32:F32) -> 1.2 | H32: =Inputs!C112 -> 1.4 | I32: =H32-G32 -> 0.2 | J32: =IF(I32<0,-I32*Inputs!D77,0) -> 0 | K32: Short-stay weighted heavier; gated on any SNF census | L32: =G32*Inputs!D77 -> 109624.32 | M32: =H32*Inputs!D77 -> 127895.04
A33: Direct care subtotal | G33: =SUM(G28:G32) -> 75.796667 | H33: =SUM(H28:H32) -> 68.2 | I33: =SUM(I28:I32) -> -7.5966667 | J33: =SUM(J28:J32) -> 478070.31 | L33: =SUM(L28:L32) -> 4916535.7 | M33: =SUM(M28:M32) -> 4456736.1
A34: TOTAL - all positions | G34: =G24+G33 -> 173.36252 | H34: =H24+H33 -> 159.5 | I34: =I24+I33 -> -13.862522 | J34: =J24+J33 -> 919012.4 | L34: =L24+L33 -> 10091234 | M34: =M24+M33 -> 9354811.6
A36: Model labour is the recommended pattern at the selected occupancy. Current labour holds today's FTE constant at the same wages, so the two diverge as occupancy moves.

Sheet Financials
A1: Financial Model
A3: A pro forma at the occupancy selected on Inputs. Revenue and variable expense move with census; fixed campus expense does not. Labour is shown twice - at the staffing the model recommends for this occupancy, and at today's headcount held constant.
A5: Revenue
A6: Line | B6: IL | C6: AL | D6: MC | E6: SNF | F6: Total | G6: Basis
A7: Resident revenue | B7: =Inputs!C14*Inputs!C31*12 -> 6523800 | C7: =Inputs!D14*Inputs!D31*12 -> 4515600 | D7: =Inputs!E14*Inputs!E31*12 -> 2730000 | E7: =Inputs!F14*Inputs!F31*365 -> 6827690 | F7: =SUM(B7:E7) -> 20597090 | G7: Occupied x rate. SNF is per patient day.
A9: Operating expense
A10: Line | B10: IL | C10: AL | D10: MC | E10: SNF | F10: Total | G10: Basis
A11: Non-labour variable expense | B11: =Inputs!C14*Inputs!C32*12 -> 534480 | C11: =Inputs!D14*Inputs!D32*12 -> 496080 | D11: =Inputs!E14*Inputs!E32*12 -> 305760 | E11: =Inputs!F14*Inputs!F32*365 -> 1646880 | F11: =SUM(B11:E11) -> 2983200 | G11: Food, supplies, variable utilities - moves with census
A12: Fixed campus expense | F12: =Inputs!C33 -> 3100000 | G12: Insurance, property, admin, base utilities
A13: Labour - at model staffing | F13: ='Staffing Model'!L34 -> 10091234 | G13: Recommended FTE at this occupancy x loaded wage
A14: Labour - at current staffing | F14: ='Staffing Model'!M34 -> 9354811.6 | G14: Today's FTE held constant - shown for comparison
A16: Result
A17: Line | E17: At model staffing | F17: At current staffing
A18: Total operating expense | E18: =F11+F12+F13 -> 16174434 | F18: =F11+F12+F14 -> 15438012
A19: Net operating income | E19: =F7-E18 -> 4422656.4 | F19: =F7-F18 -> 5159078.4
A20: Operating margin | E20: =IFERROR(E19/F7,0) -> 0.21472239 | F20: =IFERROR(F19/F7,0) -> 0.25047608
A21: Labour as % of revenue | E21: =IFERROR(F13/F7,0) -> 0.48993492 | F21: =IFERROR(F14/F7,0) -> 0.45418123
A22: Revenue per occupied unit / month | E22: =IFERROR(F7/Inputs!E19/12,0) -> 6678.6933 | F22: =IFERROR(F7/Inputs!E19/12,0) -> 6678.6933
A23: Operating expense per occupied unit / month | E23: =IFERROR(E18/Inputs!E19/12,0) -> 5244.6283 | F23: =IFERROR(F18/Inputs!E19/12,0) -> 5005.8404
A25: Benchmarks: CCRC operating margin 22.8% and labour 40% of revenue (SOSH 2025 / CARF 2024 medians). Revenue and expense per occupied unit benchmark to the SOSH segment tables. The scorecard scores these automatically.

Sheet KPI Scorecard
A1: KPI Scorecard - Operations KPI Catalog v9
A3: All 115 measures, scoped to the care levels selected on Inputs. Model-linked rows recompute when you change occupancy. Reported rows come from the uploaded operating reports and hold still. CMS rows are fetched from Care Compare.
A5: Code | B5: Measure | C5: Scope | D5: Value | E5: Basis | F5: Status | G5: Benchmark / target | H5: Benchmark source | I5: Intake screen | J5: Department
A6: Operations (8)
A7: OPS-01 | B7: Occupancy Rate by Care Level | C7: IL/AL/MC/SNF | D7: ="IL "&TEXT(Inputs!C13,"0.0%")&" | AL "&TEXT(Inputs!D13,"0.0%")&" | MC "&TEXT(Inputs!E13,"0.0%")&" | SNF "&TEXT(Inputs!F13,"0.0%") -> IL 92.3% | AL 91.4% | MC 92.9% | SNF 90.4% | E7: Model-linked | F7: =IF(AND(Inputs!C13>=0.878,Inputs!D13>=0.899,Inputs!E13>=0.86,Inputs!F13>=0.792),"On benchmark",IF(AND(Inputs!C13>=0.85,Inputs!D13>=0.87,Inputs!E13>=0.83),"Watch","Below")) -> On benchmark | G7: IL 87.8% | AL 89.9% | MC 86.0% | CCRC 90.6% | SNF 79.2% (CARF 2024) | H7: SOSH 2025 Table 2.7 (IL/AL/MC/CCRC); CARF 2025 Occupancy Trends (SNF) | I7: Census / occupancy report (Screen 09) | J7: Operations
A8: OPS-02 | B8: Net Census Change | C8: IL/AL/MC/SNF | D8: +9 units over T-12 | E8: Reported | F8: On benchmark | G8: Directional. Sector occupancy has risen ~0.5-0.7 pp/qtr for 17+ quarters; net decline against a rising market is the flag | H8: Rob Clark - internal standard | I8: Census / occupancy report (Screen 09) | J8: Operations
A9: OPS-03 | B9: Annual Resident Turnover by Care Level | C9: IL/AL/MC | D9: IL 21.4% | AL 46.2% | MC 61.5% | E9: Reported | F9: On benchmark | G9: IL 44.3% | AL 48.1% | MC 64.7% | CCRC 15.6% | H9: SOSH 2025 Table 2.15 | I9: Census / occupancy report (Screen 09) | J9: Operations
A10: OPS-04 | B10: Average Length of Stay by Care Level | C10: IL/AL/MC/SNF | D10: IL 4.7 yr | AL 2.2 yr | MC 1.6 yr | SNF 31 d | E10: Reported | F10: On benchmark | G10: Derived from SOSH turnover: IL ~2.3 yr | AL ~2.1 yr | MC ~1.5 yr. SNF Medicare LOS on own trend | H10: SOSH 2025 Table 2.15 (inverse of turnover); CMS MDS (SNF) | I10: Census report + clinical / MDS report (Screen 09) | J10: Operations
A11: OPS-05 | B11: Resident Satisfaction Score | C11: IL/AL/MC/SNF | D11: 88.4% | E11: Reported | F11: Watch | G11: RC 2025 target >= 90%. Reference: J.D. Power 2025 IL 753/1000; Holleran Choice Award > 85th percentile | H11: RC 2025 CCRC Benchmarks | I11: Manual entry (Screen 10) | J11: Operations
A12: OPS-06 | B12: Family Satisfaction Score | C12: IL/AL/MC/SNF | D12: 86.1% | E12: Reported | F12: Watch | G12: RC 2025 target >= 88%. Reference: J.D. Power 2025 AL/MC 867/1000 | H12: RC 2025 CCRC Benchmarks | I12: Manual entry (Screen 10) | J12: Operations
A13: OPS-07 | B13: Reportable Incident Rate | C13: IL/AL/MC/SNF | D13: 4.9 per 1,000 resident days | E13: Reported | F13: Watch | G13: Scored on the community's own trend. Component reference: falls 3.5-4.0 per 1,000 resident days | H13: Rob Clark - internal standard | I13: Incident and grievance log (Screen 09) | J13: Operations
A14: OPS-08 | B14: Grievance Resolution Time | C14: IL/AL/MC/SNF | D14: 11.4 day average close | 4.1 day acknowledgment | E14: Reported | F14: On benchmark | G14: Resolution <= 30 days; acknowledgment <= 5 business days | H14: CMS 42 CFR 483.10(j); CMS Medicare-plan 30-day grievance standard (reference) | I14: Incident and grievance log (Screen 09) | J14: Operations
A16: Sales and Marketing (11)
